Workbook

Sheet Início
A1: Início — Explorando Galáxias v1.1
A2: Legenda: | B2: Entrada (preencha) | C2: Calculada (automático) | D2: Aviso (texto em vermelho) | E2: Título de bloco | F2: Cabeçalho de coluna | G2: Rótulo da linha | H2: Linha alternada (outro tom) | I2: Não se aplica
A3: Comece por aqui: como usar a ficha, importar no Google Planilhas e o painel de avisos.
A5: Ficha de Personagem — Explorando Galáxias v1.1
A6: Sistema de RPG de mesa no universo de Honkai: Star Rail · autoria: MC Filhos · versão v1.1 · níveis 1 a 20. Ficha automatizada para o Google Planilhas: preencha as células amarelas e o resto se calcula sozinho. Ficha V1.1 · revisão 2.
A7: Não comece um texto com +, - ou =: o Google entende como fórmula. Se precisar, digite um apóstrofo (') antes.
A9: Painel de avisos (automático) — uma linha por aba; zero avisos = ficha conferida
A10: Aba | B10: Avisos | C10: Primeiro aviso
A11: Criação | B11: =SUMPRODUCT((LEN('Criação'!$K$6:$K$10)>0)*1)+SUMPRODUCT((LEN('Criação'!$K$20:$K$22)>0)*1)+SUMPRODUCT((LEN('Criação'!$K$25:$K$28)>0)*1)+(LEN('Criação'!$K$33)>0)*1+SUMPRODUCT((LEN('Criação'!$K$44:$K$51)>0)*1)+(LEN('Criação'!$K$54)>0)*1+(LEN('Criação'!$K$60)>0)*1+(LEN('Criação'!$K$65)>0)*1+(LEN('Criação'!$K$67)>0)*1+SUMPRODUCT((LEN('Criação'!$K$69:$K$73)>0)*1)+SUMPRODUCT((LEN('Criação'!$K$75:$K$82)>0)*1)+SUMPRODUCT((LEN('Criação'!$K$84:$K$88)>0)*1)+(LEN('Criação'!$K$91)>0)*1+SUMPRODUCT((LEN('Criação'!$K$97:$K$99)>0)*1)+SUMPRODUCT((LEN('Criação'!$K$107:$K$111)>0)*1)+SUMPRODUCT((LEN('Criação'!$K$113:$K$114)>0)*1)+SUMPRODUCT((LEN('Criação'!$K$116:$K$117)>0)*1) | C11: =IFERROR(INDEX('Criação'!$K$6:$K$10,MATCH("?*",'Criação'!$K$6:$K$10,0)),IFERROR(INDEX('Criação'!$K$20:$K$22,MATCH("?*",'Criação'!$K$20:$K$22,0)),IFERROR(INDEX('Criação'!$K$25:$K$28,MATCH("?*",'Criação'!$K$25:$K$28,0)),IFERROR(INDEX('Criação'!$K$33,MATCH("?*",'Criação'!$K$33,0)),IFERROR(INDEX('Criação'!$K$44:$K$51,MATCH("?*",'Criação'!$K$44:$K$51,0)),IFERROR(INDEX('Criação'!$K$54,MATCH("?*",'Criação'!$K$54,0)),IFERROR(INDEX('Criação'!$K$60,MATCH("?*",'Criação'!$K$60,0)),IFERROR(INDEX('Criação'!$K$65,MATCH("?*",'Criação'!$K$65,0)),IFERROR(INDEX('Criação'!$K$67,MATCH("?*",'Criação'!$K$67,0)),IFERROR(INDEX('Criação'!$K$69:$K$73,MATCH("?*",'Criação'!$K$69:$K$73,0)),IFERROR(INDEX('Criação'!$K$75:$K$82,MATCH("?*",'Criação'!$K$75:$K$82,0)),IFERROR(INDEX('Criação'!$K$84:$K$88,MATCH("?*",'Criação'!$K$84:$K$88,0)),IFERROR(INDEX('Criação'!$K$91,MATCH("?*",'Criação'!$K$91,0)),IFERROR(INDEX('Criação'!$K$97:$K$99,MATCH("?*",'Criação'!$K$97:$K$99,0)),IFERROR(INDEX('Criação'!$K$107:$K$111,MATCH("?*",'Criação'!$K$107:$K$111,0)),IFERROR(INDEX('Criação'!$K$113:$K$114,MATCH("?*",'Criação'!$K$113:$K$114,0)),IFERROR(INDEX('Criação'!$K$116:$K$117,MATCH("?*",'Criação'!$K$116:$K$117,0)),"")))))))))))))))))
A12: Em Jogo | B12: =SUMPRODUCT((LEN('Em Jogo'!$N$2:$N$20)>0)*1)+SUMPRODUCT((LEN('Em Jogo'!$N$33:$N$40)>0)*1) | C12: =IFERROR(INDEX('Em Jogo'!$N$2:$N$20,MATCH("?*",'Em Jogo'!$N$2:$N$20,0)),IFERROR(INDEX('Em Jogo'!$N$33:$N$40,MATCH("?*",'Em Jogo'!$N$33:$N$40,0)),""))
A13: Testes | B13: =SUMPRODUCT((LEN('Testes'!$K$40:$K$45)>0)*1)+SUMPRODUCT((LEN('Testes'!$L$16:$L$20)>0)*1)+SUMPRODUCT((LEN('Testes'!$L$22:$L$29)>0)*1)+SUMPRODUCT((LEN('Testes'!$L$31:$L$35)>0)*1) | C13: =IFERROR(INDEX('Testes'!$K$40:$K$45,MATCH("?*",'Testes'!$K$40:$K$45,0)),IFERROR(INDEX('Testes'!$L$16:$L$20,MATCH("?*",'Testes'!$L$16:$L$20,0)),IFERROR(INDEX('Testes'!$L$22:$L$29,MATCH("?*",'Testes'!$L$22:$L$29,0)),IFERROR(INDEX('Testes'!$L$31:$L$35,MATCH("?*",'Testes'!$L$31:$L$35,0)),""))))
A14: Habilidades | B14: =SUMPRODUCT((LEN('Habilidades'!$I$12:$I$19)>0)*1)+(LEN('Habilidades'!$K$54)>0)*1+SUMPRODUCT((LEN('Habilidades'!$K$57:$K$58)>0)*1)+SUMPRODUCT((LEN('Habilidades'!$L$7:$L$8)>0)*1)+SUMPRODUCT((LEN('Habilidades'!$L$55:$L$56)>0)*1)+(LEN('Habilidades'!$L$59)>0)*1 | C14: =IFERROR(INDEX('Habilidades'!$I$12:$I$19,MATCH("?*",'Habilidades'!$I$12:$I$19,0)),IFERROR(INDEX('Habilidades'!$K$54,MATCH("?*",'Habilidades'!$K$54,0)),IFERROR(INDEX('Habilidades'!$K$57:$K$58,MATCH("?*",'Habilidades'!$K$57:$K$58,0)),IFERROR(INDEX('Habilidades'!$L$7:$L$8,MATCH("?*",'Habilidades'!$L$7:$L$8,0)),IFERROR(INDEX('Habilidades'!$L$55:$L$56,MATCH("?*",'Habilidades'!$L$55:$L$56,0)),IFERROR(INDEX('Habilidades'!$L$59,MATCH("?*",'Habilidades'!$L$59,0)),""))))))
A15: Caminho | B15: =SUMPRODUCT((LEN('Caminho'!$K$27:$K$36)>0)*1)+SUMPRODUCT((LEN('Caminho'!$K$54:$K$58)>0)*1)+SUMPRODUCT((LEN('Caminho'!$K$60:$K$67)>0)*1)+SUMPRODUCT((LEN('Caminho'!$K$69:$K$73)>0)*1)+SUMPRODUCT((LEN('Caminho'!$K$75:$K$78)>0)*1)+SUMPRODUCT((LEN('Caminho'!$K$95:$K$96)>0)*1) | C15: =IFERROR(INDEX('Caminho'!$K$27:$K$36,MATCH("?*",'Caminho'!$K$27:$K$36,0)),IFERROR(INDEX('Caminho'!$K$54:$K$58,MATCH("?*",'Caminho'!$K$54:$K$58,0)),IFERROR(INDEX('Caminho'!$K$60:$K$67,MATCH("?*",'Caminho'!$K$60:$K$67,0)),IFERROR(INDEX('Caminho'!$K$69:$K$73,MATCH("?*",'Caminho'!$K$69:$K$73,0)),IFERROR(INDEX('Caminho'!$K$75:$K$78,MATCH("?*",'Caminho'!$K$75:$K$78,0)),IFERROR(INDEX('Caminho'!$K$95:$K$96,MATCH("?*",'Caminho'!$K$95:$K$96,0)),""))))))
A16: Equipamento | B16: =SUMPRODUCT((LEN('Equipamento'!$I$45:$I$47)>0)*1)+(LEN('Equipamento'!$K$8)>0)*1+(LEN('Equipamento'!$K$18)>0)*1+(LEN('Equipamento'!$K$21)>0)*1+(LEN('Equipamento'!$K$58)>0)*1+SUMPRODUCT((LEN('Equipamento'!$K$60:$K$69)>0)*1)+SUMPRODUCT((LEN('Equipamento'!$K$71:$K$80)>0)*1)+(LEN('Equipamento'!$K$84)>0)*1+SUMPRODUCT((LEN('Equipamento'!$K$86:$K$96)>0)*1)+SUMPRODUCT((LEN('Equipamento'!$L$19:$L$20)>0)*1)+SUMPRODUCT((LEN('Equipamento'!$L$22:$L$24)>0)*1)+SUMPRODUCT((LEN('Equipamento'!$L$36:$L$41)>0)*1)+(LEN('Equipamento'!$L$48)>0)*1 | C16: =IFERROR(INDEX('Equipamento'!$I$45:$I$47,MATCH("?*",'Equipamento'!$I$45:$I$47,0)),IFERROR(INDEX('Equipamento'!$K$8,MATCH("?*",'Equipamento'!$K$8,0)),IFERROR(INDEX('Equipamento'!$K$18,MATCH("?*",'Equipamento'!$K$18,0)),IFERROR(INDEX('Equipamento'!$K$21,MATCH("?*",'Equipamento'!$K$21,0)),IFERROR(INDEX('Equipamento'!$K$58,MATCH("?*",'Equipamento'!$K$58,0)),IFERROR(INDEX('Equipamento'!$K$60:$K$69,MATCH("?*",'Equipamento'!$K$60:$K$69,0)),IFERROR(INDEX('Equipamento'!$K$71:$K$80,MATCH("?*",'Equipamento'!$K$71:$K$80,0)),IFERROR(INDEX('Equipamento'!$K$84,MATCH("?*",'Equipamento'!$K$84,0)),IFERROR(INDEX('Equipamento'!$K$86:$K$96,MATCH("?*",'Equipamento'!$K$86:$K$96,0)),IFERROR(INDEX('Equipamento'!$L$19:$L$20,MATCH("?*",'Equipamento'!$L$19:$L$20,0)),IFERROR(INDEX('Equipamento'!$L$22:$L$24,MATCH("?*",'Equipamento'!$L$22:$L$24,0)),IFERROR(INDEX('Equipamento'!$L$36:$L$41,MATCH("?*",'Equipamento'!$L$36:$L$41,0)),IFERROR(INDEX('Equipamento'!$L$48,MATCH("?*",'Equipamento'!$L$48,0)),"")))))))))))))
A17: Progressão | B17: =SUMPRODUCT((LEN('Progressão'!$H$57:$H$62)>0)*1)+SUMPRODUCT((LEN('Progressão'!$I$67:$I$70)>0)*1) | C17: =IFERROR(INDEX('Progressão'!$H$57:$H$62,MATCH("?*",'Progressão'!$H$57:$H$62,0)),IFERROR(INDEX('Progressão'!$I$67:$I$70,MATCH("?*",'Progressão'!$I$67:$I$70,0)),""))
A18: Total | B18: =SUM(B11:B17) | C18: =IF(B18=0,"Nenhum aviso: a ficha está conferida.","Abra a aba indicada e leia a coluna Aviso (na Em Jogo, a linha 13).")
A19: Células com erro na ficha | B19: =SUM($B$21:$K$21) | C19: =IF($B$19=0,"Nenhuma célula com erro.","O Google leu como fórmula um texto que começa com +, - ou =. Procure a célula com erro na aba indicada abaixo (o aviso da linha diz o que fazer), apague e escreva de novo com um apóstrofo (') na frente, ou escolha de novo na lista.")
A20: Erros por aba | B20: Início | C20: Criação | D20: Em Jogo | E20: Testes | F20: Habilidades | G20: Caminho | H20: Equipamento | I20: Progressão | J20: Regras Rápidas | K20: Dados
A21: Células com erro | B21: =SUMPRODUCT(ISERROR($A$1:$L$18)*1)+SUMPRODUCT(ISERROR($A$22:$L$53)*1) | C21: =SUMPRODUCT(ISERROR('Criação'!$A$1:$T$126)*1) | D21: =SUMPRODUCT(ISERROR('Em Jogo'!$A$1:$AP$44)*1) | E21: =SUMPRODUCT(ISERROR('Testes'!$A$1:$O$47)*1) | F21: =SUMPRODUCT(ISERROR('Habilidades'!$A$1:$AF$63)*1) | G21: =SUMPRODUCT(ISERROR('Caminho'!$A$1:$T$96)*1) | H21: =SUMPRODUCT(ISERROR('Equipamento'!$A$1:$AM$97)*1) | I21: =SUMPRODUCT(ISERROR('Progressão'!$A$1:$W$88)*1) | J21: =SUMPRODUCT(ISERROR('Regras Rápidas'!$A$1:$L$119)*1) | K21: =SUMPRODUCT(ISERROR('Dados'!$A$1:$AT$595)*1)
A23: Como usar em 6 passos
A24: 1. Criação: preencha as células amarelas de cima para baixo — são os 12 passos do capítulo 03.
A25: 2. Caminho: escolha as Bênçãos nos slots liberados (e monte o Memoespírito, se for A Recordação).
A26: 3. Habilidades: escreva as suas Habilidades e a Ultimate; a ficha calcula dados, média, PH e rolagem.
A27: 4. Equipamento: Cone de Luz, Relíquias, Conjuntos, arma secundária, inventário e Créditos.
A28: 5. Progressão: a cada nível, mude o Nível atual na Criação e preencha os aumentos e as Ressonâncias.
A29: 6. Em Jogo: na mesa, use só esta aba — PV, Energia, PH, condições, usos e a calculadora de dano.
A31: Legenda de cores (a cor nunca é o único sinal: o texto diz)
A32: Entrada (preencha) | B32: Fundo amarelo com borda: é você quem preenche. Toda entrada sai vazia no arquivo.
A33: Calculada (automático) | B33: Fundo azul-claro: fórmula. Não edite (veja a proteção abaixo).
A34: Aviso | B34: Texto vermelho em fundo rosa: alguma regra do livro não fechou. O texto diz o quê.
A35: Título de bloco | B35: Faixa azul-escura: começo de um bloco, com o capítulo do livro.
A36: Não se aplica | B36: Cinza: não vale para o seu personagem (ou é coluna auxiliar).
A38: Como importar no Google Planilhas
A39: 1. Envie o arquivo .xlsx para o seu Google Drive.
A40: 2. Clique com o botão direito no arquivo → Abrir com → Planilhas Google.
A41: 3. No Planilhas: Arquivo → Salvar como Planilhas Google. Use essa cópia (a original continua .xlsx).
A42: 4. Confira o Painel de avisos acima: com a ficha em branco ele mostra zero avisos.
A43: 5. Para esconder a aba Dados: clique com o botão direito na aba Dados → Ocultar página. Não apague a aba Dados: as fórmulas leem dela.
A45: Como proteger as fórmulas (proteção nativa do Google, sem senha)
A46: 1. Dados → Proteger páginas e intervalos → Adicionar uma página ou um intervalo.
...

Sheet Criação
A1: Criação — Explorando Galáxias v1.1
A2: Legenda: | B2: Entrada (preencha) | C2: Calculada (automático) | E2: Aviso (texto em vermelho) | G2: Título de bloco | H2: Cabeçalho de coluna | I2: Rótulo da linha | J2: Linha alternada (outro tom) | L2: Não se aplica
A3: Os 12 passos do capítulo 03, de cima para baixo.
N4: Listas auxiliares
A5: Personagem
A6: Nome do personagem | K6: =IF(T6>0,"O Google leu como fórmula: digite de novo com ' na frente.","") | Q6: =IF(ISERROR($B$6),"",IF(ISBLANK($B$6),"",$B$6)) | T6: =ISERROR($B$6)*1
A7: Jogador | K7: =IF(T7>0,"O Google leu como fórmula: digite de novo com ' na frente.","") | T7: =ISERROR($B$7)*1
A8: Nível atual (1 a 20) | C8: ="Usado nas contas: nível "&$A$14 | K8: =IF(T8>0,"O Google leu como fórmula: digite de novo com ' na frente.",IF($Q$8="","",IF(ISNUMBER($Q$8),IF(OR($Q$8<1,$Q$8>20),"Nível fora de 1 a 20: a ficha conta com o nível "&$A$14,IF($Q$8<>INT($Q$8),"Nível precisa ser inteiro: a ficha conta com o nível "&$A$14,"")),"Nível precisa ser um número de 1 a 20: a ficha conta com o nível 1"))) | Q8: =IF(ISERROR($B$8),"",IF(ISBLANK($B$8),"",$B$8)) | T8: =ISERROR($B$8)*1
A9: Nº de jogadores na mesa | C9: ="PH do grupo: máximo "&$E$16&", começa o combate com "&$F$16 | K9: =IF(T9>0,"O Google leu como fórmula: digite de novo com ' na frente.",IF($Q$9="","",IF(ISNUMBER($Q$9),IF(OR($Q$9<1,$Q$9>6),"Nº de jogadores fora de 1 a 6: a ficha conta com "&$B$17,IF(OR($Q$9<3,$Q$9>6),"Fora da tabela do livro (3 a 6 jogadores): o PH segue a mesma regra","")),"Nº de jogadores precisa ser um número de 1 a 6"))) | Q9: =IF(ISERROR($B$9),"",IF(ISBLANK($B$9),"",$B$9)) | T9: =ISERROR($B$9)*1
A10: Método de atributos (o Mestre escolhe) | C10: =IF($Q$10="","Array oficial (15, 14, 13, 12, 10, 8) ou Compra de Pontos (28)",IF($Q$10="Array oficial","Distribua 15, 14, 13, 12, 10 e 8, um em cada Atributo","Todos começam em 8; gaste até 28 pontos")) | K10: =IF(T10>0,"O Google leu como fórmula: escolha de novo na lista.",IF($Q$10="","",IF(COUNTIF('Dados'!$AH$6:$AH$7,$Q$10)=0,"Método fora da lista",""))) | Q10: =IF(ISERROR($B$10),"",IF(ISBLANK($B$10),"",$B$10)) | T10: =ISERROR($B$10)*1
A12: Números do seu nível (automático) — 26.2 a 26.6
A13: Nível usado | B13: Faixa (1 a 5) | C13: Eficiência | D13: Eficácia | E13: Slots de Eficácia em Perícias | F13: Slots de Eficácia em Testes de Resistência | G13: Especialização de Combate | H13: Teto de RD | I13: Teto de PV temporários | J13: Teto de bônus somado | K13: Teto de penalidade somada | L13: Bênçãos possuídas
A14: =IF(ISNUMBER($Q$8),MAX(1,MIN(20,INT($Q$8))),1) | B14: =INT(($A$14-1)/4)+1 | C14: =2+INT(($A$14-1)/3) | D14: =2*$C$14 | E14: =INDEX('Dados'!$C$258:$C$277,$A$14) | F14: =INDEX('Dados'!$D$258:$D$277,$A$14) | G14: =INDEX('Dados'!$K$258:$K$277,$A$14) | H14: =INDEX('Dados'!$L$258:$L$277,$A$14) | I14: =3*$C$14 | J14: =IF($A$14<=9,3,IF($A$14<=15,4,5)) | K14: =-$J$14 | L14: =INDEX('Dados'!$E$258:$E$277,$A$14)
A15: Habilidades conhecidas | B15: Nível máx. de Habilidade | C15: Reescreve 1 Habilidade por nível | D15: Dados de Ataque Básico | E15: PH do grupo: máximo | F15: PH do grupo: início | G15: PH por Ataque Básico que acerta | H15: Ultimate: Nível equivalente | I15: Cone de Luz: Nível máximo | J15: Tier de Relíquia (1 a 4) | K15: Pontos do Memoespírito | L15: DT para descobrir Fraqueza
A16: =INDEX('Dados'!$F$258:$F$277,$A$14) | B16: =INDEX('Dados'!$H$258:$H$277,$A$14) | C16: =INDEX('Dados'!$G$258:$G$277,$A$14) | D16: =INDEX('Dados'!$J$258:$J$277,$A$14) | E16: =1+$B$17+IF($A$14>=17,2,IF($A$14>=9,1,0)) | F16: =$E$16-2 | G16: =IF($A$14<=8,1,2) | H16: =INDEX('Dados'!$B$326:$B$330,$B$14) | I16: =$B$14 | J16: =IF($A$14<=6,1,IF($A$14<=12,2,IF($A$14<=17,3,4))) | K16: =12+INT($A$14/2) | L16: =INDEX('Dados'!$B$390:$B$394,$B$14)
A17: Nº de jogadores usado (vazio = 4) | B17: =IF(ISNUMBER($Q$9),MAX(1,MIN(6,INT($Q$9))),4) | C17: Aumento de Atributo neste nível? | E17: =INDEX('Dados'!$I$258:$I$277,$A$14)
A19: Passo 1 — Conceito e Propósito de Vida
A20: Quem é esse sujeito? (conceito em uma frase) | K20: =IF(T20>0,"O Google leu como fórmula: digite de novo com ' na frente.","") | T20: =ISERROR($B$20)*1
A21: Propósito de Vida (objetivo de longo prazo) | K21: =IF(T21>0,"O Google leu como fórmula: digite de novo com ' na frente.","") | T21: =ISERROR($B$21)*1
A22: Em que você acredita (recarrega o Esforço; só Humano) | K22: =IF(T22>0,"O Google leu como fórmula: digite de novo com ' na frente.",IF(AND($Q$25<>"Humano",LEN($Q$22)>0),"O Esforço é traço do Humano: esta linha só vale para Humano","")) | Q22: =IF(ISERROR($B$22),"",IF(ISBLANK($B$22),"",$B$22)) | T22: =ISERROR($B$22)*1
A24: Passo 2 — Raça (capítulo 05)
A25: Raça | C25: =IF($Q$25="","Escolha a Raça",IF($Q$25="Humano",IF($Q$26="Dois Atributos (+1 cada)","Bônus racial: +1 em "&IF($Q$27="","?",$Q$27)&" e +1 em "&IF($Q$28="","?",$Q$28),IF($Q$27="","Escolha onde vai o +2 (qualquer Atributo)","Bônus racial: +2 em "&$Q$27)),IF($O$25="","Raça fora da lista do capítulo 05",IF($O$27="","Escolha onde vai o +2: "&$O$25&" ou "&$O$26,"Bônus racial: +2 em "&$O$27)))) | K25: =IF(T25>0,"O Google leu como fórmula: escolha de novo na lista.",IF($Q$25="","",IF(COUNTIF('Dados'!$O$6:$O$12,$Q$25)=0,"Raça fora da lista do capítulo 05",""))) | N25: =IF($Q$25="Humano",INDEX('Dados'!$Q$6:$Q$11,1),$O$25) | O25: =IF($Q$25="","",IFERROR(""&INDEX('Dados'!$D$7:$D$13,MATCH($Q$25,'Dados'!$A$7:$A$13,0)),"")) | Q25: =IF(ISERROR($B$25),"",IF(ISBLANK($B$25),"",$B$25)) | T25: =ISERROR($B$25)*1
A26: Bônus do Humano: +2 em um ou +1 em dois | C26: Só para Humano. As outras Raças têm +2 fixo ou à escolha entre duas opções. | K26: =IF(T26>0,"O Google leu como fórmula: escolha de novo na lista.",IF(AND($Q$26<>"",$Q$25<>"Humano"),"O bônus livre é só do Humano","")) | N26: =IF($Q$25="Humano",INDEX('Dados'!$Q$6:$Q$11,2),$O$26) | O26: =IF($Q$25="","",IFERROR(""&INDEX('Dados'!$E$7:$E$13,MATCH($Q$25,'Dados'!$A$7:$A$13,0)),"")) | Q26: =IF(ISERROR($B$26),"",IF(ISBLANK($B$26),"",$B$26)) | T26: =ISERROR($B$26)*1
A27: Atributo do +2 (Humano com Dois Atributos: o 1º) | C27: A lista mostra só as opções da sua Raça. | K27: =IF(T27>0,"O Google leu como fórmula: escolha de novo na lista.",IF(AND($Q$25="Humano",$Q$26="Dois Atributos (+1 cada)",$Q$27<>"",$Q$27=$Q$28),"+1 em dois exige atributos diferentes: contou só um +1",IF(AND($Q$25<>"",$Q$25<>"Humano",$O$25<>"",$Q$27<>"",$O$27=""),"Bônus fora das opções da Raça: "&$O$25&IF($O$26="",""," ou "&$O$26),""))) | N27: =IF($Q$25="Humano",INDEX('Dados'!$Q$6:$Q$11,3),"") | O27: =IF(OR($Q$25="",$Q$25="Humano"),"",IF($O$26="",IF(OR($Q$27="",$Q$27=$O$25),$O$25,""),IF(OR($Q$27=$O$25,$Q$27=$O$26),$Q$27,""))) | Q27: =IF(ISERROR($B$27),"",IF(ISBLANK($B$27),"",$B$27)) | T27: =ISERROR($B$27)*1
A28: Atributo 2 (só Humano com Dois Atributos) | K28: =IF(T28>0,"O Google leu como fórmula: escolha de novo na lista.",IF(AND($Q$28<>"",OR($Q$25<>"Humano",$Q$26<>"Dois Atributos (+1 cada)")),"Atributo 2 só vale para Humano com Dois Atributos (+1 cada)","")) | N28: =IF($Q$25="Humano",INDEX('Dados'!$Q$6:$Q$11,4),"") | Q28: =IF(ISERROR($B$28),"",IF(ISBLANK($B$28),"",$B$28)) | T28: =ISERROR($B$28)*1
A29: Traços (resumo) | B29: =IF($Q$25="","",IFERROR(INDEX('Dados'!$F$7:$F$13,MATCH($Q$25,'Dados'!$A$7:$A$13,0)),"")) | N29: =IF($Q$25="Humano",INDEX('Dados'!$Q$6:$Q$11,5),"")
A30: Traços (texto inteiro do livro) | B30: =IF($Q$25="","",IFERROR(INDEX('Dados'!$G$7:$G$13,MATCH($Q$25,'Dados'!$A$7:$A$13,0)),"")) | N30: =IF($Q$25="Humano",INDEX('Dados'!$Q$6:$Q$11,6),"")
A32: Passo 3 — Caminho (capítulo 06)
A33: Caminho | C33: =IF($Q$33="","Escolha o Caminho","Aeon: "&IF($Q$33="","",IFERROR(INDEX('Dados'!$B$84:$B$92,MATCH($Q$33,'Dados'!$A$84:$A$92,0)),""))) | K33: =IF(T33>0,"O Google leu como fórmula: escolha de novo na lista.",IF($Q$33="","",IF(COUNTIF('Dados'!$P$6:$P$14,$Q$33)=0,"Caminho fora da lista do capítulo 06",""))) | Q33: =IF(ISERROR($B$33),"",IF(ISBLANK($B$33),"",$B$33)) | T33: =ISERROR($B$33)*1
A34: Aeon | B34: =IF($Q$33="","",IFERROR(INDEX('Dados'!$B$84:$B$92,MATCH($Q$33,'Dados'!$A$84:$A$92,0)),""))
A35: A ideia, em uma frase | B35: =IF($Q$33="","",IFERROR(INDEX('Dados'!$C$84:$C$92,MATCH($Q$33,'Dados'!$A$84:$A$92,0)),""))
A36: Índice de vitalidade N (entra no PV) | B36: =IF($Q$33="",0,IFERROR(INDEX('Dados'!$J$84:$J$92,MATCH($Q$33,'Dados'!$A$84:$A$92,0)),0))
A37: Bônus de Velocidade do Caminho | B37: =IF($Q$33="",0,IFERROR(INDEX('Dados'!$K$84:$K$92,MATCH($Q$33,'Dados'!$A$84:$A$92,0)),0))
A38: As 3 Perícias do Caminho (Eficiência de graça) | B38: =IF($Q$33="","",IFERROR(INDEX('Dados'!$G$84:$G$92,MATCH($Q$33,'Dados'!$A$84:$A$92,0)),"")) | D38: =IF($Q$33="","",IFERROR(INDEX('Dados'!$H$84:$H$92,MATCH($Q$33,'Dados'!$A$84:$A$92,0)),"")) | F38: =IF($Q$33="","",IFERROR(INDEX('Dados'!$I$84:$I$92,MATCH($Q$33,'Dados'!$A$84:$A$92,0)),""))
A39: Atributo de Habilidade que o Caminho permite | B39: =IF($Q$33="","",IFERROR(INDEX('Dados'!$D$84:$D$92,MATCH($Q$33,'Dados'!$A$84:$A$92,0)),""))
A40: Recurso próprio (detalhes na aba Caminho) | B40: =IF($Q$33="","",IFERROR(INDEX('Dados'!$L$84:$L$92,MATCH($Q$33,'Dados'!$A$84:$A$92,0)),""))
A42: Passo 4 — Atributos (teto 15 antes da Raça; teto 20 sempre)
A43: Atributo | B43: Distribuído (preencha) | C43: Raça (automático) | D43: Aumentos (aba Progressão) | E43: Valor atual | F43: Bônus atual | G43: Valor na criação (com Raça) | H43: Bônus na criação | I43: Custo na Compra de Pontos | J43: Valor usado (8 a 20) | K43: Aviso
A44: Poder | C44: =IF($Q$25="Humano",IF($Q$26="Dois Atributos (+1 cada)",($Q$27="Poder")*1+AND($Q$28="Poder",$Q$28<>$Q$27)*1,($Q$27="Poder")*2),IF($O$27="Poder",2,0)) | D44: =SUMIF('Progressão'!$U$57:$U$62,"Poder",'Progressão'!$F$57:$F$62)+SUMIF('Progressão'!$V$57:$V$62,"Poder",'Progressão'!$G$57:$G$62) | E44: =MIN(20,$J$44+$C$44+$D$44) | F44: =IF($E$44<15,VLOOKUP($E$44,'Dados'!$A$27:$B$39,2,FALSE),INT(($E$44-15)/2)+3) | G44: =MIN(20,$J$44+$C$44) | H44: =IF($G$44<15,VLOOKUP($G$44,'Dados'!$A$27:$B$39,2,FALSE),INT(($G$44-15)/2)+3) | I44: =IF($Q$10="Compra de Pontos",VLOOKUP(MAX(8,MIN(15,$J$44)),'Dados'!$A$43:$B$50,2,FALSE),"") | J44: =IF(ISNUMBER($Q$44),MAX(8,MIN(20,INT($Q$44))),8) | K44: =IF(T44>0,"O Google leu como fórmula: digite de novo com ' na frente.",IF($Q$44="","",IF(ISNUMBER($Q$44),IF(OR($Q$44<8,$Q$44>20),"Fora de 8 a 20: a ficha conta com "&$J$44&". ","")&IF($Q$44>15,"Acima de 15 antes da Raça. ",""),"Precisa ser um número. "))&IF(AND($D$44>0,$J$44+$C$44+$D$44>20),"Aumento desperdiçado: passou do teto 20.","")) | Q44: =IF(ISERROR($B$44),"",IF(ISBLANK($B$44),"",$B$44)) | T44: =ISERROR($B$44)*1
A45: Agilidade | C45: =IF($Q$25="Humano",IF($Q$26="Dois Atributos (+1 cada)",($Q$27="Agilidade")*1+AND($Q$28="Agilidade",$Q$28<>$Q$27)*1,($Q$27="Agilidade")*2),IF($O$27="Agilidade",2,0)) | D45: =SUMIF('Progressão'!$U$57:$U$62,"Agilidade",'Progressão'!$F$57:$F$62)+SUMIF('Progressão'!$V$57:$V$62,"Agilidade",'Progressão'!$G$57:$G$62) | E45: =MIN(20,$J$45+$C$45+$D$45) | F45: =IF($E$45<15,VLOOKUP($E$45,'Dados'!$A$27:$B$39,2,FALSE),INT(($E$45-15)/2)+3) | G45: =MIN(20,$J$45+$C$45) | H45: =IF($G$45<15,VLOOKUP($G$45,'Dados'!$A$27:$B$39,2,FALSE),INT(($G$45-15)/2)+3) | I45: =IF($Q$10="Compra de Pontos",VLOOKUP(MAX(8,MIN(15,$J$45)),'Dados'!$A$43:$B$50,2,FALSE),"") | J45: =IF(ISNUMBER($Q$45),MAX(8,MIN(20,INT($Q$45))),8) | K45: =IF(T45>0,"O Google leu como fórmula: digite de novo com ' na frente.",IF($Q$45="","",IF(ISNUMBER($Q$45),IF(OR($Q$45<8,$Q$45>20),"Fora de 8 a 20: a ficha conta com "&$J$45&". ","")&IF($Q$45>15,"Acima de 15 antes da Raça. ",""),"Precisa ser um número. "))&IF(AND($D$45>0,$J$45+$C$45+$D$45>20),"Aumento desperdiçado: passou do teto 20.","")) | Q45: =IF(ISERROR($B$45),"",IF(ISBLANK($B$45),"",$B$45)) | T45: =ISERROR($B$45)*1
...

Sheet Em Jogo
A1: Resumo para o Jogador | E1: Recursos (preencha os amarelos) | I1: Calculadora de dano (23.1 e 23.3) | N1: Avisos desta aba (automático; o resumo aparece na linha 13) | P1: Valores auxiliares (automático) | S1: Usos (auxiliar): nome | T1: frequência | U1: entra? | V1: ordem | W1: Perícias (auxiliar) | AC1: Usos (auxiliar): frequência por linha
A2: Nome | B2: =IF(LEN('Criação'!$Q$6)=0,"(sem nome)",""&'Criação'!$Q$6) | E2: PV atual | G2: ="de "&'Criação'!$D$95&IF($Q$3="Sim"," · Morrendo"," · vazio = cheio") | I2: Dano recebido | K2: depois de dados e bônus | N2: =IF(AP2>0,"O Google leu como fórmula: digite de novo com ' na frente.",IF(LEN($AK$2)=0,"",IF(ISNUMBER($AK$2),IF($AK$2>'Criação'!$D$95,"PV atual acima do máximo ("&'Criação'!$D$95&"). ","")&IF($AK$2<0,"PV não fica abaixo de 0 (23.4). ",""),"PV atual precisa ser um número."))) | P2: PV atual usado (vazio = cheio) | Q2: =IF(ISNUMBER($AK$2),MAX(0,INT($AK$2)),'Criação'!$D$95) | S2: ="Descanso Curto" | T2: ="2/dia" | U2: =1 | V2: =IF(U2=1,0+1,0) | W2: Atletismo | X2: =0+IF('Criação'!$E$69="Sim",1,0) | Y2: =IF('Criação'!$E$69="Sim",X2,0) | Z2: ='Testes'!$I$16 | AA2: =IF(LEN('Testes'!$J$16)>0,"Vantagem","") | AB2: =IFERROR(INDEX($AA$2:$AA$19,MATCH(1,$Y$2:$Y$19,0)),"") | AC2: =IFERROR(INDEX($T$2:$T$16,MATCH(1,$V$2:$V$16,0)),"") | AD2: =IF($AF$37="","",IF($AF$37="Sangramento",IF(ISNUMBER($AI$37),MIN(INT('Criação'!$D$95*5/100),3*IF(ISNUMBER($AI$37),$AI$37,0))&" por turno","5% PV, teto 3×Ef"),IF($AF$37="Queimadura","2d6+"&IF(ISNUMBER($AI$37),IF(ISNUMBER($AI$37),$AI$37,0),"Ef"),IF(OR($AF$37="Choque",$AF$37="Aprisionamento"),"1d6+"&IF(ISNUMBER($AI$37),IF(ISNUMBER($AI$37),$AI$37,0),"Ef"),IF(OR($AF$37="Cisalhamento de Vento",$AF$37="Embaraço"),"1d6 por acúmulo",IF($AF$37="Surpreso","casa pulada no 1º Ciclo","—")))))) | AK2: =IF(ISERROR($F$2),"",IF(ISBLANK($F$2),"",$F$2)) | AO2: =IF(ISERROR($J$2),"",IF(ISBLANK($J$2),"",$J$2)) | AP2: =ISERROR($F$2)*1+ISERROR($J$2)*1
A3: Raça · Caminho | B3: =IF('Criação'!$Q$25="","Raça?",'Criação'!$Q$25)&" · "&IF('Criação'!$Q$33="","Caminho?",'Criação'!$Q$33)&" · nível "&'Criação'!$A$14 | E3: Temporários | G3: ="ou Barreira · teto "&'Criação'!$I$14&" · não acumulam" | I3: Contínuo? | K3: Contínuo ignora a RD | N3: =IF(AP3>0,"O Google leu como fórmula: escolha de novo ou digite com ' na frente.",IF(LEN($AK$3)=0,"",IF(ISNUMBER($AK$3),IF($AK$3>'Criação'!$I$14,"PV temporários acima do teto ("&'Criação'!$I$14&", 23.3): conta o teto.",""),"PV temporários precisa ser um número."))) | P3: Morrendo (PV 0) | Q3: =IF($Q$2=0,"Sim","Não") | S3: ="Técnica" | T3: ="2/Desc. Longo" | U3: =1 | V3: =IF(U3=1,MAX($V$2:V2)+1,0) | W3: Acrobacia | X3: =X2+IF('Criação'!$E$70="Sim",1,0) | Y3: =IF('Criação'!$E$70="Sim",X3,0) | Z3: ='Testes'!$I$17 | AA3: =IF(LEN('Testes'!$J$17)>0,"Vantagem","") | AB3: =IFERROR(INDEX($AA$2:$AA$19,MATCH(2,$Y$2:$Y$19,0)),"") | AC3: =IFERROR(INDEX($T$2:$T$16,MATCH(2,$V$2:$V$16,0)),"") | AD3: =IF($AF$38="","",IF($AF$38="Sangramento",IF(ISNUMBER($AI$38),MIN(INT('Criação'!$D$95*5/100),3*IF(ISNUMBER($AI$38),$AI$38,0))&" por turno","5% PV, teto 3×Ef"),IF($AF$38="Queimadura","2d6+"&IF(ISNUMBER($AI$38),IF(ISNUMBER($AI$38),$AI$38,0),"Ef"),IF(OR($AF$38="Choque",$AF$38="Aprisionamento"),"1d6+"&IF(ISNUMBER($AI$38),IF(ISNUMBER($AI$38),$AI$38,0),"Ef"),IF(OR($AF$38="Cisalhamento de Vento",$AF$38="Embaraço"),"1d6 por acúmulo",IF($AF$38="Surpreso","casa pulada no 1º Ciclo","—")))))) | AK3: =IF(ISERROR($F$3),"",IF(ISBLANK($F$3),"",$F$3)) | AO3: =IF(ISERROR($J$3),"",IF(ISBLANK($J$3),"",$J$3)) | AP3: =ISERROR($F$3)*1+ISERROR($J$3)*1
A4: Elemento | B4: =IF('Criação'!$Q$60="","—",'Criação'!$Q$60)&" (Ataque Básico: "&'Criação'!$D$110&")" | E4: Energia | G4: ="0 a 100 · Ultimate pronta: "&IF($Q$22="Sim","Sim","Não ("&'Habilidades'!$G$61&")") | I4: RD aplicada | J4: =IF($AO$3="Sim",0,'Criação'!$D$98) | N4: =IF(AP4>0,"O Google leu como fórmula: digite de novo com ' na frente.",IF(LEN($AK$4)=0,"",IF(ISNUMBER($AK$4),IF($AK$4>100,"Energia acima de 100 é perdida (17.1).","")&IF($AK$4<0,"Energia não fica abaixo de 0.",""),"Energia precisa ser um número."))) | P4: PV temporários usados (teto) | Q4: =IF(ISNUMBER($AK$3),MAX(0,MIN('Criação'!$I$14,INT($AK$3))),0) | S4: ="To na sua mente" | T4: ="2/dia" | U4: =IF('Criação'!$Q$25="Haloviano",1,0) | V4: =IF(U4=1,MAX($V$2:V3)+1,0) | W4: Furtividade | X4: =X3+IF('Criação'!$E$71="Sim",1,0) | Y4: =IF('Criação'!$E$71="Sim",X4,0) | Z4: ='Testes'!$I$18 | AA4: =IF(LEN('Testes'!$J$18)>0,"Vantagem","") | AB4: =IFERROR(INDEX($AA$2:$AA$19,MATCH(3,$Y$2:$Y$19,0)),"") | AC4: =IFERROR(INDEX($T$2:$T$16,MATCH(3,$V$2:$V$16,0)),"") | AD4: =IF($AF$39="","",IF($AF$39="Sangramento",IF(ISNUMBER($AI$39),MIN(INT('Criação'!$D$95*5/100),3*IF(ISNUMBER($AI$39),$AI$39,0))&" por turno","5% PV, teto 3×Ef"),IF($AF$39="Queimadura","2d6+"&IF(ISNUMBER($AI$39),IF(ISNUMBER($AI$39),$AI$39,0),"Ef"),IF(OR($AF$39="Choque",$AF$39="Aprisionamento"),"1d6+"&IF(ISNUMBER($AI$39),IF(ISNUMBER($AI$39),$AI$39,0),"Ef"),IF(OR($AF$39="Cisalhamento de Vento",$AF$39="Embaraço"),"1d6 por acúmulo",IF($AF$39="Surpreso","casa pulada no 1º Ciclo","—")))))) | AK4: =IF(ISERROR($F$4),"",IF(ISBLANK($F$4),"",$F$4)) | AP4: =ISERROR($F$4)*1
A5: PV | B5: =$Q$2&" / "&'Criação'!$D$95&IF($Q$4>0," (+"&$Q$4&" temporários)","")&IF($Q$3="Sim"," · Morrendo","") | E5: PH do grupo | G5: ="máx "&'Criação'!$E$16&" · início "&'Criação'!$F$16&" · +"&'Criação'!$G$16&" por acerto" | I5: Após a RD | J5: =IF(ISNUMBER($AO$2),IF($AO$2<=0,0,MAX(1,$AO$2-$J$4)),0) | K5: mínimo 1 | N5: =IF(AP5>0,"O Google leu como fórmula: digite de novo com ' na frente.",IF(LEN($AK$5)=0,"",IF(ISNUMBER($AK$5),IF($AK$5>'Criação'!$E$16,"PH acima do máximo do grupo ("&'Criação'!$E$16&", 16.2).",""),"PH precisa ser um número."))) | P5: Energia usada (0 a 100) | Q5: =IF(ISNUMBER($AK$4),MAX(0,MIN(100,INT($AK$4))),0) | S5: ="Efeito do Cone de Luz" | T5: =IF('Equipamento'!$P$28=1,"1/combate","1/Ciclo") | U5: =IF('Equipamento'!$P$28>0,1,0) | V5: =IF(U5=1,MAX($V$2:V4)+1,0) | W5: Pilotagem | X5: =X4+IF('Criação'!$E$72="Sim",1,0) | Y5: =IF('Criação'!$E$72="Sim",X5,0) | Z5: ='Testes'!$I$19 | AA5: =IF(LEN('Testes'!$J$19)>0,"Vantagem","") | AB5: =IFERROR(INDEX($AA$2:$AA$19,MATCH(4,$Y$2:$Y$19,0)),"") | AC5: =IFERROR(INDEX($T$2:$T$16,MATCH(4,$V$2:$V$16,0)),"") | AD5: =IF($AF$40="","",IF($AF$40="Sangramento",IF(ISNUMBER($AI$40),MIN(INT('Criação'!$D$95*5/100),3*IF(ISNUMBER($AI$40),$AI$40,0))&" por turno","5% PV, teto 3×Ef"),IF($AF$40="Queimadura","2d6+"&IF(ISNUMBER($AI$40),IF(ISNUMBER($AI$40),$AI$40,0),"Ef"),IF(OR($AF$40="Choque",$AF$40="Aprisionamento"),"1d6+"&IF(ISNUMBER($AI$40),IF(ISNUMBER($AI$40),$AI$40,0),"Ef"),IF(OR($AF$40="Cisalhamento de Vento",$AF$40="Embaraço"),"1d6 por acúmulo",IF($AF$40="Surpreso","casa pulada no 1º Ciclo","—")))))) | AK5: =IF(ISERROR($F$5),"",IF(ISBLANK($F$5),"",$F$5)) | AP5: =ISERROR($F$5)*1
A6: Defesa · Esquiva | B6: ='Criação'!$D$96&IF($Q$16>'Criação'!$D$96," ("&$Q$16&" com temporários)","")&" · Esquiva "&IF(ISNUMBER('Criação'!$D$97),'Criação'!$D$97,"proibida") | E6: Esforço | G6: =IF('Criação'!$Q$25="Humano","máx 1 · volta no Descanso Longo","só para Humano") | I6: Absorvido | J6: =MIN($Q$4,$J$5) | K6: pelos temporários | N6: =IF(AP6>0,"O Google leu como fórmula: digite de novo com ' na frente.",IF(LEN($AK$6)=0,"",IF(ISNUMBER($AK$6),IF('Criação'!$Q$25<>"Humano","O Esforço é traço do Humano (05). ","")&IF($AK$6>1,"Esforço máximo 1 (05).",""),"Esforço precisa ser um número."))) | P6: Memoespírito ativo (só A Recordação) | Q6: =IF(AND($AK$7="Sim",'Criação'!$Q$33="A Recordação"),"Sim","Não") | S6: ="Corda de Ligação" | T6: ="1/combate" | U6: =IF('Equipamento'!$G$41>0,1,0) | V6: =IF(U6=1,MAX($V$2:V5)+1,0) | W6: Resistência | X6: =X5+IF('Criação'!$E$73="Sim",1,0) | Y6: =IF('Criação'!$E$73="Sim",X6,0) | Z6: ='Testes'!$I$20 | AA6: =IF(LEN('Testes'!$J$20)>0,"Vantagem","") | AB6: =IFERROR(INDEX($AA$2:$AA$19,MATCH(5,$Y$2:$Y$19,0)),"") | AC6: =IFERROR(INDEX($T$2:$T$16,MATCH(5,$V$2:$V$16,0)),"") | AK6: =IF(ISERROR($F$6),"",IF(ISBLANK($F$6),"",$F$6)) | AP6: =ISERROR($F$6)*1
A7: RD · Velocidade | B7: ="RD "&'Criação'!$D$98&" · VEL "&'Criação'!$D$99 | E7: Memoespírito | G7: =IF('Criação'!$Q$33="A Recordação","PV dele (máx "&'Caminho'!$B$80&")","só A Recordação") | I7: PV perdidos | J7: =$J$5-$J$6 | N7: =IF(AP7>0,"O Google leu como fórmula: escolha de novo ou digite com ' na frente.",IF(AND(OR($AK$7="Sim",LEN($AM$7)>0),'Criação'!$Q$33<>"A Recordação"),"Memoespírito só na Recordação: não conta. ","")&IF(LEN($AM$7)=0,"",IF(ISNUMBER($AM$7),IF(AND('Criação'!$Q$33="A Recordação",$AM$7>'Caminho'!$B$80),"PV do Memoespírito acima do máximo ("&'Caminho'!$B$80&"). ",""),"PV do Memoespírito precisa ser um número."))) | P7: Fúria (Sacrifício Desesperado, máx. 2) | Q7: =IF($G$8="Fúria",MIN(2,IF(ISNUMBER($AK$8),MAX(0,INT($AK$8)),0)),0) | S7: =""&'Caminho'!$I$27 | T7: =IF('Caminho'!$H$27="Uma vez por turno","1/turno",IF('Caminho'!$H$27="Uma vez por Ciclo","1/Ciclo",IF('Caminho'!$H$27="Uma vez por combate por alvo","1/combate/alvo",IF('Caminho'!$H$27="Uma vez por combate","1/combate",IF('Caminho'!$H$27="Uma vez por Descanso Longo","1/Desc. Longo",IF('Caminho'!$H$27="Uma vez por sessão","1/sessão",IF('Caminho'!$H$27="Duas vezes por dia","2/dia",""&'Caminho'!$H$27))))))) | U7: =IF(AND(LEN('Caminho'!$I$27)>0,LEN('Caminho'!$H$27)>0,'Caminho'!$H$27<>"Sem limite declarado"),1,0) | V7: =IF(U7=1,MAX($V$2:V6)+1,0) | W7: Tecnologia | X7: =X6+IF('Criação'!$E$75="Sim",1,0) | Y7: =IF('Criação'!$E$75="Sim",X7,0) | Z7: ='Testes'!$I$22 | AA7: =IF(LEN('Testes'!$J$22)>0,"Vantagem","") | AB7: =IFERROR(INDEX($AA$2:$AA$19,MATCH(6,$Y$2:$Y$19,0)),"") | AC7: =IFERROR(INDEX($T$2:$T$16,MATCH(6,$V$2:$V$16,0)),"") | AK7: =IF(ISERROR($F$7),"",IF(ISBLANK($F$7),"",$F$7)) | AM7: =IF(ISERROR($H$7),"",IF(ISBLANK($H$7),"",$H$7)) | AP7: =ISERROR($F$7)*1+ISERROR($H$7)*1
A8: DT das Habilidades | B8: ='Criação'!$B$56&" · ataque de Habilidade "&'Criação'!$C$57 | E8: Acúmulos | G8: =IF((COUNTIF('Caminho'!$I$27:$I$36,"Sacrifício Desesperado")>0),"Fúria",IF((COUNTIF('Caminho'!$I$27:$I$36,"Florescimento da Alma")>0),"Florescimento",IF((COUNTIF('Caminho'!$I$27:$I$36,"Memória Devastadora")>0),"Fragmentos de Memória",IF('Criação'!$Q$33="A Erudição","Acúmulos de Cálculo","—")))) | H8: =IF($G$8="—","sem acúmulo","máx "&IF($G$8="Fúria",2,IF($G$8="Acúmulos de Cálculo",IF((COUNTIF('Caminho'!$I$27:$I$36,"Teto Rompido")>0),7,5),IF($G$8="—",0,5)))) | I8: PV novo | J8: =MAX(0,$Q$2-$J$7) | K8: ="PV novo: "&$J$8&" · temp. "&($Q$4-$J$6) | N8: =IF(AP8>0,"O Google leu como fórmula: digite de novo com ' na frente.",IF(LEN($AK$8)=0,"",IF(ISNUMBER($AK$8),IF($G$8="—","Nenhuma Bênção sua tem acúmulo neste campo.",IF($AK$8>IF($G$8="Fúria",2,IF($G$8="Acúmulos de Cálculo",IF((COUNTIF('Caminho'!$I$27:$I$36,"Teto Rompido")>0),7,5),IF($G$8="—",0,5))),"Máximo "&IF($G$8="Fúria",2,IF($G$8="Acúmulos de Cálculo",IF((COUNTIF('Caminho'!$I$27:$I$36,"Teto Rompido")>0),7,5),IF($G$8="—",0,5)))&" acúmulos de "&$G$8&".","")),"Acúmulos precisa ser um número."))) | P8: Florescimento (máx. 5) | Q8: =IF($G$8="Florescimento",MIN(5,IF(ISNUMBER($AK$8),MAX(0,INT($AK$8)),0)),0) | S8: =""&'Caminho'!$I$28 | T8: =IF('Caminho'!$H$28="Uma vez por turno","1/turno",IF('Caminho'!$H$28="Uma vez por Ciclo","1/Ciclo",IF('Caminho'!$H$28="Uma vez por combate por alvo","1/combate/alvo",IF('Caminho'!$H$28="Uma vez por combate","1/combate",IF('Caminho'!$H$28="Uma vez por Descanso Longo","1/Desc. Longo",IF('Caminho'!$H$28="Uma vez por sessão","1/sessão",IF('Caminho'!$H$28="Duas vezes por dia","2/dia",""&'Caminho'!$H$28))))))) | U8: =IF(AND(LEN('Caminho'!$I$28)>0,LEN('Caminho'!$H$28)>0,'Caminho'!$H$28<>"Sem limite declarado"),1,0) | V8: =IF(U8=1,MAX($V$2:V7)+1,0) | W8: Pesquisa | X8: =X7+IF('Criação'!$E$76="Sim",1,0) | Y8: =IF('Criação'!$E$76="Sim",X8,0) | Z8: ='Testes'!$I$23 | AA8: =IF(LEN('Testes'!$J$23)>0,"Vantagem","") | AB8: =IFERROR(INDEX($AA$2:$AA$19,MATCH(7,$Y$2:$Y$19,0)),"") | AC8: =IFERROR(INDEX($T$2:$T$16,MATCH(7,$V$2:$V$16,0)),"") | AK8: =IF(ISERROR($F$8),"",IF(ISBLANK($F$8),"",$F$8)) | AP8: =ISERROR($F$8)*1
A9: Melhor ataque | B9: =IF('Criação'!$Q$108="","Habilidades "&'Criação'!$C$57,"Ataque Básico "&'Equipamento'!$B$13&" · "&'Equipamento'!$C$13&" (média "&'Equipamento'!$D$13&")") | E9: Marcas | G9: =IF((COUNTIF('Caminho'!$I$27:$I$36,"Cicatriz da Destruição")>0),"Marcas da Ruína","—") | H9: =IF($G$9="—","sem acúmulo","máx 5") | I9: =IF($J$5=0,"Preencha o dano para ver o resultado",IF($Q$3="Sim","Já Morrendo: 1 falha (2 se crítico ou Nível 5+)",IF($J$8=0,"Cai a 0 PV: fica Morrendo (23.4)","Continua de pé"))) | N9: =IF(AP9>0,"O Google leu como fórmula: digite de novo com ' na frente.",IF(LEN($AK$9)=0,"",IF(ISNUMBER($AK$9),IF($G$9="—","Nenhuma Bênção sua tem acúmulo neste campo.",IF($AK$9>5,"Máximo 5 Marcas da Ruína.","")),"Acúmulos precisa ser um número."))) | P9: Fragmentos de Memória (máx. 5) | Q9: =IF($G$8="Fragmentos de Memória",MIN(5,IF(ISNUMBER($AK$8),MAX(0,INT($AK$8)),0)),0) | S9: =""&'Caminho'!$I$29 | T9: =IF('Caminho'!$H$29="Uma vez por turno","1/turno",IF('Caminho'!$H$29="Uma vez por Ciclo","1/Ciclo",IF('Caminho'!$H$29="Uma vez por combate por alvo","1/combate/alvo",IF('Caminho'!$H$29="Uma vez por combate","1/combate",IF('Caminho'!$H$29="Uma vez por Descanso Longo","1/Desc. Longo",IF('Caminho'!$H$29="Uma vez por sessão","1/sessão",IF('Caminho'!$H$29="Duas vezes por dia","2/dia",""&'Caminho'!$H$29))))))) | U9: =IF(AND(LEN('Caminho'!$I$29)>0,LEN('Caminho'!$H$29)>0,'Caminho'!$H$29<>"Sem limite declarado"),1,0) | V9: =IF(U9=1,MAX($V$2:V8)+1,0) | W9: Ciência | X9: =X8+IF('Criação'!$E$77="Sim",1,0) | Y9: =IF('Criação'!$E$77="Sim",X9,0) | Z9: ='Testes'!$I$24 | AA9: =IF(LEN('Testes'!$J$24)>0,"Vantagem","") | AB9: =IFERROR(INDEX($AA$2:$AA$19,MATCH(8,$Y$2:$Y$19,0)),"") | AC9: =IFERROR(INDEX($T$2:$T$16,MATCH(8,$V$2:$V$16,0)),"") | AK9: =IF(ISERROR($F$9),"",IF(ISBLANK($F$9),"",$F$9)) | AP9: =ISERROR($F$9)*1
A10: Vantagens raciais | B10: =IF('Criação'!$Q$25="Humano","Esforço (máximo 1 ponto)",IF('Criação'!$Q$25="Intellitron","Tecnologia, Mecânica, descobrir Fraqueza",IF('Criação'!$Q$25="Avginiano","Resistência e Percepção Mental, Força de Vontade",IF('Criação'!$Q$25="Vulpes","Perícias de Presença e Força de Vontade",IF('Criação'!$Q$25="Vidyadhara","Resistência Física contra água, frio e afogamento",IF('Criação'!$Q$25="Xianzhouíta","todo Teste de Resistência, inclusive Morrendo","—")))))) | E10: =IF('Criação'!$Q$33="","Recurso do Caminho: escolha o Caminho",IF('Criação'!$Q$33="A Destruição","PV como moeda: "&(2*'Criação'!$A$14)&" PV por ativação",IF('Criação'!$Q$33="A Preservação","Barreira: teto "&$Q$17,IF('Criação'!$Q$33="A Erudição","Acúmulos de Cálculo: máx "&IF((COUNTIF('Caminho'!$I$27:$I$36,"Teto Rompido")>0),7,5),IF('Criação'!$Q$33="A Caça","Marcação de Presa: 1 alvo · crítico "&IF((COUNTIF('Caminho'!$I$27:$I$36,"Olho de Lan")>0),"19-20","20"),IF('Criação'!$Q$33="A Euforia","Tabela do Riso: 1d6 (aba Caminho)",IF('Criação'!$Q$33="A Recordação","Memoespírito: ficha na aba Caminho",IF('Criação'!$Q$33="A Inexistência","Recurso: acúmulos de Marca do Vazio e Corrupção",IF('Criação'!$Q$33="A Harmonia","Recurso: acúmulos de Eco da Vitória (máx 3)",IF('Criação'!$Q$33="A Abundância","Recurso: acúmulos de Florescimento (máx 5)","Recurso do Caminho: escolha um Caminho da lista")))))))))) | I10: Cura recebida | K10: ="PV depois: "&IF(ISNUMBER($AO$10),MIN('Criação'!$D$95,$Q$2+MAX(0,$AO$10)),$Q$2) | N10: =IF(AP10>0,"O Google leu como fórmula: digite de novo com ' na frente.",IF(LEN($AO$2)=0,"",IF(ISNUMBER($AO$2),IF($AO$2<0,"Dano não é negativo: use a cura.",""),"Dano recebido precisa ser um número."))) | P10: Acúmulos de Cálculo (máx. 5 ou 7) | Q10: =IF($G$8="Acúmulos de Cálculo",MIN(IF((COUNTIF('Caminho'!$I$27:$I$36,"Teto Rompido")>0),7,5),IF(ISNUMBER($AK$8),MAX(0,INT($AK$8)),0)),0) | S10: =""&'Caminho'!$I$30 | T10: =IF('Caminho'!$H$30="Uma vez por turno","1/turno",IF('Caminho'!$H$30="Uma vez por Ciclo","1/Ciclo",IF('Caminho'!$H$30="Uma vez por combate por alvo","1/combate/alvo",IF('Caminho'!$H$30="Uma vez por combate","1/combate",IF('Caminho'!$H$30="Uma vez por Descanso Longo","1/Desc. Longo",IF('Caminho'!$H$30="Uma vez por sessão","1/sessão",IF('Caminho'!$H$30="Duas vezes por dia","2/dia",""&'Caminho'!$H$30))))))) | U10: =IF(AND(LEN('Caminho'!$I$30)>0,LEN('Caminho'!$H$30)>0,'Caminho'!$H$30<>"Sem limite declarado"),1,0) | V10: =IF(U10=1,MAX($V$2:V9)+1,0) | W10: Mecânica | X10: =X9+IF('Criação'!$E$78="Sim",1,0) | Y10: =IF('Criação'!$E$78="Sim",X10,0) | Z10: ='Testes'!$I$25 | AA10: =IF(LEN('Testes'!$J$25)>0,"Vantagem","") | AB10: =IFERROR(INDEX($AA$2:$AA$19,MATCH(9,$Y$2:$Y$19,0)),"") | AO10: =IF(ISERROR($J$10),"",IF(ISBLANK($J$10),"",$J$10)) | AP10: =ISERROR($J$10)*1
A11: Condições ativas | B11: =IF($Q$24=0,"Nenhuma",$Q$25&IF($Q$24>1," + "&($Q$24-1)&" (linhas 37-40)","")) | E11: ="Energia de equipamento: "&IF('Equipamento'!$G$41>0,"Corda +"&'Equipamento'!$G$41&" ao entrar na Fila","sem Corda")&IF('Equipamento'!$P$28>=3," · Cone +5 por Ciclo","") | I11: Descanso Curto | J11: =2*'Criação'!$A$14+'Criação'!$F$46 | K11: ="PV depois: "&MIN('Criação'!$D$95,$Q$2+$J$11) | N11: =IF(AND(LEN($AO$10)>0,NOT(ISNUMBER($AO$10))),"Cura precisa ser um número.","") | P11: Marcas da Ruína (máx. 5) | Q11: =IF($G$9="Marcas da Ruína",MIN(5,IF(ISNUMBER($AK$9),MAX(0,INT($AK$9)),0)),0) | S11: =""&'Caminho'!$I$31 | T11: =IF('Caminho'!$H$31="Uma vez por turno","1/turno",IF('Caminho'!$H$31="Uma vez por Ciclo","1/Ciclo",IF('Caminho'!$H$31="Uma vez por combate por alvo","1/combate/alvo",IF('Caminho'!$H$31="Uma vez por combate","1/combate",IF('Caminho'!$H$31="Uma vez por Descanso Longo","1/Desc. Longo",IF('Caminho'!$H$31="Uma vez por sessão","1/sessão",IF('Caminho'!$H$31="Duas vezes por dia","2/dia",""&'Caminho'!$H$31))))))) | U11: =IF(AND(LEN('Caminho'!$I$31)>0,LEN('Caminho'!$H$31)>0,'Caminho'!$H$31<>"Sem limite declarado"),1,0) | V11: =IF(U11=1,MAX($V$2:V10)+1,0) | W11: Percepção | X11: =X10+IF('Criação'!$E$79="Sim",1,0) | Y11: =IF('Criação'!$E$79="Sim",X11,0) | Z11: ='Testes'!$I$26 | AA11: =IF(LEN('Testes'!$J$26)>0,"Vantagem","") | AB11: =IFERROR(INDEX($AA$2:$AA$19,MATCH(10,$Y$2:$Y$19,0)),"")
A12: Pode ser Executado? | B12: =IF('Criação'!$Q$25="Xianzhouíta","Não (Xianzhouíta, 23.5)",IF($Q$3="Sim","Sim: está Morrendo (23.5)","Só se estiver Morrendo (23.5)")) | E12: =IF('Equipamento'!$B$58="Não consegue se mover","Movimento: não se move (carga)",IF($Q$20=1,"Movimento: Lentidão, só Esforço Total move 1 passo","Movimento: 1 Distância por ação · Esforço Total: 2")) | I12: ="Descanso Longo: PV cheios, sem condições, Esforço de volta" | N12: =IF(OR(AND(LEN($AI$33)>0,NOT(ISNUMBER($AI$33))),AND(LEN($AK$33)>0,NOT(ISNUMBER($AK$33)))),"Sucessos e falhas precisam ser números de 0 a 3. ",IF(OR(IF(ISNUMBER($AI$33),$AI$33,0)>3,IF(ISNUMBER($AK$33),$AK$33,0)>3),"Sucessos e falhas vão de 0 a 3. ",""))&IF(AND($Q$3="Não",IF(ISNUMBER($AI$33),$AI$33,0)+IF(ISNUMBER($AK$33),$AK$33,0)>0),"Contador de Morrendo preenchido com PV acima de 0: a cura zera o contador (23.4).","") | P12: Instinto de Sobrevivência ligado (PV ≤ 1/3) | Q12: =IF(AND((COUNTIF('Caminho'!$I$27:$I$36,"Instinto de Sobrevivência")>0),ISNUMBER($AK$2),$Q$2*3<='Criação'!$D$95),1,0) | S12: =""&'Caminho'!$I$32 | T12: =IF('Caminho'!$H$32="Uma vez por turno","1/turno",IF('Caminho'!$H$32="Uma vez por Ciclo","1/Ciclo",IF('Caminho'!$H$32="Uma vez por combate por alvo","1/combate/alvo",IF('Caminho'!$H$32="Uma vez por combate","1/combate",IF('Caminho'!$H$32="Uma vez por Descanso Longo","1/Desc. Longo",IF('Caminho'!$H$32="Uma vez por sessão","1/sessão",IF('Caminho'!$H$32="Duas vezes por dia","2/dia",""&'Caminho'!$H$32))))))) | U12: =IF(AND(LEN('Caminho'!$I$32)>0,LEN('Caminho'!$H$32)>0,'Caminho'!$H$32<>"Sem limite declarado"),1,0) | V12: =IF(U12=1,MAX($V$2:V11)+1,0) | W12: Sobrevivência | X12: =X11+IF('Criação'!$E$80="Sim",1,0) | Y12: =IF('Criação'!$E$80="Sim",X12,0) | Z12: ='Testes'!$I$27 | AA12: =IF(LEN('Testes'!$J$27)>0,"Vantagem","")
A13: =IF((IF(LEN(N2)>0,1,0)+IF(LEN(N3)>0,1,0)+IF(LEN(N4)>0,1,0)+IF(LEN(N5)>0,1,0)+IF(LEN(N6)>0,1,0)+IF(LEN(N7)>0,1,0)+IF(LEN(N8)>0,1,0)+IF(LEN(N9)>0,1,0)+IF(LEN(N10)>0,1,0)+IF(LEN(N11)>0,1,0)+IF(LEN(N12)>0,1,0)+IF(LEN(N13)>0,1,0)+IF(LEN(N14)>0,1,0)+IF(LEN(N15)>0,1,0)+IF(LEN(N16)>0,1,0)+IF(LEN(N17)>0,1,0)+IF(LEN(N18)>0,1,0)+IF(LEN(N19)>0,1,0)+IF(LEN(N20)>0,1,0)+IF(LEN(N33)>0,1,0)+IF(LEN(N34)>0,1,0)+IF(LEN(N35)>0,1,0)+IF(LEN(N36)>0,1,0)+IF(LEN(N37)>0,1,0)+IF(LEN(N38)>0,1,0)+IF(LEN(N39)>0,1,0)+IF(LEN(N40)>0,1,0))=0,"","Avisos ("&(IF(LEN(N2)>0,1,0)+IF(LEN(N3)>0,1,0)+IF(LEN(N4)>0,1,0)+IF(LEN(N5)>0,1,0)+IF(LEN(N6)>0,1,0)+IF(LEN(N7)>0,1,0)+IF(LEN(N8)>0,1,0)+IF(LEN(N9)>0,1,0)+IF(LEN(N10)>0,1,0)+IF(LEN(N11)>0,1,0)+IF(LEN(N12)>0,1,0)+IF(LEN(N13)>0,1,0)+IF(LEN(N14)>0,1,0)+IF(LEN(N15)>0,1,0)+IF(LEN(N16)>0,1,0)+IF(LEN(N17)>0,1,0)+IF(LEN(N18)>0,1,0)+IF(LEN(N19)>0,1,0)+IF(LEN(N20)>0,1,0)+IF(LEN(N33)>0,1,0)+IF(LEN(N34)>0,1,0)+IF(LEN(N35)>0,1,0)+IF(LEN(N36)>0,1,0)+IF(LEN(N37)>0,1,0)+IF(LEN(N38)>0,1,0)+IF(LEN(N39)>0,1,0)+IF(LEN(N40)>0,1,0))&"): "&IF(LEN(N2)>0,N2,IF(LEN(N3)>0,N3,IF(LEN(N4)>0,N4,IF(LEN(N5)>0,N5,IF(LEN(N6)>0,N6,IF(LEN(N7)>0,N7,IF(LEN(N8)>0,N8,IF(LEN(N9)>0,N9,IF(LEN(N10)>0,N10,IF(LEN(N11)>0,N11,IF(LEN(N12)>0,N12,IF(LEN(N13)>0,N13,IF(LEN(N14)>0,N14,IF(LEN(N15)>0,N15,IF(LEN(N16)>0,N16,IF(LEN(N17)>0,N17,IF(LEN(N18)>0,N18,IF(LEN(N19)>0,N19,IF(LEN(N20)>0,N20,IF(LEN(N33)>0,N33,IF(LEN(N34)>0,N34,IF(LEN(N35)>0,N35,IF(LEN(N36)>0,N36,IF(LEN(N37)>0,N37,IF(LEN(N38)>0,N38,IF(LEN(N39)>0,N39,IF(LEN(N40)>0,N40,"")))))))))))))))))))))))))))&IF((IF(LEN(N2)>0,1,0)+IF(LEN(N3)>0,1,0)+IF(LEN(N4)>0,1,0)+IF(LEN(N5)>0,1,0)+IF(LEN(N6)>0,1,0)+IF(LEN(N7)>0,1,0)+IF(LEN(N8)>0,1,0)+IF(LEN(N9)>0,1,0)+IF(LEN(N10)>0,1,0)+IF(LEN(N11)>0,1,0)+IF(LEN(N12)>0,1,0)+IF(LEN(N13)>0,1,0)+IF(LEN(N14)>0,1,0)+IF(LEN(N15)>0,1,0)+IF(LEN(N16)>0,1,0)+IF(LEN(N17)>0,1,0)+IF(LEN(N18)>0,1,0)+IF(LEN(N19)>0,1,0)+IF(LEN(N20)>0,1,0)+IF(LEN(N33)>0,1,0)+IF(LEN(N34)>0,1,0)+IF(LEN(N35)>0,1,0)+IF(LEN(N36)>0,1,0)+IF(LEN(N37)>0,1,0)+IF(LEN(N38)>0,1,0)+IF(LEN(N39)>0,1,0)+IF(LEN(N40)>0,1,0))>1," · os outros estão na coluna N","")) | N13: =IF($AF$37="","",IF($AF$37="Quebrado","Quebrado é só de inimigos (20.3).",IF($AF$37="Morrendo","Morrendo liga sozinho com PV 0.",IF(COUNTIF('Dados'!$Y$6:$Y$18,$AF$37)=0,"Condição fora da lista de 21.5.","")))) | P13: Bônus temporário no Teste de Ataque (antes do teto) | Q13: =2*$Q$12+IF(AND(($Q$6="Sim"),'Caminho'!$P$57="Catalisador"),1,0)+IF(AND(($Q$6="Sim"),COUNTIF('Caminho'!$Q$75:$Q$77,"Fusão de Memórias")>0),1,0)+IF(AND(($Q$6="Sim"),(COUNTIF('Caminho'!$I$27:$I$36,"Memória Compartilhada")>0)),1,0)+COUNTIF('Equipamento'!$P$45:$P$47,"Teste de Ataque") | S13: =""&'Caminho'!$I$33 | T13: =IF('Caminho'!$H$33="Uma vez por turno","1/turno",IF('Caminho'!$H$33="Uma vez por Ciclo","1/Ciclo",IF('Caminho'!$H$33="Uma vez por combate por alvo","1/combate/alvo",IF('Caminho'!$H$33="Uma vez por combate","1/combate",IF('Caminho'!$H$33="Uma vez por Descanso Longo","1/Desc. Longo",IF('Caminho'!$H$33="Uma vez por sessão","1/sessão",IF('Caminho'!$H$33="Duas vezes por dia","2/dia",""&'Caminho'!$H$33))))))) | U13: =IF(AND(LEN('Caminho'!$I$33)>0,LEN('Caminho'!$H$33)>0,'Caminho'!$H$33<>"Sem limite declarado"),1,0) | V13: =IF(U13=1,MAX($V$2:V12)+1,0) | W13: Intuição | X13: =X12+IF('Criação'!$E$81="Sim",1,0) | Y13: =IF('Criação'!$E$81="Sim",X13,0) | Z13: ='Testes'!$I$28 | AA13: =IF(LEN('Testes'!$J$28)>0,"Vantagem","")
A14: Ações — Ataque Básico (18), Habilidades (16) e Ultimate (17) | N14: =IF($AF$38="","",IF($AF$38="Quebrado","Quebrado é só de inimigos (20.3).",IF($AF$38="Morrendo","Morrendo liga sozinho com PV 0.",IF(COUNTIF('Dados'!$Y$6:$Y$18,$AF$38)=0,"Condição fora da lista de 21.5.","")))) | P14: Bônus temporário no Teste de Ataque (no teto) | Q14: =MIN('Criação'!$J$14,$Q$13) | S14: =""&'Caminho'!$I$34 | T14: =IF('Caminho'!$H$34="Uma vez por turno","1/turno",IF('Caminho'!$H$34="Uma vez por Ciclo","1/Ciclo",IF('Caminho'!$H$34="Uma vez por combate por alvo","1/combate/alvo",IF('Caminho'!$H$34="Uma vez por combate","1/combate",IF('Caminho'!$H$34="Uma vez por Descanso Longo","1/Desc. Longo",IF('Caminho'!$H$34="Uma vez por sessão","1/sessão",IF('Caminho'!$H$34="Duas vezes por dia","2/dia",""&'Caminho'!$H$34))))))) | U14: =IF(AND(LEN('Caminho'!$I$34)>0,LEN('Caminho'!$H$34)>0,'Caminho'!$H$34<>"Sem limite declarado"),1,0) | V14: =IF(U14=1,MAX($V$2:V13)+1,0) | W14: Investigação | X14: =X13+IF('Criação'!$E$82="Sim",1,0) | Y14: =IF('Criação'!$E$82="Sim",X14,0) | Z14: ='Testes'!$I$29 | AA14: =IF(LEN('Testes'!$J$29)>0,"Vantagem","")
A15: Ataque Básico | C15: Ataque | D15: Dano | E15: Média | F15: Do atributo | G15: Equipamento | H15: Contra Fraqueza | I15: Crítico | J15: RT | K15: Alcance · Elemento | N15: =IF($AF$39="","",IF($AF$39="Quebrado","Quebrado é só de inimigos (20.3).",IF($AF$39="Morrendo","Morrendo liga sozinho com PV 0.",IF(COUNTIF('Dados'!$Y$6:$Y$18,$AF$39)=0,"Condição fora da lista de 21.5.","")))) | P15: Defesa temporária (Florescimento, Memória da Guarda) | Q15: =$Q$8+IF(AND((COUNTIF('Caminho'!$I$27:$I$36,"Fragmentos do Eu Perdido")>0),($Q$6="Sim"),'Caminho'!$P$95="Guarda"),'Criação'!$C$14,0) | S15: =""&'Caminho'!$I$35 | T15: =IF('Caminho'!$H$35="Uma vez por turno","1/turno",IF('Caminho'!$H$35="Uma vez por Ciclo","1/Ciclo",IF('Caminho'!$H$35="Uma vez por combate por alvo","1/combate/alvo",IF('Caminho'!$H$35="Uma vez por combate","1/combate",IF('Caminho'!$H$35="Uma vez por Descanso Longo","1/Desc. Longo",IF('Caminho'!$H$35="Uma vez por sessão","1/sessão",IF('Caminho'!$H$35="Duas vezes por dia","2/dia",""&'Caminho'!$H$35))))))) | U15: =IF(AND(LEN('Caminho'!$I$35)>0,LEN('Caminho'!$H$35)>0,'Caminho'!$H$35<>"Sem limite declarado"),1,0) | V15: =IF(U15=1,MAX($V$2:V14)+1,0) | W15: Persuasão | X15: =X14+IF('Criação'!$E$84="Sim",1,0) | Y15: =IF('Criação'!$E$84="Sim",X15,0) | Z15: ='Testes'!$I$31 | AA15: =IF(LEN('Testes'!$J$31)>0,"Vantagem","")
A16: =IF('Criação'!$Q$108="","Arma principal: —",IF(LEN('Criação'!$Q$107)=0,"Arma "&'Criação'!$Q$108,""&'Criação'!$Q$107)) | C16: ='Equipamento'!$B$13 | D16: ='Equipamento'!$C$13 | E16: ='Equipamento'!$D$13 | F16: ='Equipamento'!$E$13 | G16: ='Equipamento'!$F$13 | H16: =IF(LEN('Equipamento'!$G$13)=0,"",'Equipamento'!$G$13&" ("&'Equipamento'!$H$13&")") | I16: ='Equipamento'!$I$13 | J16: ='Equipamento'!$J$13 | K16: =IF(LEN('Equipamento'!$K$13)=0,"",'Equipamento'!$K$13&" · "&'Equipamento'!$L$13) | N16: =IF($AF$40="","",IF($AF$40="Quebrado","Quebrado é só de inimigos (20.3).",IF($AF$40="Morrendo","Morrendo liga sozinho com PV 0.",IF(COUNTIF('Dados'!$Y$6:$Y$18,$AF$40)=0,"Condição fora da lista de 21.5.","")))) | P16: Defesa com temporários | Q16: ='Criação'!$D$96+MIN('Criação'!$J$14,$Q$15) | S16: =""&'Caminho'!$I$36 | T16: =IF('Caminho'!$H$36="Uma vez por turno","1/turno",IF('Caminho'!$H$36="Uma vez por Ciclo","1/Ciclo",IF('Caminho'!$H$36="Uma vez por combate por alvo","1/combate/alvo",IF('Caminho'!$H$36="Uma vez por combate","1/combate",IF('Caminho'!$H$36="Uma vez por Descanso Longo","1/Desc. Longo",IF('Caminho'!$H$36="Uma vez por sessão","1/sessão",IF('Caminho'!$H$36="Duas vezes por dia","2/dia",""&'Caminho'!$H$36))))))) | U16: =IF(AND(LEN('Caminho'!$I$36)>0,LEN('Caminho'!$H$36)>0,'Caminho'!$H$36<>"Sem limite declarado"),1,0) | V16: =IF(U16=1,MAX($V$2:V15)+1,0) | W16: Intimidação | X16: =X15+IF('Criação'!$E$85="Sim",1,0) | Y16: =IF('Criação'!$E$85="Sim",X16,0) | Z16: ='Testes'!$I$32 | AA16: =IF(LEN('Testes'!$J$32)>0,"Vantagem","")
A17: =IF('Equipamento'!$AE$8="","Arma secundária: —",IF(LEN('Equipamento'!$AD$8)=0,"Arma "&'Equipamento'!$AE$8,""&'Equipamento'!$AD$8)) | C17: ='Equipamento'!$B$14 | D17: ='Equipamento'!$C$14 | E17: ='Equipamento'!$D$14 | F17: ='Equipamento'!$E$14 | G17: ='Equipamento'!$F$14 | H17: =IF(LEN('Equipamento'!$G$14)=0,"",'Equipamento'!$G$14&" ("&'Equipamento'!$H$14&")") | I17: ='Equipamento'!$I$14 | J17: ='Equipamento'!$J$14 | K17: =IF(LEN('Equipamento'!$K$14)=0,"",'Equipamento'!$K$14&" · "&'Equipamento'!$L$14) | N17: =IF(MAX($V$2:$V$16)>8,"Mais usos do que cabem aqui: veja a frequência das Bênçãos na aba Caminho.","") | P17: Teto de Barreira (Preservação) | Q17: =IF('Criação'!$Q$33="A Preservação",3*'Criação'!$C$14,"") | W17: Enganação | X17: =X16+IF('Criação'!$E$86="Sim",1,0) | Y17: =IF('Criação'!$E$86="Sim",X17,0) | Z17: ='Testes'!$I$33 | AA17: =IF(LEN('Testes'!$J$33)>0,"Vantagem","")
A18: Habilidade | C18: Rolagem | D18: Dano · média | E18: Nível · PH · RT · alvos | G18: Habilidade | I18: Rolagem | J18: Dano · média | K18: Nível · PH · RT · alvos | N18: =IF(AND(ISNUMBER($AO$33),$AO$33>2),"Descanso Curto: até 2 por dia (23.6).","") | P18: Silenciado | Q18: =IF(COUNTIF($AF$37:$AF$40,"Silenciado")>0,1,0) | W18: Liderança | X18: =X17+IF('Criação'!$E$87="Sim",1,0) | Y18: =IF('Criação'!$E$87="Sim",X18,0) | Z18: ='Testes'!$I$34 | AA18: =IF(LEN('Testes'!$J$34)>0,"Vantagem","")
A19: =IF('Habilidades'!$P$12=0,"—",'Habilidades'!$B$34) | C19: =IF('Habilidades'!$P$12=0,"",IF(LEN(IF($Q$19=1,"BLOQUEADA",IF(AND($Q$18=1,'Habilidades'!$S$12>=4),"BLOQUEADA","")))>0,IF($Q$19=1,"BLOQUEADA",IF(AND($Q$18=1,'Habilidades'!$S$12>=4),"BLOQUEADA","")),IF(LEN('Habilidades'!$F$34)=0,IF('Habilidades'!$Z$12="Passiva","Passiva","—"),'Habilidades'!$F$34))) | D19: =IF(LEN('Habilidades'!$D$34)=0,"",'Habilidades'!$D$34&" ("&'Habilidades'!$E$34&")") | E19: =IF('Habilidades'!$P$12=0,"",'Habilidades'!$S$12&" · "&'Habilidades'!$G$34&" PH · RT "&'Habilidades'!$H$34&" · "&'Habilidades'!$J$34&IF('Habilidades'!$J$34=1," alvo"," alvos")) | G19: =IF('Habilidades'!$P$16=0,"—",'Habilidades'!$B$38) | I19: =IF('Habilidades'!$P$16=0,"",IF(LEN(IF($Q$19=1,"BLOQUEADA",IF(AND($Q$18=1,'Habilidades'!$S$16>=4),"BLOQUEADA","")))>0,IF($Q$19=1,"BLOQUEADA",IF(AND($Q$18=1,'Habilidades'!$S$16>=4),"BLOQUEADA","")),IF(LEN('Habilidades'!$F$38)=0,IF('Habilidades'!$Z$16="Passiva","Passiva","—"),'Habilidades'!$F$38))) | J19: =IF(LEN('Habilidades'!$D$38)=0,"",'Habilidades'!$D$38&" ("&'Habilidades'!$E$38&")") | K19: =IF('Habilidades'!$P$16=0,"",'Habilidades'!$S$16&" · "&'Habilidades'!$G$38&" PH · RT "&'Habilidades'!$H$38&" · "&'Habilidades'!$J$38&IF('Habilidades'!$J$38=1," alvo"," alvos")) | N19: =IF($Q$13>'Criação'!$J$14,"Bônus temporário no Teste de Ataque acima do teto (+"&'Criação'!$J$14&"): conta só o teto (26.6). ","")&IF($Q$15>'Criação'!$J$14,"Defesa temporária acima do teto (+"&'Criação'!$J$14&"): conta só o teto (26.6).","") | P19: Controlado | Q19: =IF(COUNTIF($AF$37:$AF$40,"Controlado")>0,1,0) | W19: Sintonia | X19: =X18+IF('Criação'!$E$88="Sim",1,0) | Y19: =IF('Criação'!$E$88="Sim",X19,0) | Z19: ='Testes'!$I$35 | AA19: =IF(LEN('Testes'!$J$35)>0,"Vantagem","")
A20: =IF('Habilidades'!$P$13=0,"—",'Habilidades'!$B$35) | C20: =IF('Habilidades'!$P$13=0,"",IF(LEN(IF($Q$19=1,"BLOQUEADA",IF(AND($Q$18=1,'Habilidades'!$S$13>=4),"BLOQUEADA","")))>0,IF($Q$19=1,"BLOQUEADA",IF(AND($Q$18=1,'Habilidades'!$S$13>=4),"BLOQUEADA","")),IF(LEN('Habilidades'!$F$35)=0,IF('Habilidades'!$Z$13="Passiva","Passiva","—"),'Habilidades'!$F$35))) | D20: =IF(LEN('Habilidades'!$D$35)=0,"",'Habilidades'!$D$35&" ("&'Habilidades'!$E$35&")") | E20: =IF('Habilidades'!$P$13=0,"",'Habilidades'!$S$13&" · "&'Habilidades'!$G$35&" PH · RT "&'Habilidades'!$H$35&" · "&'Habilidades'!$J$35&IF('Habilidades'!$J$35=1," alvo"," alvos")) | G20: =IF('Habilidades'!$P$17=0,"—",'Habilidades'!$B$39) | I20: =IF('Habilidades'!$P$17=0,"",IF(LEN(IF($Q$19=1,"BLOQUEADA",IF(AND($Q$18=1,'Habilidades'!$S$17>=4),"BLOQUEADA","")))>0,IF($Q$19=1,"BLOQUEADA",IF(AND($Q$18=1,'Habilidades'!$S$17>=4),"BLOQUEADA","")),IF(LEN('Habilidades'!$F$39)=0,IF('Habilidades'!$Z$17="Passiva","Passiva","—"),'Habilidades'!$F$39))) | J20: =IF(LEN('Habilidades'!$D$39)=0,"",'Habilidades'!$D$39&" ("&'Habilidades'!$E$39&")") | K20: =IF('Habilidades'!$P$17=0,"",'Habilidades'!$S$17&" · "&'Habilidades'!$G$39&" PH · RT "&'Habilidades'!$H$39&" · "&'Habilidades'!$J$39&IF('Habilidades'!$J$39=1," alvo"," alvos")) | N20: =IF($Q$21=1,"Surpreso: a sua casa é pulada no primeiro Ciclo.","") | P20: Lentidão (condição ou carga) | Q20: =IF(OR(COUNTIF($AF$37:$AF$40,"Lentidão")>0,'Equipamento'!$B$58="Lentidão"),1,0)
A21: =IF('Habilidades'!$P$14=0,"—",'Habilidades'!$B$36) | C21: =IF('Habilidades'!$P$14=0,"",IF(LEN(IF($Q$19=1,"BLOQUEADA",IF(AND($Q$18=1,'Habilidades'!$S$14>=4),"BLOQUEADA","")))>0,IF($Q$19=1,"BLOQUEADA",IF(AND($Q$18=1,'Habilidades'!$S$14>=4),"BLOQUEADA","")),IF(LEN('Habilidades'!$F$36)=0,IF('Habilidades'!$Z$14="Passiva","Passiva","—"),'Habilidades'!$F$36))) | D21: =IF(LEN('Habilidades'!$D$36)=0,"",'Habilidades'!$D$36&" ("&'Habilidades'!$E$36&")") | E21: =IF('Habilidades'!$P$14=0,"",'Habilidades'!$S$14&" · "&'Habilidades'!$G$36&" PH · RT "&'Habilidades'!$H$36&" · "&'Habilidades'!$J$36&IF('Habilidades'!$J$36=1," alvo"," alvos")) | G21: =IF('Habilidades'!$P$18=0,"—",'Habilidades'!$B$40) | I21: =IF('Habilidades'!$P$18=0,"",IF(LEN(IF($Q$19=1,"BLOQUEADA",IF(AND($Q$18=1,'Habilidades'!$S$18>=4),"BLOQUEADA","")))>0,IF($Q$19=1,"BLOQUEADA",IF(AND($Q$18=1,'Habilidades'!$S$18>=4),"BLOQUEADA","")),IF(LEN('Habilidades'!$F$40)=0,IF('Habilidades'!$Z$18="Passiva","Passiva","—"),'Habilidades'!$F$40))) | J21: =IF(LEN('Habilidades'!$D$40)=0,"",'Habilidades'!$D$40&" ("&'Habilidades'!$E$40&")") | K21: =IF('Habilidades'!$P$18=0,"",'Habilidades'!$S$18&" · "&'Habilidades'!$G$40&" PH · RT "&'Habilidades'!$H$40&" · "&'Habilidades'!$J$40&IF('Habilidades'!$J$40=1," alvo"," alvos")) | P21: Surpreso | Q21: =IF(COUNTIF($AF$37:$AF$40,"Surpreso")>0,1,0)
A22: =IF('Habilidades'!$P$15=0,"—",'Habilidades'!$B$37) | C22: =IF('Habilidades'!$P$15=0,"",IF(LEN(IF($Q$19=1,"BLOQUEADA",IF(AND($Q$18=1,'Habilidades'!$S$15>=4),"BLOQUEADA","")))>0,IF($Q$19=1,"BLOQUEADA",IF(AND($Q$18=1,'Habilidades'!$S$15>=4),"BLOQUEADA","")),IF(LEN('Habilidades'!$F$37)=0,IF('Habilidades'!$Z$15="Passiva","Passiva","—"),'Habilidades'!$F$37))) | D22: =IF(LEN('Habilidades'!$D$37)=0,"",'Habilidades'!$D$37&" ("&'Habilidades'!$E$37&")") | E22: =IF('Habilidades'!$P$15=0,"",'Habilidades'!$S$15&" · "&'Habilidades'!$G$37&" PH · RT "&'Habilidades'!$H$37&" · "&'Habilidades'!$J$37&IF('Habilidades'!$J$37=1," alvo"," alvos")) | G22: =IF('Habilidades'!$P$19=0,"—",'Habilidades'!$B$41) | I22: =IF('Habilidades'!$P$19=0,"",IF(LEN(IF($Q$19=1,"BLOQUEADA",IF(AND($Q$18=1,'Habilidades'!$S$19>=4),"BLOQUEADA","")))>0,IF($Q$19=1,"BLOQUEADA",IF(AND($Q$18=1,'Habilidades'!$S$19>=4),"BLOQUEADA","")),IF(LEN('Habilidades'!$F$41)=0,IF('Habilidades'!$Z$19="Passiva","Passiva","—"),'Habilidades'!$F$41))) | J22: =IF(LEN('Habilidades'!$D$41)=0,"",'Habilidades'!$D$41&" ("&'Habilidades'!$E$41&")") | K22: =IF('Habilidades'!$P$19=0,"",'Habilidades'!$S$19&" · "&'Habilidades'!$G$41&" PH · RT "&'Habilidades'!$H$41&" · "&'Habilidades'!$J$41&IF('Habilidades'!$J$41=1," alvo"," alvos")) | P22: Ultimate pronta | Q22: =IF($Q$5>='Habilidades'!$G$61,"Sim","Não")
A23: =IF(LEN('Habilidades'!$Z$54)=0,"Ultimate: —",""&'Habilidades'!$Z$54) | C23: =IF(LEN(IF($Q$19=1,"BLOQUEADA",""))>0,IF($Q$19=1,"BLOQUEADA",""),IF(LEN('Habilidades'!$F$61)=0,"—",'Habilidades'!$F$61)) | D23: =IF(LEN('Habilidades'!$D$61)=0,"",'Habilidades'!$D$61&" ("&'Habilidades'!$E$61&")") | E23: ="RT "&'Habilidades'!$H$61&" · "&'Habilidades'!$I$61&IF('Habilidades'!$I$61=1," alvo"," alvos") | G23: ="Ultimate ("&$Q$5&"/"&'Habilidades'!$G$61&" de Energia): "&IF(LEN(IF($Q$19=1,"BLOQUEADA",""))>0,"BLOQUEADA (Controlado)",IF($Q$22="Sim","pronta, diga o nome em voz alta","faltam "&('Habilidades'!$G$61-$Q$5))) | P23: Condições ativas (texto inteiro) | Q23: =""&$AF$37&IF(LEN(""&$AF$38)>0,IF(LEN(""&$AF$37)>0," · ","")&""&$AF$38,"")&IF(LEN(""&$AF$39)>0,IF(LEN(""&$AF$37&""&$AF$38)>0," · ","")&""&$AF$39,"")&IF(LEN(""&$AF$40)>0,IF(LEN(""&$AF$37&""&$AF$38&""&$AF$39)>0," · ","")&""&$AF$40,"")&IF(LEN(IF($Q$3="Sim","Morrendo",""))>0,IF(LEN(""&$AF$37&""&$AF$38&""&$AF$39&""&$AF$40)>0," · ","")&IF($Q$3="Sim","Morrendo",""),"")&IF(LEN(IF('Equipamento'!$B$58<>"Normal","Lentidão (carga)",""))>0,IF(LEN(""&$AF$37&""&$AF$38&""&$AF$39&""&$AF$40&IF($Q$3="Sim","Morrendo",""))>0," · ","")&IF('Equipamento'!$B$58<>"Normal","Lentidão (carga)",""),"")
A24: ="Neste ataque: "&IF(AND(($Q$6="Sim"),(COUNTIF('Caminho'!$I$27:$I$36,"Memória Compartilhada")>0)),"+1d6 (Memória Compartilhada) · ","")&IF(AND(($Q$6="Sim"),(COUNTIF('Caminho'!$I$27:$I$36,"Fragmentos do Eu Perdido")>0),'Caminho'!$P$95="Fúria"),"+1d8 (Memória da Fúria) · ","")&IF($Q$7>0,"+"&$Q$7&"d6 (Fúria) · ","")&IF($Q$11>0,"+"&MIN('Criação'!$J$14,$Q$11)&" de dano (Cicatriz) · ","")&IF($Q$12=1,"+2 no ataque, já somado (Instinto) · ","")&"temporários: no máximo +3 por rolagem, fora a Fraqueza (26.6)" | P24: Condições ativas (quantas) | Q24: =IF(LEN(""&$AF$37)>0,1,0)+IF(LEN(""&$AF$38)>0,1,0)+IF(LEN(""&$AF$39)>0,1,0)+IF(LEN(""&$AF$40)>0,1,0)+IF(LEN(IF($Q$3="Sim","Morrendo",""))>0,1,0)+IF(LEN(IF('Equipamento'!$B$58<>"Normal","Lentidão (carga)",""))>0,1,0)
P25: Condições ativas (a primeira) | Q25: =IF(LEN(""&$AF$37)>0,""&$AF$37,IF(LEN(""&$AF$38)>0,""&$AF$38,IF(LEN(""&$AF$39)>0,""&$AF$39,IF(LEN(""&$AF$40)>0,""&$AF$40,IF(LEN(IF($Q$3="Sim","Morrendo",""))>0,IF($Q$3="Sim","Morrendo",""),IF(LEN(IF('Equipamento'!$B$58<>"Normal","Lentidão (carga)",""))>0,IF('Equipamento'!$B$58<>"Normal","Lentidão (carga)",""),""))))))
A26: Testes de Resistência (d20 + Bônus + Eficiência) | G26: Perícias com Eficiência (rolagem pronta)
A27: Potência Física | B27: ='Testes'!$I$40 | C27: =IF(OR('Criação'!$Q$25="Xianzhouíta"),"Vantagem ("&'Criação'!$Q$25&")","") | E27: =IF('Testes'!$G$40=0,"",IF('Testes'!$G$40>=0,"+","")&'Testes'!$G$40&" de equipamento/Bênção") | G27: =IFERROR(INDEX($W$2:$W$19,MATCH(1,$Y$2:$Y$19,0))&IF(LEN($AB$2)>0," · Vantagem",""),"") | I27: =IFERROR(INDEX($Z$2:$Z$19,MATCH(1,$Y$2:$Y$19,0)),"") | J27: =IFERROR(INDEX($W$2:$W$19,MATCH(6,$Y$2:$Y$19,0))&IF(LEN($AB$7)>0," · Vantagem",""),"") | L27: =IFERROR(INDEX($Z$2:$Z$19,MATCH(6,$Y$2:$Y$19,0)),"")
A28: Reflexos | B28: ='Testes'!$I$41 | C28: =IF(OR('Criação'!$Q$25="Xianzhouíta"),"Vantagem ("&'Criação'!$Q$25&")","") | E28: =IF('Testes'!$G$41=0,"",IF('Testes'!$G$41>=0,"+","")&'Testes'!$G$41&" de equipamento/Bênção") | G28: =IFERROR(INDEX($W$2:$W$19,MATCH(2,$Y$2:$Y$19,0))&IF(LEN($AB$3)>0," · Vantagem",""),"") | I28: =IFERROR(INDEX($Z$2:$Z$19,MATCH(2,$Y$2:$Y$19,0)),"") | J28: =IFERROR(INDEX($W$2:$W$19,MATCH(7,$Y$2:$Y$19,0))&IF(LEN($AB$8)>0," · Vantagem",""),"") | L28: =IFERROR(INDEX($Z$2:$Z$19,MATCH(7,$Y$2:$Y$19,0)),"")
