Workbook

Sheet Início
A1: Início — Explorando Galáxias v1.2 | AA1: =SUMPRODUCT((LEN($K$16:$K$16)>0)*1) | AB1: =IFERROR(INDEX($K$16:$K$16,MATCH("?*",$K$16:$K$16,0))&"","") | AC1: =IF(LEN(AB1)>0,AB1,"")
A2: Legenda: | B2: Entrada (preencha) | C2: Calculada (automático) | D2: Aviso (texto em vermelho) | E2: Título de bloco | F2: Cabeçalho de coluna | G2: Rótulo da linha | H2: Linha alternada (outro tom) | I2: Não se aplica
A3: Comece por aqui: semente da campanha, índice das abas e como a planilha se organiza. | AA3: =SUMPRODUCT((LEN('Campanha'!$K$7:$K$13)>0)*1) | AB3: =IFERROR(INDEX('Campanha'!$K$7:$K$13,MATCH("?*",'Campanha'!$K$7:$K$13,0))&"","") | AC3: =IF(LEN(AB3)>0,AB3,AC4)
AA4: =SUMPRODUCT((LEN('Campanha'!$K$38:$K$38)>0)*1) | AB4: =IFERROR(INDEX('Campanha'!$K$38:$K$38,MATCH("?*",'Campanha'!$K$38:$K$38,0))&"","") | AC4: =IF(LEN(AB4)>0,AB4,AC5)
A5: Comece por aqui | AA5: =SUMPRODUCT((LEN('Campanha'!$K$47:$K$58)>0)*1) | AB5: =IFERROR(INDEX('Campanha'!$K$47:$K$58,MATCH("?*",'Campanha'!$K$47:$K$58,0))&"","") | AC5: =IF(LEN(AB5)>0,AB5,AC6)
A6: 1. Abra no Google Planilhas (Arquivo → Importar) e trabalhe numa cópia por campanha. | AA6: =SUMPRODUCT((LEN('Campanha'!$K$62:$K$71)>0)*1) | AB6: =IFERROR(INDEX('Campanha'!$K$62:$K$71,MATCH("?*",'Campanha'!$K$62:$K$71,0))&"","") | AC6: =IF(LEN(AB6)>0,AB6,AC7)
A7: 2. Aba Campanha: nível do grupo e nº de jogadores (uma vez; todas as abas leem daqui). Faça a Sessão Zero. | AA7: =SUMPRODUCT((LEN('Campanha'!$K$76:$K$85)>0)*1) | AB7: =IFERROR(INDEX('Campanha'!$K$76:$K$85,MATCH("?*",'Campanha'!$K$76:$K$85,0))&"","") | AC7: =IF(LEN(AB7)>0,AB7,AC8)
A8: 3. Aba Grupo: copie da ficha de cada jogador os números de combate e os testes. | AA8: =SUMPRODUCT((LEN('Campanha'!$K$87:$K$96)>0)*1) | AB8: =IFERROR(INDEX('Campanha'!$K$87:$K$96,MATCH("?*",'Campanha'!$K$87:$K$96,0))&"","") | AC8: =IF(LEN(AB8)>0,AB8,AC9)
A9: 4. Prepare: Encontros (com Inimigos e Bestiário), NPCs, Aventuras, Mundos; a sessão na aba Sessões. | AA9: =SUMPRODUCT((LEN('Campanha'!$K$98:$K$107)>0)*1) | AB9: =IFERROR(INDEX('Campanha'!$K$98:$K$107,MATCH("?*",'Campanha'!$K$98:$K$107,0))&"","") | AC9: =IF(LEN(AB9)>0,AB9,AC10)
A10: 5. Jogue com Combate e Improviso; o Escudo do Mestre impresso fica na mesa. | AA10: =SUMPRODUCT((LEN('Campanha'!$K$122:$K$131)>0)*1) | AB10: =IFERROR(INDEX('Campanha'!$K$122:$K$131,MATCH("?*",'Campanha'!$K$122:$K$131,0))&"","") | AC10: =IF(LEN(AB10)>0,AB10,AC11)
A11: 6. Depois: diário (Sessões), Missões, Recompensas, relógios e linha do tempo (Campanha). | AA11: =SUMPRODUCT((LEN('Campanha'!$K$134:$K$143)>0)*1) | AB11: =IFERROR(INDEX('Campanha'!$K$134:$K$143,MATCH("?*",'Campanha'!$K$134:$K$143,0))&"","") | AC11: =IF(LEN(AB11)>0,AB11,AC12)
A12: Amarelo = você preenche; azul = automático; vermelho = aviso; 'Sugestão da planilha' = não é regra do livro. | AA12: =SUMPRODUCT((LEN('Campanha'!$K$146:$K$153)>0)*1) | AB12: =IFERROR(INDEX('Campanha'!$K$146:$K$153,MATCH("?*",'Campanha'!$K$146:$K$153,0))&"","") | AC12: =IF(LEN(AB12)>0,AB12,AC13)
A13: Não comece um texto com +, - ou =: o Google entende como fórmula. Se precisar, digite um apóstrofo (') antes. | AA13: =SUMPRODUCT((LEN('Campanha'!$K$156:$K$165)>0)*1) | AB13: =IFERROR(INDEX('Campanha'!$K$156:$K$165,MATCH("?*",'Campanha'!$K$156:$K$165,0))&"","") | AC13: =IF(LEN(AB13)>0,AB13,AC14)
AA14: =SUMPRODUCT((LEN('Campanha'!$K$169:$K$181)>0)*1) | AB14: =IFERROR(INDEX('Campanha'!$K$169:$K$181,MATCH("?*",'Campanha'!$K$169:$K$181,0))&"","") | AC14: =IF(LEN(AB14)>0,AB14,AC15)
A15: Semente da campanha (geradores determinísticos, sem sorteio escondido) | AA15: =SUMPRODUCT((LEN('Campanha'!$K$183:$K$185)>0)*1) | AB15: =IFERROR(INDEX('Campanha'!$K$183:$K$185,MATCH("?*",'Campanha'!$K$183:$K$185,0))&"","") | AC15: =IF(LEN(AB15)>0,AB15,AC16)
A16: Semente da campanha | D16: Semente efetiva | E16: =IF(ISNUMBER($P$16),IF(AND($P$16>=1,$P$16<=2147483646,INT($P$16)=$P$16),$P$16,12345),12345) | G16: Vazia = 12345. | K16: =IF(Q16>0,"O Google leu como fórmula: digite de novo com ' na frente.",IF(LEN($P$16)=0,"",IF(ISNUMBER($P$16),IF(AND($P$16>=1,$P$16<=2147483646,INT($P$16)=$P$16),"","Semente fora de 1 a 2.147.483.646: usando 12345"),"Semente fora de 1 a 2.147.483.646: usando 12345"))) | P16: =IF(ISERROR($B$16),"",IF(ISBLANK($B$16),"",$B$16)) | Q16: =ISERROR($B$16)*1 | AA16: =SUMPRODUCT((LEN('Campanha'!$K$188:$K$192)>0)*1) | AB16: =IFERROR(INDEX('Campanha'!$K$188:$K$192,MATCH("?*",'Campanha'!$K$188:$K$192,0))&"","") | AC16: =IF(LEN(AB16)>0,AB16,"")
A17: Mesma semente e mesma 'Rolagem nº' dão sempre o mesmo resultado; editar outra célula não muda o sorteio. Para rolar de novo, some 1 na 'Rolagem nº' do gerador; para outra campanha, troque a semente.
AA18: =SUMPRODUCT((LEN('Grupo'!$K$7:$K$12)>0)*1) | AB18: =IFERROR(INDEX('Grupo'!$K$7:$K$12,MATCH("?*",'Grupo'!$K$7:$K$12,0))&"","") | AC18: =IF(LEN(AB18)>0,AB18,AC19)
A19: Painel da campanha (automático) | AA19: =SUMPRODUCT((LEN('Grupo'!$K$16:$K$21)>0)*1) | AB19: =IFERROR(INDEX('Grupo'!$K$16:$K$21,MATCH("?*",'Grupo'!$K$16:$K$21,0))&"","") | AC19: =IF(LEN(AB19)>0,AB19,AC20)
A20: Campo | B20: Agora | G20: De onde vem | AA20: =SUMPRODUCT((LEN('Grupo'!$K$25:$K$30)>0)*1) | AB20: =IFERROR(INDEX('Grupo'!$K$25:$K$30,MATCH("?*",'Grupo'!$K$25:$K$30,0))&"","") | AC20: =IF(LEN(AB20)>0,AB20,AC21)
A21: Campanha | B21: =IF(LEN('Campanha'!$AD$7)>0,'Campanha'!$AD$7,"(sem nome: aba Campanha)") | G21: Aba Campanha, Mesa. | AA21: =SUMPRODUCT((LEN('Grupo'!$K$34:$K$39)>0)*1) | AB21: =IFERROR(INDEX('Grupo'!$K$34:$K$39,MATCH("?*",'Grupo'!$K$34:$K$39,0))&"","") | AC21: =IF(LEN(AB21)>0,AB21,AC22)
A22: Sessão atual | B22: =IF(ISNUMBER('Campanha'!$AD$10),'Campanha'!$AD$10,"(vazia)")&" · dia de campanha "&'Campanha'!$B$41 | G22: Aba Campanha, Mesa. | AA22: =SUMPRODUCT((LEN('Grupo'!$K$43:$K$48)>0)*1) | AB22: =IFERROR(INDEX('Grupo'!$K$43:$K$48,MATCH("?*",'Grupo'!$K$43:$K$48,0))&"","") | AC22: =IF(LEN(AB22)>0,AB22,AC23)
A23: Nível e faixa | B23: ="Nível "&'Campanha'!$B$17&", faixa "&'Campanha'!$B$19&" · Eficiência +"&'Campanha'!$B$20 | G23: 26.1, 26.2, 26.3. | AA23: =SUMPRODUCT((LEN('Grupo'!$K$52:$K$57)>0)*1) | AB23: =IFERROR(INDEX('Grupo'!$K$52:$K$57,MATCH("?*",'Grupo'!$K$52:$K$57,0))&"","") | AC23: =IF(LEN(AB23)>0,AB23,AC24)
A24: PH do grupo | B24: ="Máximo "&'Campanha'!$B$24&" · início do combate "&'Campanha'!$B$25&" ("&'Campanha'!$B$21&" jogadores)" | G24: 16.2. | AA24: =SUMPRODUCT((LEN('Grupo'!$K$61:$K$66)>0)*1) | AB24: =IFERROR(INDEX('Grupo'!$K$61:$K$66,MATCH("?*",'Grupo'!$K$61:$K$66,0))&"","") | AC24: =IF(LEN(AB24)>0,AB24,AC25)
A25: Missões ativas | B25: ='Missões'!$C$54&" ativa(s) · "&'Missões'!$B$54&" oferecida(s) · "&'Missões'!$D$54&" concluída(s)" | G25: Aba Missões. | AA25: =SUMPRODUCT((LEN('Grupo'!$K$70:$K$75)>0)*1) | AB25: =IFERROR(INDEX('Grupo'!$K$70:$K$75,MATCH("?*",'Grupo'!$K$70:$K$75,0))&"","") | AC25: =IF(LEN(AB25)>0,AB25,AC26)
A26: Relógios a 1 de encher | B26: =COUNTIF('Campanha'!$G$62:$G$71,"Falta 1") | G26: Aba Campanha, relógios (Sugestão da planilha, H16). | AA26: =SUMPRODUCT((LEN('Grupo'!$C$79:$C$79)>0)*1) | AB26: =IFERROR(INDEX('Grupo'!$C$79:$C$79,MATCH("?*",'Grupo'!$C$79:$C$79,0))&"","") | AC26: =IF(LEN(AB26)>0,AB26,"")
A27: Próxima Ressonância | B27: ='Campanha'!$B$39 | G27: 26.7; sempre marco de história.
A28: Sessões no nível atual | B28: =IF(ISNUMBER('Campanha'!$AD$38),'Campanha'!$AD$38&IF('Campanha'!$AD$38=1," sessão"," sessões")&" no nível · ","")&'Campanha'!$E$38 | G28: 26.1. | AA28: =SUMPRODUCT((LEN('Sessões'!$K$7:$K$10)>0)*1) | AB28: =IFERROR(INDEX('Sessões'!$K$7:$K$10,MATCH("?*",'Sessões'!$K$7:$K$10,0))&"","") | AC28: =IF(LEN(AB28)>0,AB28,AC29)
A29: Próxima sessão preparada | B29: =IF(LEN('Sessões'!$R$9)>0,IF(ISNUMBER('Sessões'!$R$7),"Sessão "&'Sessões'!$R$7&": ","")&'Sessões'!$R$9,"(nenhuma: aba Sessões)") | G29: Aba Sessões. | AA29: =SUMPRODUCT((LEN('Sessões'!$K$14:$K$18)>0)*1) | AB29: =IFERROR(INDEX('Sessões'!$K$14:$K$18,MATCH("?*",'Sessões'!$K$14:$K$18,0))&"","") | AC29: =IF(LEN(AB29)>0,AB29,AC30)
AA30: =SUMPRODUCT((LEN('Sessões'!$K$28:$K$37)>0)*1) | AB30: =IFERROR(INDEX('Sessões'!$K$28:$K$37,MATCH("?*",'Sessões'!$K$28:$K$37,0))&"","") | AC30: =IF(LEN(AB30)>0,AB30,AC31)
A31: Índice das abas | AA31: =SUMPRODUCT((LEN('Sessões'!$K$41:$K$41)>0)*1) | AB31: =IFERROR(INDEX('Sessões'!$K$41:$K$41,MATCH("?*",'Sessões'!$K$41:$K$41,0))&"","") | AC31: =IF(LEN(AB31)>0,AB31,AC32)
A32: Aba | B32: Para que serve | H32: Quando usar | AA32: =SUMPRODUCT((LEN('Sessões'!$K$46:$K$51)>0)*1) | AB32: =IFERROR(INDEX('Sessões'!$K$46:$K$51,MATCH("?*",'Sessões'!$K$46:$K$51,0))&"","") | AC32: =IF(LEN(AB32)>0,AB32,AC33)
A33: Início | B33: Semente da campanha, painel, índice e avisos. | H33: Na primeira vez e no começo de cada sessão. | AA33: =SUMPRODUCT((LEN('Sessões'!$K$55:$K$59)>0)*1) | AB33: =IFERROR(INDEX('Sessões'!$K$55:$K$59,MATCH("?*",'Sessões'!$K$55:$K$59,0))&"","") | AC33: =IF(LEN(AB33)>0,AB33,AC34)
A34: Campanha | B34: Mesa, marcos, facções, relógios, linha do tempo, Ficha de Decisões e Sessão Zero. | H34: Ao começar e entre sessões. | AA34: =SUMPRODUCT((LEN('Sessões'!$K$64:$K$73)>0)*1) | AB34: =IFERROR(INDEX('Sessões'!$K$64:$K$73,MATCH("?*",'Sessões'!$K$64:$K$73,0))&"","") | AC34: =IF(LEN(AB34)>0,AB34,AC35)
A35: Grupo | B35: Os PJs copiados da ficha de cada jogador, com os testes que o Mestre pede. | H35: Ao começar e quando a ficha muda. | AA35: =SUMPRODUCT((LEN('Sessões'!$K$75:$K$84)>0)*1) | AB35: =IFERROR(INDEX('Sessões'!$K$75:$K$84,MATCH("?*",'Sessões'!$K$75:$K$84,0))&"","") | AC35: =IF(LEN(AB35)>0,AB35,AC36)
A36: Sessões | B36: Preparar a próxima sessão (cenas, pistas, ganchos, checklist) e o diário. | H36: Entre sessões. | AA36: =SUMPRODUCT((LEN('Sessões'!$K$86:$K$95)>0)*1) | AB36: =IFERROR(INDEX('Sessões'!$K$86:$K$95,MATCH("?*",'Sessões'!$K$86:$K$95,0))&"","") | AC36: =IF(LEN(AB36)>0,AB36,AC37)
A37: Missões | B37: Missões oferecidas, ativas e concluídas. | H37: Entre sessões. | AA37: =SUMPRODUCT((LEN('Sessões'!$K$98:$K$107)>0)*1) | AB37: =IFERROR(INDEX('Sessões'!$K$98:$K$107,MATCH("?*",'Sessões'!$K$98:$K$107,0))&"","") | AC37: =IF(LEN(AB37)>0,AB37,AC38)
A38: NPCs | B38: Gerador de NPCs, elenco e cartões. | H38: Preparando a história. | AA38: =SUMPRODUCT((LEN('Sessões'!$K$109:$K$118)>0)*1) | AB38: =IFERROR(INDEX('Sessões'!$K$109:$K$118,MATCH("?*",'Sessões'!$K$109:$K$118,0))&"","") | AC38: =IF(LEN(AB38)>0,AB38,AC39)
A39: Inimigos | B39: Criador de Inimigos: a ficha de 28.1 pronta. | H39: Preparando o combate. | AA39: =SUMPRODUCT((LEN('Sessões'!$K$120:$K$129)>0)*1) | AB39: =IFERROR(INDEX('Sessões'!$K$120:$K$129,MATCH("?*",'Sessões'!$K$120:$K$129,0))&"","") | AC39: =IF(LEN(AB39)>0,AB39,"")
A40: Bestiário | B40: As 32 fichas do capítulo 28 com filtro. | H40: Preparando o combate.
...

Sheet Campanha
A1: Campanha — Explorando Galáxias v1.2
A2: Legenda: | B2: Entrada (preencha) | C2: Calculada (automático) | D2: Aviso (texto em vermelho) | E2: Título de bloco | F2: Cabeçalho de coluna | G2: Rótulo da linha | H2: Linha alternada (outro tom) | I2: Não se aplica
A3: A mesa, os marcos, as facções e a reputação, os relógios, a linha do tempo, a Ficha de Decisões e a Sessão Zero.
A5: Mesa (preencha uma vez: todas as abas leem daqui — D9) | AA5: ='Tabelas'!$X$12&""
A6: Campo | B6: Valor (preencha) | E6: O que a planilha usa (automático) | K6: Aviso | AA6: ='Tabelas'!$X$13&""
A7: Nome da campanha | E7: ="A campanha aparece no título das abas de jogo." | K7: =IF(AM7>0,"O Google leu como fórmula: digite de novo com ' na frente.","") | AA7: ='Tabelas'!$X$14&"" | AD7: =IF(ISERROR($B$7),"",IF(ISBLANK($B$7),"",$B$7)) | AM7: =ISERROR($B$7)*1
A8: Nº de jogadores | E8: =IF(ISNUMBER($AD$8),"Jogadores na mesa: "&$B$21&".","Vazio: usando o nº de PJs da aba Grupo ("&$B$21&").") | K8: =IF(AM8>0,"O Google leu como fórmula: digite de novo com ' na frente.",IF(LEN($AD$8)=0,"",IF(NOT(ISNUMBER($AD$8)),"Nº de jogadores não é número: usando o nº de PJs do Grupo",IF(OR($AD$8<1,$AD$8>6,INT($AD$8)<>$AD$8),"Nº de jogadores fora de 1 a 6: usando o limite",IF(OR($AD$8<3,$AD$8>6),"Fora da tabela de 16.2 (3 a 6): PH calculado com o limite 3 a 6",""))))) | AA8: ='Tabelas'!$X$15&"" | AD8: =IF(ISERROR($B$8),"",IF(ISBLANK($B$8),"",$B$8)) | AM8: =ISERROR($B$8)*1
A9: Nível do grupo | E9: =IF(ISNUMBER($AD$9),"Nível "&$B$17&", faixa "&$B$19&".","Vazio: as abas calculam com o nível 1 (faixa 1-4).") | K9: =IF(AM9>0,"O Google leu como fórmula: digite de novo com ' na frente.",IF(LEN($AD$9)=0,"",IF(NOT(ISNUMBER($AD$9)),"Nível não é número: usando 1",IF(OR($AD$9<1,$AD$9>20,INT($AD$9)<>$AD$9),"Nível fora de 1 a 20: usando o limite","")))) | AA9: ='Tabelas'!$X$16&"" | AD9: =IF(ISERROR($B$9),"",IF(ISBLANK($B$9),"",$B$9)) | AM9: =ISERROR($B$9)*1
A10: Sessão atual | E10: ="Lida pela aba Sessões (preparação e diário) e pela Início." | K10: =IF(AM10>0,"O Google leu como fórmula: digite de novo com ' na frente.","") | AA10: ='Tabelas'!$X$17&"" | AD10: =IF(ISERROR($B$10),"",IF(ISBLANK($B$10),"",$B$10)) | AM10: =ISERROR($B$10)*1
A11: Dia de campanha | E11: ="Usado pela linha do tempo (nesta aba, mais abaixo)." | K11: =IF(AM11>0,"O Google leu como fórmula: digite de novo com ' na frente.","") | AA11: ='Tabelas'!$X$18&"" | AD11: =IF(ISERROR($B$11),"",IF(ISBLANK($B$11),"",$B$11)) | AM11: =ISERROR($B$11)*1
A12: Método de atributos | E12: ="Lembrete da Sessão Zero (capítulo 03)." | K12: =IF(AM12>0,"O Google leu como fórmula: escolha de novo na lista.","") | AA12: ='Tabelas'!$X$19&"" | AD12: =IF(ISERROR($B$12),"",IF(ISBLANK($B$12),"",$B$12)) | AM12: =ISERROR($B$12)*1
A13: Variantes da mesa | E13: ="Texto livre: média impressa, PV rolado, outra variante (06.4, 28.3)." | K13: =IF(AM13>0,"O Google leu como fórmula: digite de novo com ' na frente.","") | AA13: ='Tabelas'!$X$20&"" | AD13: =IF(ISERROR($B$13),"",IF(ISBLANK($B$13),"",$B$13)) | AM13: =ISERROR($B$13)*1
AA14: ='Tabelas'!$X$21&""
A15: Números do grupo (automático) | AA15: ='Tabelas'!$X$22&""
A16: Campo | B16: Valor | D16: Fonte no livro | G16: Observação | AA16: ='Tabelas'!$X$23&""
A17: Nível efetivo | B17: =IF(ISNUMBER($AD$9),MIN(20,MAX(1,INT($AD$9))),1) | D17: 26.1 | G17: Vazio = 1. | AA17: ='Tabelas'!$X$24&""
A18: Índice da faixa | B18: =INT(($B$17-1)/4)+1 | D18: 26.3 | G18: 1 a 5. | AA18: ='Tabelas'!$X$26&""
A19: Faixa do grupo | B19: =INDEX('Dados'!$B$7:$B$11,$B$18) | D19: 26.3 | G19: A faixa do inimigo é a faixa do grupo (28.4 passo 1). | AA19: ='Tabelas'!$X$27&""
A20: Eficiência | B20: =INDEX('Dados'!$B$15:$B$34,$B$17) | D20: 26.2 (02.3) | G20: Usada no Dano de Quebra e nas condições. | AA20: ='Tabelas'!$X$28&""
A21: Nº de jogadores efetivo | B21: =IF(ISNUMBER($AD$8),MIN(6,MAX(1,INT($AD$8))),MAX(1,'Grupo'!$B$79)) | D21: 16.2 | G21: Vazio = nº de PJs da aba Grupo (mínimo 1). | AA21: ='Tabelas'!$X$29&""
A22: Jogadores para o PH | B22: =MIN(6,MAX(3,$B$21)) | D22: 16.2 | G22: A tabela de 16.2 vai de 3 a 6 jogadores. | AA22: ='Tabelas'!$X$30&""
A23: Degrau de PH | B23: =IF($B$17<=8,1,IF($B$17<=16,2,3)) | D23: 16.2 | G23: 1 = níveis 1-8; 2 = 9-16; 3 = 17-20. | AA23: ='Tabelas'!$X$31&""
A24: PH máximo do grupo | B24: =IF($B$23=1,INDEX('Dados'!$B$343:$B$346,MATCH($B$22,'Dados'!$A$343:$A$346,0)),IF($B$23=2,INDEX('Dados'!$C$343:$C$346,MATCH($B$22,'Dados'!$A$343:$A$346,0)),INDEX('Dados'!$D$343:$D$346,MATCH($B$22,'Dados'!$A$343:$A$346,0)))) | D24: 16.2 | G24: Degraus 1-8, 9-16 e 17-20. | AA24: ='Tabelas'!$X$32&""
A25: PH no início do combate | B25: =IF($B$23=1,INDEX('Dados'!$E$343:$E$346,MATCH($B$22,'Dados'!$A$343:$A$346,0)),IF($B$23=2,INDEX('Dados'!$F$343:$F$346,MATCH($B$22,'Dados'!$A$343:$A$346,0)),INDEX('Dados'!$G$343:$G$346,MATCH($B$22,'Dados'!$A$343:$A$346,0)))) | D25: 16.2 | G25: Começa cada combate com o máximo menos 2. | AA25: ='Tabelas'!$X$33&""
A26: Campo | B26: Valor | D26: Fonte no livro | G26: Observação | AA26: ='Tabelas'!$X$34&""
A27: DT Média da faixa | B27: =IF($B$18=1,INDEX('Dados'!$B$284:$B$289,3),IF($B$18=2,INDEX('Dados'!$C$284:$C$289,3),IF($B$18=3,INDEX('Dados'!$D$284:$D$289,3),IF($B$18=4,INDEX('Dados'!$E$284:$E$289,3),INDEX('Dados'!$F$284:$F$289,3))))) | D27: 27.2 | G27: Regra 1: a faixa é a do desafio, não a do personagem. | AA27: ='Tabelas'!$X$35&""
A28: DT Difícil da faixa | B28: =IF($B$18=1,INDEX('Dados'!$B$284:$B$289,4),IF($B$18=2,INDEX('Dados'!$C$284:$C$289,4),IF($B$18=3,INDEX('Dados'!$D$284:$D$289,4),IF($B$18=4,INDEX('Dados'!$E$284:$E$289,4),INDEX('Dados'!$F$284:$F$289,4))))) | D28: 27.2 | AA28: ='Tabelas'!$X$36&""
A29: DT para descobrir Fraqueza | B29: =IFERROR(INDEX('Dados'!$B$293:$B$297,MATCH($B$19,'Dados'!$A$293:$A$297,0)),"") | D29: 20.2 | G29: Pela faixa do inimigo mais forte da cena. | AA29: ='Tabelas'!$X$37&""
A30: Cone de Luz máximo | B30: =IFERROR(INDEX('Dados'!$B$380:$B$384,MATCH($B$19,'Dados'!$A$380:$A$384,0)),"") | D30: 25.1 | AA30: ='Tabelas'!$X$38&""
A31: Relíquias | B31: =IFERROR(INDEX('Dados'!$C$380:$C$384,MATCH($B$19,'Dados'!$A$380:$A$384,0)),"") | D31: 25.1 | AA31: ='Tabelas'!$X$40&""
A32: Verba de marco (Cr) | B32: =IFERROR(INDEX('Dados'!$B$372:$B$376,MATCH($B$19,'Dados'!$A$372:$A$376,0)),"") | D32: 24.5 | G32: Por marco, para o grupo. | AA32: ='Tabelas'!$X$41&""
AA33: ='Tabelas'!$X$42&""
A34: Não existe experiência por inimigo derrotado: a progressão é por marco narrativo (26.1). | AA34: ='Tabelas'!$X$43&""
AA35: ='Tabelas'!$X$44&""
A36: Marcos e progressão (26.1): o grupo sobe de nível junto, por marco narrativo | AA36: ='Tabelas'!$X$45&""
A37: Campo | B37: Valor | E37: O que a planilha usa (automático) | K37: Aviso | AA37: ='Tabelas'!$X$46&""
A38: Sessões jogadas no nível atual | E38: ="Ritmo sugerido: "&IF($B$17<='Dados'!$B$724,'Dados'!$E$724,'Dados'!$E$725)&" (26.1)." | K38: =IF(AM38>0,"O Google leu como fórmula: digite de novo com ' na frente.",IF(LEN($AD$38)=0,"",IF(NOT(ISNUMBER($AD$38)),"Sessões não é número",IF(OR($AD$38<0,$AD$38>99,INT($AD$38)<>$AD$38),"Sessões fora de 0 a 99",IF($AD$38>IF($B$17<='Dados'!$B$724,'Dados'!$D$724,'Dados'!$D$725),"Ritmo acima do sugerido (26.1): mais de "&IF($B$17<='Dados'!$B$724,'Dados'!$D$724,'Dados'!$D$725)&" sessões no nível",""))))) | AA38: ='Tabelas'!$X$47&"" | AD38: =IF(ISERROR($B$38),"",IF(ISBLANK($B$38),"",$B$38)) | AM38: =ISERROR($B$38)*1
A39: Próxima Ressonância | B39: =IF((COUNTIF('Dados'!$B$490:$B$493,"<="&$B$17)+1)>4,"Todas (nível 20)","Ressonância "&INDEX('Dados'!$A$490:$A$493,MIN(4,(COUNTIF('Dados'!$B$490:$B$493,"<="&$B$17)+1)))&" no nível "&INDEX('Dados'!$B$490:$B$493,MIN(4,(COUNTIF('Dados'!$B$490:$B$493,"<="&$B$17)+1)))) | E39: Sempre um marco de história, escolhida com o Mestre na hora (26.1, 26.7). É o lugar natural para fechar um capítulo do Propósito de Vida de alguém. | AA39: ='Tabelas'!$X$48&""
A40: Marcos concluídos | B40: =COUNTIFS('Missões'!$AK$8:$AK$28,"Concluída",'Missões'!$AD$31:$AD$51,"Sim") | E40: Missões concluídas que eram marco de nível (aba Missões). | AA40: ='Tabelas'!$X$49&""
A41: Dia de campanha efetivo | B41: =IF(ISNUMBER($AD$11),MAX(1,INT($AD$11)),1) | E41: Vazio = dia 1. A linha do tempo mostra os próximos eventos a partir deste dia. | AA41: ='Tabelas'!$X$50&""
...

Sheet Grupo
A1: Grupo — Explorando Galáxias v1.2
A2: Legenda: | B2: Entrada (preencha) | C2: Calculada (automático) | D2: Aviso (texto em vermelho) | E2: Título de bloco | F2: Cabeçalho de coluna | G2: Rótulo da linha | H2: Linha alternada (outro tom) | I2: Não se aplica
A3: Os personagens jogadores, copiados da ficha de cada jogador (uma linha por PJ).
A5: G1 · Quem é (preencha, da ficha de cada jogador)
A6: Nome do PJ | B6: Jogador | C6: Raça | D6: Caminho | E6: Elemento | F6: Propósito de Vida | I6: Crença do Esforço (Humano) | K6: Aviso
K7: =IF(Z7>0,"O Google leu como fórmula: escolha de novo ou digite com ' na frente.",IF(AND(LEN($R$7)>0,COUNTIF('Dados'!$A$350:$A$356,$R$7)=0),"Raça fora da lista do capítulo 05",IF(AND(LEN($T$7)>0,COUNTIF($T$7:$T$12,$T$7)>1),"Elemento repetido no grupo: cuidado com a Resistência (regra irmã, 27.5)",IF(AND(LEN($P$7)=0,LEN($R$7&$T$7&$S$7)>0),"Linha sem nome: o PJ não entra na contagem","")))) | P7: =IF(ISERROR($A$7),"",IF(ISBLANK($A$7),"",$A$7)) | R7: =IF(ISERROR($C$7),"",IF(ISBLANK($C$7),"",$C$7)) | S7: =IF(ISERROR($D$7),"",IF(ISBLANK($D$7),"",$D$7)) | T7: =IF(ISERROR($E$7),"",IF(ISBLANK($E$7),"",$E$7)) | U7: =IF(ISERROR($F$7),"",IF(ISBLANK($F$7),"",$F$7)) | Z7: =ISERROR($A$7)*1+ISERROR($B$7)*1+ISERROR($C$7)*1+ISERROR($D$7)*1+ISERROR($E$7)*1+ISERROR($F$7)*1+ISERROR($I$7)*1
K8: =IF(Z8>0,"O Google leu como fórmula: escolha de novo ou digite com ' na frente.",IF(AND(LEN($R$8)>0,COUNTIF('Dados'!$A$350:$A$356,$R$8)=0),"Raça fora da lista do capítulo 05",IF(AND(LEN($T$8)>0,COUNTIF($T$7:$T$12,$T$8)>1),"Elemento repetido no grupo: cuidado com a Resistência (regra irmã, 27.5)",IF(AND(LEN($P$8)=0,LEN($R$8&$T$8&$S$8)>0),"Linha sem nome: o PJ não entra na contagem","")))) | P8: =IF(ISERROR($A$8),"",IF(ISBLANK($A$8),"",$A$8)) | R8: =IF(ISERROR($C$8),"",IF(ISBLANK($C$8),"",$C$8)) | S8: =IF(ISERROR($D$8),"",IF(ISBLANK($D$8),"",$D$8)) | T8: =IF(ISERROR($E$8),"",IF(ISBLANK($E$8),"",$E$8)) | U8: =IF(ISERROR($F$8),"",IF(ISBLANK($F$8),"",$F$8)) | Z8: =ISERROR($A$8)*1+ISERROR($B$8)*1+ISERROR($C$8)*1+ISERROR($D$8)*1+ISERROR($E$8)*1+ISERROR($F$8)*1+ISERROR($I$8)*1
K9: =IF(Z9>0,"O Google leu como fórmula: escolha de novo ou digite com ' na frente.",IF(AND(LEN($R$9)>0,COUNTIF('Dados'!$A$350:$A$356,$R$9)=0),"Raça fora da lista do capítulo 05",IF(AND(LEN($T$9)>0,COUNTIF($T$7:$T$12,$T$9)>1),"Elemento repetido no grupo: cuidado com a Resistência (regra irmã, 27.5)",IF(AND(LEN($P$9)=0,LEN($R$9&$T$9&$S$9)>0),"Linha sem nome: o PJ não entra na contagem","")))) | P9: =IF(ISERROR($A$9),"",IF(ISBLANK($A$9),"",$A$9)) | R9: =IF(ISERROR($C$9),"",IF(ISBLANK($C$9),"",$C$9)) | S9: =IF(ISERROR($D$9),"",IF(ISBLANK($D$9),"",$D$9)) | T9: =IF(ISERROR($E$9),"",IF(ISBLANK($E$9),"",$E$9)) | U9: =IF(ISERROR($F$9),"",IF(ISBLANK($F$9),"",$F$9)) | Z9: =ISERROR($A$9)*1+ISERROR($B$9)*1+ISERROR($C$9)*1+ISERROR($D$9)*1+ISERROR($E$9)*1+ISERROR($F$9)*1+ISERROR($I$9)*1
K10: =IF(Z10>0,"O Google leu como fórmula: escolha de novo ou digite com ' na frente.",IF(AND(LEN($R$10)>0,COUNTIF('Dados'!$A$350:$A$356,$R$10)=0),"Raça fora da lista do capítulo 05",IF(AND(LEN($T$10)>0,COUNTIF($T$7:$T$12,$T$10)>1),"Elemento repetido no grupo: cuidado com a Resistência (regra irmã, 27.5)",IF(AND(LEN($P$10)=0,LEN($R$10&$T$10&$S$10)>0),"Linha sem nome: o PJ não entra na contagem","")))) | P10: =IF(ISERROR($A$10),"",IF(ISBLANK($A$10),"",$A$10)) | R10: =IF(ISERROR($C$10),"",IF(ISBLANK($C$10),"",$C$10)) | S10: =IF(ISERROR($D$10),"",IF(ISBLANK($D$10),"",$D$10)) | T10: =IF(ISERROR($E$10),"",IF(ISBLANK($E$10),"",$E$10)) | U10: =IF(ISERROR($F$10),"",IF(ISBLANK($F$10),"",$F$10)) | Z10: =ISERROR($A$10)*1+ISERROR($B$10)*1+ISERROR($C$10)*1+ISERROR($D$10)*1+ISERROR($E$10)*1+ISERROR($F$10)*1+ISERROR($I$10)*1
K11: =IF(Z11>0,"O Google leu como fórmula: escolha de novo ou digite com ' na frente.",IF(AND(LEN($R$11)>0,COUNTIF('Dados'!$A$350:$A$356,$R$11)=0),"Raça fora da lista do capítulo 05",IF(AND(LEN($T$11)>0,COUNTIF($T$7:$T$12,$T$11)>1),"Elemento repetido no grupo: cuidado com a Resistência (regra irmã, 27.5)",IF(AND(LEN($P$11)=0,LEN($R$11&$T$11&$S$11)>0),"Linha sem nome: o PJ não entra na contagem","")))) | P11: =IF(ISERROR($A$11),"",IF(ISBLANK($A$11),"",$A$11)) | R11: =IF(ISERROR($C$11),"",IF(ISBLANK($C$11),"",$C$11)) | S11: =IF(ISERROR($D$11),"",IF(ISBLANK($D$11),"",$D$11)) | T11: =IF(ISERROR($E$11),"",IF(ISBLANK($E$11),"",$E$11)) | U11: =IF(ISERROR($F$11),"",IF(ISBLANK($F$11),"",$F$11)) | Z11: =ISERROR($A$11)*1+ISERROR($B$11)*1+ISERROR($C$11)*1+ISERROR($D$11)*1+ISERROR($E$11)*1+ISERROR($F$11)*1+ISERROR($I$11)*1
K12: =IF(Z12>0,"O Google leu como fórmula: escolha de novo ou digite com ' na frente.",IF(AND(LEN($R$12)>0,COUNTIF('Dados'!$A$350:$A$356,$R$12)=0),"Raça fora da lista do capítulo 05",IF(AND(LEN($T$12)>0,COUNTIF($T$7:$T$12,$T$12)>1),"Elemento repetido no grupo: cuidado com a Resistência (regra irmã, 27.5)",IF(AND(LEN($P$12)=0,LEN($R$12&$T$12&$S$12)>0),"Linha sem nome: o PJ não entra na contagem","")))) | P12: =IF(ISERROR($A$12),"",IF(ISBLANK($A$12),"",$A$12)) | R12: =IF(ISERROR($C$12),"",IF(ISBLANK($C$12),"",$C$12)) | S12: =IF(ISERROR($D$12),"",IF(ISBLANK($D$12),"",$D$12)) | T12: =IF(ISERROR($E$12),"",IF(ISBLANK($E$12),"",$E$12)) | U12: =IF(ISERROR($F$12),"",IF(ISBLANK($F$12),"",$F$12)) | Z12: =ISERROR($A$12)*1+ISERROR($B$12)*1+ISERROR($C$12)*1+ISERROR($D$12)*1+ISERROR($E$12)*1+ISERROR($F$12)*1+ISERROR($I$12)*1
A14: G2 · Números de combate (preencha, da aba Em Jogo da ficha)
A15: PJ | B15: PV máx. | C15: Defesa | D15: Esquiva | E15: RD | F15: VEL | G15: Bônus de Agilidade | H15: Bônus de Discernimento | I15: Bônus de Presença | J15: DT das Habilidades | K15: Aviso
A16: =IF(LEN($P$7)>0,$P$7,"PJ 1") | K16: =IF(Z16>0,"O Google leu como fórmula: digite de novo com ' na frente.",IF(AND(ISNUMBER($U$16),OR($U$16<7,$U$16>25)),"VEL fora dos extremos 7 a 25 da fórmula: confira na ficha (19.1)",IF(OR(AND(ISNUMBER($V$16),OR($V$16<-1,$V$16>5)),AND(ISNUMBER($W$16),OR($W$16<-1,$W$16>5)),AND(ISNUMBER($X$16),OR($X$16<-1,$X$16>5))),"Bônus de Atributo fora de -1 a +5: confira na ficha",IF(AND(ISNUMBER($Q$16),OR($Q$16<1,$Q$16>999)),"PV fora de 1 a 999: confira na ficha","")))) | Q16: =IF(ISERROR($B$16),"",IF(ISBLANK($B$16),"",$B$16)) | U16: =IF(ISERROR($F$16),"",IF(ISBLANK($F$16),"",$F$16)) | V16: =IF(ISERROR($G$16),"",IF(ISBLANK($G$16),"",$G$16)) | W16: =IF(ISERROR($H$16),"",IF(ISBLANK($H$16),"",$H$16)) | X16: =IF(ISERROR($I$16),"",IF(ISBLANK($I$16),"",$I$16)) | Z16: =ISERROR($B$16)*1+ISERROR($C$16)*1+ISERROR($D$16)*1+ISERROR($E$16)*1+ISERROR($F$16)*1+ISERROR($G$16)*1+ISERROR($H$16)*1+ISERROR($I$16)*1+ISERROR($J$16)*1
A17: =IF(LEN($P$8)>0,$P$8,"PJ 2") | K17: =IF(Z17>0,"O Google leu como fórmula: digite de novo com ' na frente.",IF(AND(ISNUMBER($U$17),OR($U$17<7,$U$17>25)),"VEL fora dos extremos 7 a 25 da fórmula: confira na ficha (19.1)",IF(OR(AND(ISNUMBER($V$17),OR($V$17<-1,$V$17>5)),AND(ISNUMBER($W$17),OR($W$17<-1,$W$17>5)),AND(ISNUMBER($X$17),OR($X$17<-1,$X$17>5))),"Bônus de Atributo fora de -1 a +5: confira na ficha",IF(AND(ISNUMBER($Q$17),OR($Q$17<1,$Q$17>999)),"PV fora de 1 a 999: confira na ficha","")))) | Q17: =IF(ISERROR($B$17),"",IF(ISBLANK($B$17),"",$B$17)) | U17: =IF(ISERROR($F$17),"",IF(ISBLANK($F$17),"",$F$17)) | V17: =IF(ISERROR($G$17),"",IF(ISBLANK($G$17),"",$G$17)) | W17: =IF(ISERROR($H$17),"",IF(ISBLANK($H$17),"",$H$17)) | X17: =IF(ISERROR($I$17),"",IF(ISBLANK($I$17),"",$I$17)) | Z17: =ISERROR($B$17)*1+ISERROR($C$17)*1+ISERROR($D$17)*1+ISERROR($E$17)*1+ISERROR($F$17)*1+ISERROR($G$17)*1+ISERROR($H$17)*1+ISERROR($I$17)*1+ISERROR($J$17)*1
A18: =IF(LEN($P$9)>0,$P$9,"PJ 3") | K18: =IF(Z18>0,"O Google leu como fórmula: digite de novo com ' na frente.",IF(AND(ISNUMBER($U$18),OR($U$18<7,$U$18>25)),"VEL fora dos extremos 7 a 25 da fórmula: confira na ficha (19.1)",IF(OR(AND(ISNUMBER($V$18),OR($V$18<-1,$V$18>5)),AND(ISNUMBER($W$18),OR($W$18<-1,$W$18>5)),AND(ISNUMBER($X$18),OR($X$18<-1,$X$18>5))),"Bônus de Atributo fora de -1 a +5: confira na ficha",IF(AND(ISNUMBER($Q$18),OR($Q$18<1,$Q$18>999)),"PV fora de 1 a 999: confira na ficha","")))) | Q18: =IF(ISERROR($B$18),"",IF(ISBLANK($B$18),"",$B$18)) | U18: =IF(ISERROR($F$18),"",IF(ISBLANK($F$18),"",$F$18)) | V18: =IF(ISERROR($G$18),"",IF(ISBLANK($G$18),"",$G$18)) | W18: =IF(ISERROR($H$18),"",IF(ISBLANK($H$18),"",$H$18)) | X18: =IF(ISERROR($I$18),"",IF(ISBLANK($I$18),"",$I$18)) | Z18: =ISERROR($B$18)*1+ISERROR($C$18)*1+ISERROR($D$18)*1+ISERROR($E$18)*1+ISERROR($F$18)*1+ISERROR($G$18)*1+ISERROR($H$18)*1+ISERROR($I$18)*1+ISERROR($J$18)*1
A19: =IF(LEN($P$10)>0,$P$10,"PJ 4") | K19: =IF(Z19>0,"O Google leu como fórmula: digite de novo com ' na frente.",IF(AND(ISNUMBER($U$19),OR($U$19<7,$U$19>25)),"VEL fora dos extremos 7 a 25 da fórmula: confira na ficha (19.1)",IF(OR(AND(ISNUMBER($V$19),OR($V$19<-1,$V$19>5)),AND(ISNUMBER($W$19),OR($W$19<-1,$W$19>5)),AND(ISNUMBER($X$19),OR($X$19<-1,$X$19>5))),"Bônus de Atributo fora de -1 a +5: confira na ficha",IF(AND(ISNUMBER($Q$19),OR($Q$19<1,$Q$19>999)),"PV fora de 1 a 999: confira na ficha","")))) | Q19: =IF(ISERROR($B$19),"",IF(ISBLANK($B$19),"",$B$19)) | U19: =IF(ISERROR($F$19),"",IF(ISBLANK($F$19),"",$F$19)) | V19: =IF(ISERROR($G$19),"",IF(ISBLANK($G$19),"",$G$19)) | W19: =IF(ISERROR($H$19),"",IF(ISBLANK($H$19),"",$H$19)) | X19: =IF(ISERROR($I$19),"",IF(ISBLANK($I$19),"",$I$19)) | Z19: =ISERROR($B$19)*1+ISERROR($C$19)*1+ISERROR($D$19)*1+ISERROR($E$19)*1+ISERROR($F$19)*1+ISERROR($G$19)*1+ISERROR($H$19)*1+ISERROR($I$19)*1+ISERROR($J$19)*1
A20: =IF(LEN($P$11)>0,$P$11,"PJ 5") | K20: =IF(Z20>0,"O Google leu como fórmula: digite de novo com ' na frente.",IF(AND(ISNUMBER($U$20),OR($U$20<7,$U$20>25)),"VEL fora dos extremos 7 a 25 da fórmula: confira na ficha (19.1)",IF(OR(AND(ISNUMBER($V$20),OR($V$20<-1,$V$20>5)),AND(ISNUMBER($W$20),OR($W$20<-1,$W$20>5)),AND(ISNUMBER($X$20),OR($X$20<-1,$X$20>5))),"Bônus de Atributo fora de -1 a +5: confira na ficha",IF(AND(ISNUMBER($Q$20),OR($Q$20<1,$Q$20>999)),"PV fora de 1 a 999: confira na ficha","")))) | Q20: =IF(ISERROR($B$20),"",IF(ISBLANK($B$20),"",$B$20)) | U20: =IF(ISERROR($F$20),"",IF(ISBLANK($F$20),"",$F$20)) | V20: =IF(ISERROR($G$20),"",IF(ISBLANK($G$20),"",$G$20)) | W20: =IF(ISERROR($H$20),"",IF(ISBLANK($H$20),"",$H$20)) | X20: =IF(ISERROR($I$20),"",IF(ISBLANK($I$20),"",$I$20)) | Z20: =ISERROR($B$20)*1+ISERROR($C$20)*1+ISERROR($D$20)*1+ISERROR($E$20)*1+ISERROR($F$20)*1+ISERROR($G$20)*1+ISERROR($H$20)*1+ISERROR($I$20)*1+ISERROR($J$20)*1
A21: =IF(LEN($P$12)>0,$P$12,"PJ 6") | K21: =IF(Z21>0,"O Google leu como fórmula: digite de novo com ' na frente.",IF(AND(ISNUMBER($U$21),OR($U$21<7,$U$21>25)),"VEL fora dos extremos 7 a 25 da fórmula: confira na ficha (19.1)",IF(OR(AND(ISNUMBER($V$21),OR($V$21<-1,$V$21>5)),AND(ISNUMBER($W$21),OR($W$21<-1,$W$21>5)),AND(ISNUMBER($X$21),OR($X$21<-1,$X$21>5))),"Bônus de Atributo fora de -1 a +5: confira na ficha",IF(AND(ISNUMBER($Q$21),OR($Q$21<1,$Q$21>999)),"PV fora de 1 a 999: confira na ficha","")))) | Q21: =IF(ISERROR($B$21),"",IF(ISBLANK($B$21),"",$B$21)) | U21: =IF(ISERROR($F$21),"",IF(ISBLANK($F$21),"",$F$21)) | V21: =IF(ISERROR($G$21),"",IF(ISBLANK($G$21),"",$G$21)) | W21: =IF(ISERROR($H$21),"",IF(ISBLANK($H$21),"",$H$21)) | X21: =IF(ISERROR($I$21),"",IF(ISBLANK($I$21),"",$I$21)) | Z21: =ISERROR($B$21)*1+ISERROR($C$21)*1+ISERROR($D$21)*1+ISERROR($E$21)*1+ISERROR($F$21)*1+ISERROR($G$21)*1+ISERROR($H$21)*1+ISERROR($I$21)*1+ISERROR($J$21)*1
A23: G3 · Equipamento de faixa (preencha)
A24: PJ | B24: Nível do Cone | C24: Tier de Relíquias | D24: Slots de Relíquia | E24: Sobreposições nesta faixa | F24: Total no Cone | G24: Ressonâncias escolhidas | K24: Aviso
A25: =IF(LEN($P$7)>0,$P$7,"PJ 1") | K25: =IF(Z25>0,"O Google leu como fórmula: digite de novo com ' na frente.",IF(AND(ISNUMBER($Q$25),$Q$25>'Campanha'!$B$18),"Cone acima do máximo da faixa (25.1)",IF(AND(ISNUMBER($T$25),$T$25>1),"Mais de 1 Sobreposição nesta faixa (25.2)",IF(AND(ISNUMBER($Q$25),$Q$25>=1,$Q$25<=5),IF(MAX(IF(ISNUMBER($U$25),$U$25,0),IF(ISNUMBER($T$25),$T$25,0))>INDEX('Dados'!$H$468:$H$472,INT($Q$25)),"Acima do teto do Cone (25.2): o Nível "&INT($Q$25)&" aceita até "&INDEX('Dados'!$H$468:$H$472,INT($Q$25)),IF(AND(ISNUMBER($U$25),ISNUMBER($T$25),$U$25<$T$25),"Total no Cone menor que as desta faixa","")),IF(AND(ISNUMBER($U$25),ISNUMBER($T$25),$U$25<$T$25),"Total no Cone menor que as desta faixa",""))))) | Q25: =IF(ISERROR($B$25),"",IF(ISBLANK($B$25),"",$B$25)) | R25: =IF(ISERROR($C$25),"",IF(ISBLANK($C$25),"",$C$25)) | T25: =IF(ISERROR($E$25),"",IF(ISBLANK($E$25),"",$E$25)) | U25: =IF(ISERROR($F$25),"",IF(ISBLANK($F$25),"",$F$25)) | Z25: =ISERROR($B$25)*1+ISERROR($C$25)*1+ISERROR($D$25)*1+ISERROR($E$25)*1+ISERROR($F$25)*1+ISERROR($G$25)*1
A26: =IF(LEN($P$8)>0,$P$8,"PJ 2") | K26: =IF(Z26>0,"O Google leu como fórmula: digite de novo com ' na frente.",IF(AND(ISNUMBER($Q$26),$Q$26>'Campanha'!$B$18),"Cone acima do máximo da faixa (25.1)",IF(AND(ISNUMBER($T$26),$T$26>1),"Mais de 1 Sobreposição nesta faixa (25.2)",IF(AND(ISNUMBER($Q$26),$Q$26>=1,$Q$26<=5),IF(MAX(IF(ISNUMBER($U$26),$U$26,0),IF(ISNUMBER($T$26),$T$26,0))>INDEX('Dados'!$H$468:$H$472,INT($Q$26)),"Acima do teto do Cone (25.2): o Nível "&INT($Q$26)&" aceita até "&INDEX('Dados'!$H$468:$H$472,INT($Q$26)),IF(AND(ISNUMBER($U$26),ISNUMBER($T$26),$U$26<$T$26),"Total no Cone menor que as desta faixa","")),IF(AND(ISNUMBER($U$26),ISNUMBER($T$26),$U$26<$T$26),"Total no Cone menor que as desta faixa",""))))) | Q26: =IF(ISERROR($B$26),"",IF(ISBLANK($B$26),"",$B$26)) | R26: =IF(ISERROR($C$26),"",IF(ISBLANK($C$26),"",$C$26)) | T26: =IF(ISERROR($E$26),"",IF(ISBLANK($E$26),"",$E$26)) | U26: =IF(ISERROR($F$26),"",IF(ISBLANK($F$26),"",$F$26)) | Z26: =ISERROR($B$26)*1+ISERROR($C$26)*1+ISERROR($D$26)*1+ISERROR($E$26)*1+ISERROR($F$26)*1+ISERROR($G$26)*1
A27: =IF(LEN($P$9)>0,$P$9,"PJ 3") | K27: =IF(Z27>0,"O Google leu como fórmula: digite de novo com ' na frente.",IF(AND(ISNUMBER($Q$27),$Q$27>'Campanha'!$B$18),"Cone acima do máximo da faixa (25.1)",IF(AND(ISNUMBER($T$27),$T$27>1),"Mais de 1 Sobreposição nesta faixa (25.2)",IF(AND(ISNUMBER($Q$27),$Q$27>=1,$Q$27<=5),IF(MAX(IF(ISNUMBER($U$27),$U$27,0),IF(ISNUMBER($T$27),$T$27,0))>INDEX('Dados'!$H$468:$H$472,INT($Q$27)),"Acima do teto do Cone (25.2): o Nível "&INT($Q$27)&" aceita até "&INDEX('Dados'!$H$468:$H$472,INT($Q$27)),IF(AND(ISNUMBER($U$27),ISNUMBER($T$27),$U$27<$T$27),"Total no Cone menor que as desta faixa","")),IF(AND(ISNUMBER($U$27),ISNUMBER($T$27),$U$27<$T$27),"Total no Cone menor que as desta faixa",""))))) | Q27: =IF(ISERROR($B$27),"",IF(ISBLANK($B$27),"",$B$27)) | R27: =IF(ISERROR($C$27),"",IF(ISBLANK($C$27),"",$C$27)) | T27: =IF(ISERROR($E$27),"",IF(ISBLANK($E$27),"",$E$27)) | U27: =IF(ISERROR($F$27),"",IF(ISBLANK($F$27),"",$F$27)) | Z27: =ISERROR($B$27)*1+ISERROR($C$27)*1+ISERROR($D$27)*1+ISERROR($E$27)*1+ISERROR($F$27)*1+ISERROR($G$27)*1
A28: =IF(LEN($P$10)>0,$P$10,"PJ 4") | K28: =IF(Z28>0,"O Google leu como fórmula: digite de novo com ' na frente.",IF(AND(ISNUMBER($Q$28),$Q$28>'Campanha'!$B$18),"Cone acima do máximo da faixa (25.1)",IF(AND(ISNUMBER($T$28),$T$28>1),"Mais de 1 Sobreposição nesta faixa (25.2)",IF(AND(ISNUMBER($Q$28),$Q$28>=1,$Q$28<=5),IF(MAX(IF(ISNUMBER($U$28),$U$28,0),IF(ISNUMBER($T$28),$T$28,0))>INDEX('Dados'!$H$468:$H$472,INT($Q$28)),"Acima do teto do Cone (25.2): o Nível "&INT($Q$28)&" aceita até "&INDEX('Dados'!$H$468:$H$472,INT($Q$28)),IF(AND(ISNUMBER($U$28),ISNUMBER($T$28),$U$28<$T$28),"Total no Cone menor que as desta faixa","")),IF(AND(ISNUMBER($U$28),ISNUMBER($T$28),$U$28<$T$28),"Total no Cone menor que as desta faixa",""))))) | Q28: =IF(ISERROR($B$28),"",IF(ISBLANK($B$28),"",$B$28)) | R28: =IF(ISERROR($C$28),"",IF(ISBLANK($C$28),"",$C$28)) | T28: =IF(ISERROR($E$28),"",IF(ISBLANK($E$28),"",$E$28)) | U28: =IF(ISERROR($F$28),"",IF(ISBLANK($F$28),"",$F$28)) | Z28: =ISERROR($B$28)*1+ISERROR($C$28)*1+ISERROR($D$28)*1+ISERROR($E$28)*1+ISERROR($F$28)*1+ISERROR($G$28)*1
A29: =IF(LEN($P$11)>0,$P$11,"PJ 5") | K29: =IF(Z29>0,"O Google leu como fórmula: digite de novo com ' na frente.",IF(AND(ISNUMBER($Q$29),$Q$29>'Campanha'!$B$18),"Cone acima do máximo da faixa (25.1)",IF(AND(ISNUMBER($T$29),$T$29>1),"Mais de 1 Sobreposição nesta faixa (25.2)",IF(AND(ISNUMBER($Q$29),$Q$29>=1,$Q$29<=5),IF(MAX(IF(ISNUMBER($U$29),$U$29,0),IF(ISNUMBER($T$29),$T$29,0))>INDEX('Dados'!$H$468:$H$472,INT($Q$29)),"Acima do teto do Cone (25.2): o Nível "&INT($Q$29)&" aceita até "&INDEX('Dados'!$H$468:$H$472,INT($Q$29)),IF(AND(ISNUMBER($U$29),ISNUMBER($T$29),$U$29<$T$29),"Total no Cone menor que as desta faixa","")),IF(AND(ISNUMBER($U$29),ISNUMBER($T$29),$U$29<$T$29),"Total no Cone menor que as desta faixa",""))))) | Q29: =IF(ISERROR($B$29),"",IF(ISBLANK($B$29),"",$B$29)) | R29: =IF(ISERROR($C$29),"",IF(ISBLANK($C$29),"",$C$29)) | T29: =IF(ISERROR($E$29),"",IF(ISBLANK($E$29),"",$E$29)) | U29: =IF(ISERROR($F$29),"",IF(ISBLANK($F$29),"",$F$29)) | Z29: =ISERROR($B$29)*1+ISERROR($C$29)*1+ISERROR($D$29)*1+ISERROR($E$29)*1+ISERROR($F$29)*1+ISERROR($G$29)*1
A30: =IF(LEN($P$12)>0,$P$12,"PJ 6") | K30: =IF(Z30>0,"O Google leu como fórmula: digite de novo com ' na frente.",IF(AND(ISNUMBER($Q$30),$Q$30>'Campanha'!$B$18),"Cone acima do máximo da faixa (25.1)",IF(AND(ISNUMBER($T$30),$T$30>1),"Mais de 1 Sobreposição nesta faixa (25.2)",IF(AND(ISNUMBER($Q$30),$Q$30>=1,$Q$30<=5),IF(MAX(IF(ISNUMBER($U$30),$U$30,0),IF(ISNUMBER($T$30),$T$30,0))>INDEX('Dados'!$H$468:$H$472,INT($Q$30)),"Acima do teto do Cone (25.2): o Nível "&INT($Q$30)&" aceita até "&INDEX('Dados'!$H$468:$H$472,INT($Q$30)),IF(AND(ISNUMBER($U$30),ISNUMBER($T$30),$U$30<$T$30),"Total no Cone menor que as desta faixa","")),IF(AND(ISNUMBER($U$30),ISNUMBER($T$30),$U$30<$T$30),"Total no Cone menor que as desta faixa",""))))) | Q30: =IF(ISERROR($B$30),"",IF(ISBLANK($B$30),"",$B$30)) | R30: =IF(ISERROR($C$30),"",IF(ISBLANK($C$30),"",$C$30)) | T30: =IF(ISERROR($E$30),"",IF(ISBLANK($E$30),"",$E$30)) | U30: =IF(ISERROR($F$30),"",IF(ISBLANK($F$30),"",$F$30)) | Z30: =ISERROR($B$30)*1+ISERROR($C$30)*1+ISERROR($D$30)*1+ISERROR($E$30)*1+ISERROR($F$30)*1+ISERROR($G$30)*1
A32: G4 · O que a Raça muda no combate (automático)
A33: PJ | B33: Morrendo com Vantagem? | C33: Pode ser Executado? | D33: Esforço? | E33: Descobre Fraqueza | G33: Lembrete da Raça | K33: Aviso
A34: =IF(LEN($P$7)>0,$P$7,"PJ 1") | B34: =IFERROR(INDEX('Dados'!$B$350:$B$356,MATCH($R$7,'Dados'!$A$350:$A$356,0)),"") | C34: =IFERROR(INDEX('Dados'!$C$350:$C$356,MATCH($R$7,'Dados'!$A$350:$A$356,0)),"") | D34: =IFERROR(INDEX('Dados'!$D$350:$D$356,MATCH($R$7,'Dados'!$A$350:$A$356,0)),"") | E34: =IFERROR(INDEX('Dados'!$E$350:$E$356,MATCH($R$7,'Dados'!$A$350:$A$356,0)),"") | G34: =IF($R$7="Vulpes","Raposa Astuta: segunda chance contra a Surpresa (DT 10, 19.3 e 27.3)",IF($R$7="Haloviano","To na sua mente: DT 13 de ativação; a falha gasta o uso (05, 27.3)",IF($R$7="Xianzhouíta","Não pode ser Executado (05, 23.5)",IF($R$7="Intellitron","Descobre Fraqueza com Vantagem e 2 por sucesso (20.2)",IF($R$7="Vidyadhara","Maré que Volta: 1 por Descanso Curto, nível + Vigor PV em si (05)",IF($R$7="Avginiano","Não Foi a Primeira Vez: 1 por combate, metade da duração na falha (05)",IF($R$7="Humano","Esforço: no máximo 1 ponto (05)",""))))))) | K34: =IF(AND(ISNUMBER($Q$25),$Q$25<'Campanha'!$B$18),"Cone abaixo do esperado: encontros ficam mais duros (27.8)",IF(AND(ISNUMBER($R$25),$R$25<IF('Campanha'!$B$17<=6,1,IF('Campanha'!$B$17<=12,2,IF('Campanha'!$B$17<=17,3,4)))),"Tier abaixo do esperado: encontros ficam mais duros (27.8)",IF(AND(ISNUMBER($R$25),$R$25>IF('Campanha'!$B$17<=6,1,IF('Campanha'!$B$17<=12,2,IF('Campanha'!$B$17<=17,3,4)))),"Tier acima do Tier do nível do grupo (25.1, 25.3)","")))
A35: =IF(LEN($P$8)>0,$P$8,"PJ 2") | B35: =IFERROR(INDEX('Dados'!$B$350:$B$356,MATCH($R$8,'Dados'!$A$350:$A$356,0)),"") | C35: =IFERROR(INDEX('Dados'!$C$350:$C$356,MATCH($R$8,'Dados'!$A$350:$A$356,0)),"") | D35: =IFERROR(INDEX('Dados'!$D$350:$D$356,MATCH($R$8,'Dados'!$A$350:$A$356,0)),"") | E35: =IFERROR(INDEX('Dados'!$E$350:$E$356,MATCH($R$8,'Dados'!$A$350:$A$356,0)),"") | G35: =IF($R$8="Vulpes","Raposa Astuta: segunda chance contra a Surpresa (DT 10, 19.3 e 27.3)",IF($R$8="Haloviano","To na sua mente: DT 13 de ativação; a falha gasta o uso (05, 27.3)",IF($R$8="Xianzhouíta","Não pode ser Executado (05, 23.5)",IF($R$8="Intellitron","Descobre Fraqueza com Vantagem e 2 por sucesso (20.2)",IF($R$8="Vidyadhara","Maré que Volta: 1 por Descanso Curto, nível + Vigor PV em si (05)",IF($R$8="Avginiano","Não Foi a Primeira Vez: 1 por combate, metade da duração na falha (05)",IF($R$8="Humano","Esforço: no máximo 1 ponto (05)",""))))))) | K35: =IF(AND(ISNUMBER($Q$26),$Q$26<'Campanha'!$B$18),"Cone abaixo do esperado: encontros ficam mais duros (27.8)",IF(AND(ISNUMBER($R$26),$R$26<IF('Campanha'!$B$17<=6,1,IF('Campanha'!$B$17<=12,2,IF('Campanha'!$B$17<=17,3,4)))),"Tier abaixo do esperado: encontros ficam mais duros (27.8)",IF(AND(ISNUMBER($R$26),$R$26>IF('Campanha'!$B$17<=6,1,IF('Campanha'!$B$17<=12,2,IF('Campanha'!$B$17<=17,3,4)))),"Tier acima do Tier do nível do grupo (25.1, 25.3)","")))
A36: =IF(LEN($P$9)>0,$P$9,"PJ 3") | B36: =IFERROR(INDEX('Dados'!$B$350:$B$356,MATCH($R$9,'Dados'!$A$350:$A$356,0)),"") | C36: =IFERROR(INDEX('Dados'!$C$350:$C$356,MATCH($R$9,'Dados'!$A$350:$A$356,0)),"") | D36: =IFERROR(INDEX('Dados'!$D$350:$D$356,MATCH($R$9,'Dados'!$A$350:$A$356,0)),"") | E36: =IFERROR(INDEX('Dados'!$E$350:$E$356,MATCH($R$9,'Dados'!$A$350:$A$356,0)),"") | G36: =IF($R$9="Vulpes","Raposa Astuta: segunda chance contra a Surpresa (DT 10, 19.3 e 27.3)",IF($R$9="Haloviano","To na sua mente: DT 13 de ativação; a falha gasta o uso (05, 27.3)",IF($R$9="Xianzhouíta","Não pode ser Executado (05, 23.5)",IF($R$9="Intellitron","Descobre Fraqueza com Vantagem e 2 por sucesso (20.2)",IF($R$9="Vidyadhara","Maré que Volta: 1 por Descanso Curto, nível + Vigor PV em si (05)",IF($R$9="Avginiano","Não Foi a Primeira Vez: 1 por combate, metade da duração na falha (05)",IF($R$9="Humano","Esforço: no máximo 1 ponto (05)",""))))))) | K36: =IF(AND(ISNUMBER($Q$27),$Q$27<'Campanha'!$B$18),"Cone abaixo do esperado: encontros ficam mais duros (27.8)",IF(AND(ISNUMBER($R$27),$R$27<IF('Campanha'!$B$17<=6,1,IF('Campanha'!$B$17<=12,2,IF('Campanha'!$B$17<=17,3,4)))),"Tier abaixo do esperado: encontros ficam mais duros (27.8)",IF(AND(ISNUMBER($R$27),$R$27>IF('Campanha'!$B$17<=6,1,IF('Campanha'!$B$17<=12,2,IF('Campanha'!$B$17<=17,3,4)))),"Tier acima do Tier do nível do grupo (25.1, 25.3)","")))
A37: =IF(LEN($P$10)>0,$P$10,"PJ 4") | B37: =IFERROR(INDEX('Dados'!$B$350:$B$356,MATCH($R$10,'Dados'!$A$350:$A$356,0)),"") | C37: =IFERROR(INDEX('Dados'!$C$350:$C$356,MATCH($R$10,'Dados'!$A$350:$A$356,0)),"") | D37: =IFERROR(INDEX('Dados'!$D$350:$D$356,MATCH($R$10,'Dados'!$A$350:$A$356,0)),"") | E37: =IFERROR(INDEX('Dados'!$E$350:$E$356,MATCH($R$10,'Dados'!$A$350:$A$356,0)),"") | G37: =IF($R$10="Vulpes","Raposa Astuta: segunda chance contra a Surpresa (DT 10, 19.3 e 27.3)",IF($R$10="Haloviano","To na sua mente: DT 13 de ativação; a falha gasta o uso (05, 27.3)",IF($R$10="Xianzhouíta","Não pode ser Executado (05, 23.5)",IF($R$10="Intellitron","Descobre Fraqueza com Vantagem e 2 por sucesso (20.2)",IF($R$10="Vidyadhara","Maré que Volta: 1 por Descanso Curto, nível + Vigor PV em si (05)",IF($R$10="Avginiano","Não Foi a Primeira Vez: 1 por combate, metade da duração na falha (05)",IF($R$10="Humano","Esforço: no máximo 1 ponto (05)",""))))))) | K37: =IF(AND(ISNUMBER($Q$28),$Q$28<'Campanha'!$B$18),"Cone abaixo do esperado: encontros ficam mais duros (27.8)",IF(AND(ISNUMBER($R$28),$R$28<IF('Campanha'!$B$17<=6,1,IF('Campanha'!$B$17<=12,2,IF('Campanha'!$B$17<=17,3,4)))),"Tier abaixo do esperado: encontros ficam mais duros (27.8)",IF(AND(ISNUMBER($R$28),$R$28>IF('Campanha'!$B$17<=6,1,IF('Campanha'!$B$17<=12,2,IF('Campanha'!$B$17<=17,3,4)))),"Tier acima do Tier do nível do grupo (25.1, 25.3)","")))
A38: =IF(LEN($P$11)>0,$P$11,"PJ 5") | B38: =IFERROR(INDEX('Dados'!$B$350:$B$356,MATCH($R$11,'Dados'!$A$350:$A$356,0)),"") | C38: =IFERROR(INDEX('Dados'!$C$350:$C$356,MATCH($R$11,'Dados'!$A$350:$A$356,0)),"") | D38: =IFERROR(INDEX('Dados'!$D$350:$D$356,MATCH($R$11,'Dados'!$A$350:$A$356,0)),"") | E38: =IFERROR(INDEX('Dados'!$E$350:$E$356,MATCH($R$11,'Dados'!$A$350:$A$356,0)),"") | G38: =IF($R$11="Vulpes","Raposa Astuta: segunda chance contra a Surpresa (DT 10, 19.3 e 27.3)",IF($R$11="Haloviano","To na sua mente: DT 13 de ativação; a falha gasta o uso (05, 27.3)",IF($R$11="Xianzhouíta","Não pode ser Executado (05, 23.5)",IF($R$11="Intellitron","Descobre Fraqueza com Vantagem e 2 por sucesso (20.2)",IF($R$11="Vidyadhara","Maré que Volta: 1 por Descanso Curto, nível + Vigor PV em si (05)",IF($R$11="Avginiano","Não Foi a Primeira Vez: 1 por combate, metade da duração na falha (05)",IF($R$11="Humano","Esforço: no máximo 1 ponto (05)",""))))))) | K38: =IF(AND(ISNUMBER($Q$29),$Q$29<'Campanha'!$B$18),"Cone abaixo do esperado: encontros ficam mais duros (27.8)",IF(AND(ISNUMBER($R$29),$R$29<IF('Campanha'!$B$17<=6,1,IF('Campanha'!$B$17<=12,2,IF('Campanha'!$B$17<=17,3,4)))),"Tier abaixo do esperado: encontros ficam mais duros (27.8)",IF(AND(ISNUMBER($R$29),$R$29>IF('Campanha'!$B$17<=6,1,IF('Campanha'!$B$17<=12,2,IF('Campanha'!$B$17<=17,3,4)))),"Tier acima do Tier do nível do grupo (25.1, 25.3)","")))
A39: =IF(LEN($P$12)>0,$P$12,"PJ 6") | B39: =IFERROR(INDEX('Dados'!$B$350:$B$356,MATCH($R$12,'Dados'!$A$350:$A$356,0)),"") | C39: =IFERROR(INDEX('Dados'!$C$350:$C$356,MATCH($R$12,'Dados'!$A$350:$A$356,0)),"") | D39: =IFERROR(INDEX('Dados'!$D$350:$D$356,MATCH($R$12,'Dados'!$A$350:$A$356,0)),"") | E39: =IFERROR(INDEX('Dados'!$E$350:$E$356,MATCH($R$12,'Dados'!$A$350:$A$356,0)),"") | G39: =IF($R$12="Vulpes","Raposa Astuta: segunda chance contra a Surpresa (DT 10, 19.3 e 27.3)",IF($R$12="Haloviano","To na sua mente: DT 13 de ativação; a falha gasta o uso (05, 27.3)",IF($R$12="Xianzhouíta","Não pode ser Executado (05, 23.5)",IF($R$12="Intellitron","Descobre Fraqueza com Vantagem e 2 por sucesso (20.2)",IF($R$12="Vidyadhara","Maré que Volta: 1 por Descanso Curto, nível + Vigor PV em si (05)",IF($R$12="Avginiano","Não Foi a Primeira Vez: 1 por combate, metade da duração na falha (05)",IF($R$12="Humano","Esforço: no máximo 1 ponto (05)",""))))))) | K39: =IF(AND(ISNUMBER($Q$30),$Q$30<'Campanha'!$B$18),"Cone abaixo do esperado: encontros ficam mais duros (27.8)",IF(AND(ISNUMBER($R$30),$R$30<IF('Campanha'!$B$17<=6,1,IF('Campanha'!$B$17<=12,2,IF('Campanha'!$B$17<=17,3,4)))),"Tier abaixo do esperado: encontros ficam mais duros (27.8)",IF(AND(ISNUMBER($R$30),$R$30>IF('Campanha'!$B$17<=6,1,IF('Campanha'!$B$17<=12,2,IF('Campanha'!$B$17<=17,3,4)))),"Tier acima do Tier do nível do grupo (25.1, 25.3)","")))
A41: G5 · Testes de Resistência e Perícias de mesa (preencha o total da ficha: o que soma ao d20)
A42: PJ | B42: Potência Física | C42: Reflexos | D42: Resistência Física | E42: Resistência Mental | F42: Percepção Mental | G42: Força de Vontade | H42: Percepção | I42: Intuição | J42: Furtividade | K42: Aviso
A43: =IF(LEN($P$7)>0,$P$7,"PJ 1") | K43: =IF(Z43>0,"O Google leu como fórmula: digite de novo com ' na frente.",IF(OR(AND(ISNUMBER($Q$43),OR($Q$43<-5,$Q$43>40)),AND(ISNUMBER($R$43),OR($R$43<-5,$R$43>40)),AND(ISNUMBER($S$43),OR($S$43<-5,$S$43>40)),AND(ISNUMBER($T$43),OR($T$43<-5,$T$43>40)),AND(ISNUMBER($U$43),OR($U$43<-5,$U$43>40)),AND(ISNUMBER($V$43),OR($V$43<-5,$V$43>40)),AND(ISNUMBER($W$43),OR($W$43<-5,$W$43>40)),AND(ISNUMBER($X$43),OR($X$43<-5,$X$43>40)),AND(ISNUMBER($Y$43),OR($Y$43<-5,$Y$43>40))),"Total fora de −5 a +40: confira na ficha","")) | Q43: =IF(ISERROR($B$43),"",IF(ISBLANK($B$43),"",$B$43)) | R43: =IF(ISERROR($C$43),"",IF(ISBLANK($C$43),"",$C$43)) | S43: =IF(ISERROR($D$43),"",IF(ISBLANK($D$43),"",$D$43)) | T43: =IF(ISERROR($E$43),"",IF(ISBLANK($E$43),"",$E$43)) | U43: =IF(ISERROR($F$43),"",IF(ISBLANK($F$43),"",$F$43)) | V43: =IF(ISERROR($G$43),"",IF(ISBLANK($G$43),"",$G$43)) | W43: =IF(ISERROR($H$43),"",IF(ISBLANK($H$43),"",$H$43)) | X43: =IF(ISERROR($I$43),"",IF(ISBLANK($I$43),"",$I$43)) | Y43: =IF(ISERROR($J$43),"",IF(ISBLANK($J$43),"",$J$43)) | Z43: =ISERROR($B$43)*1+ISERROR($C$43)*1+ISERROR($D$43)*1+ISERROR($E$43)*1+ISERROR($F$43)*1+ISERROR($G$43)*1+ISERROR($H$43)*1+ISERROR($I$43)*1+ISERROR($J$43)*1
A44: =IF(LEN($P$8)>0,$P$8,"PJ 2") | K44: =IF(Z44>0,"O Google leu como fórmula: digite de novo com ' na frente.",IF(OR(AND(ISNUMBER($Q$44),OR($Q$44<-5,$Q$44>40)),AND(ISNUMBER($R$44),OR($R$44<-5,$R$44>40)),AND(ISNUMBER($S$44),OR($S$44<-5,$S$44>40)),AND(ISNUMBER($T$44),OR($T$44<-5,$T$44>40)),AND(ISNUMBER($U$44),OR($U$44<-5,$U$44>40)),AND(ISNUMBER($V$44),OR($V$44<-5,$V$44>40)),AND(ISNUMBER($W$44),OR($W$44<-5,$W$44>40)),AND(ISNUMBER($X$44),OR($X$44<-5,$X$44>40)),AND(ISNUMBER($Y$44),OR($Y$44<-5,$Y$44>40))),"Total fora de −5 a +40: confira na ficha","")) | Q44: =IF(ISERROR($B$44),"",IF(ISBLANK($B$44),"",$B$44)) | R44: =IF(ISERROR($C$44),"",IF(ISBLANK($C$44),"",$C$44)) | S44: =IF(ISERROR($D$44),"",IF(ISBLANK($D$44),"",$D$44)) | T44: =IF(ISERROR($E$44),"",IF(ISBLANK($E$44),"",$E$44)) | U44: =IF(ISERROR($F$44),"",IF(ISBLANK($F$44),"",$F$44)) | V44: =IF(ISERROR($G$44),"",IF(ISBLANK($G$44),"",$G$44)) | W44: =IF(ISERROR($H$44),"",IF(ISBLANK($H$44),"",$H$44)) | X44: =IF(ISERROR($I$44),"",IF(ISBLANK($I$44),"",$I$44)) | Y44: =IF(ISERROR($J$44),"",IF(ISBLANK($J$44),"",$J$44)) | Z44: =ISERROR($B$44)*1+ISERROR($C$44)*1+ISERROR($D$44)*1+ISERROR($E$44)*1+ISERROR($F$44)*1+ISERROR($G$44)*1+ISERROR($H$44)*1+ISERROR($I$44)*1+ISERROR($J$44)*1
A45: =IF(LEN($P$9)>0,$P$9,"PJ 3") | K45: =IF(Z45>0,"O Google leu como fórmula: digite de novo com ' na frente.",IF(OR(AND(ISNUMBER($Q$45),OR($Q$45<-5,$Q$45>40)),AND(ISNUMBER($R$45),OR($R$45<-5,$R$45>40)),AND(ISNUMBER($S$45),OR($S$45<-5,$S$45>40)),AND(ISNUMBER($T$45),OR($T$45<-5,$T$45>40)),AND(ISNUMBER($U$45),OR($U$45<-5,$U$45>40)),AND(ISNUMBER($V$45),OR($V$45<-5,$V$45>40)),AND(ISNUMBER($W$45),OR($W$45<-5,$W$45>40)),AND(ISNUMBER($X$45),OR($X$45<-5,$X$45>40)),AND(ISNUMBER($Y$45),OR($Y$45<-5,$Y$45>40))),"Total fora de −5 a +40: confira na ficha","")) | Q45: =IF(ISERROR($B$45),"",IF(ISBLANK($B$45),"",$B$45)) | R45: =IF(ISERROR($C$45),"",IF(ISBLANK($C$45),"",$C$45)) | S45: =IF(ISERROR($D$45),"",IF(ISBLANK($D$45),"",$D$45)) | T45: =IF(ISERROR($E$45),"",IF(ISBLANK($E$45),"",$E$45)) | U45: =IF(ISERROR($F$45),"",IF(ISBLANK($F$45),"",$F$45)) | V45: =IF(ISERROR($G$45),"",IF(ISBLANK($G$45),"",$G$45)) | W45: =IF(ISERROR($H$45),"",IF(ISBLANK($H$45),"",$H$45)) | X45: =IF(ISERROR($I$45),"",IF(ISBLANK($I$45),"",$I$45)) | Y45: =IF(ISERROR($J$45),"",IF(ISBLANK($J$45),"",$J$45)) | Z45: =ISERROR($B$45)*1+ISERROR($C$45)*1+ISERROR($D$45)*1+ISERROR($E$45)*1+ISERROR($F$45)*1+ISERROR($G$45)*1+ISERROR($H$45)*1+ISERROR($I$45)*1+ISERROR($J$45)*1
...

Sheet Sessões
A1: Sessões — Explorando Galáxias v1.2
A2: Legenda: | B2: Entrada (preencha) | C2: Calculada (automático) | D2: Aviso (texto em vermelho) | E2: Título de bloco | F2: Cabeçalho de coluna | G2: Rótulo da linha | H2: Linha alternada (outro tom) | I2: Não se aplica
A3: Preparar a próxima sessão (cenas, pistas, ganchos, checklist) e o diário de campanha.
A5: Preparar a próxima sessão (preencha)
A6: Campo | B6: Valor (preencha) | K6: Aviso
A7: Sessão nº | C7: ="Sessão atual na Mesa: "&IF(ISNUMBER('Campanha'!$AD$10),'Campanha'!$AD$10,"(vazia)")&"." | K7: =IF(AA7>0,"O Google leu como fórmula: digite de novo com ' na frente.",IF(AND(ISNUMBER($R$7),ISNUMBER('Campanha'!$AD$10)),IF($R$7<'Campanha'!$AD$10,"Sessão preparada anterior à sessão atual da Mesa",""),"")) | R7: =IF(ISERROR($B$7),"",IF(ISBLANK($B$7),"",$B$7)) | AA7: =ISERROR($B$7)*1
A8: Data real | K8: =IF(AA8>0,"O Google leu como fórmula: digite de novo com ' na frente.","") | AA8: =ISERROR($B$8)*1
A9: Título | K9: =IF(AA9>0,"O Google leu como fórmula: digite de novo com ' na frente.","") | R9: =IF(ISERROR($B$9),"",IF(ISBLANK($B$9),"",$B$9)) | AA9: =ISERROR($B$9)*1
A10: Objetivo da sessão | K10: =IF(AA10>0,"O Google leu como fórmula: digite de novo com ' na frente.","") | AA10: =ISERROR($B$10)*1
A12: 5 cenas planejadas (a DT usa a faixa do desafio, não a do grupo: 27.2 regra 1)
A13: Cena | B13: Tipo | C13: Descrição | F13: NPCs presentes | H13: Encontro ligado | I13: Dificuldade | J13: Faixa do desafio | K13: Aviso
A14: Cena 1 | K14: =IF(AA14>0,"O Google leu como fórmula: escolha de novo ou digite com ' na frente.",IF(AND(LEN($Y$14)>0,COUNTIF('Dados'!$A$284:$A$289,$Y$14)=0),"Dificuldade fora da lista (27.2)",IF(AND(LEN($Z$14)>0,COUNTIF('Dados'!$AP$6:$AP$10,$Z$14)=0),"Faixa fora da lista: usando a do grupo",IF(AND(LEN($X$14)>0,$X$14<>"Nenhum",$X$14<>"A",$X$14<>"B",$X$14<>"C"),"Encontro fora da lista (A, B ou C)","")))) | R14: =IF(ISERROR($B$14),"",IF(ISBLANK($B$14),"",$B$14)) | X14: =IF(ISERROR($H$14),"",IF(ISBLANK($H$14),"",$H$14)) | Y14: =IF(ISERROR($I$14),"",IF(ISBLANK($I$14),"",$I$14)) | Z14: =IF(ISERROR($J$14),"",IF(ISBLANK($J$14),"",$J$14)) | AA14: =ISERROR($B$14)*1+ISERROR($C$14)*1+ISERROR($F$14)*1+ISERROR($H$14)*1+ISERROR($I$14)*1+ISERROR($J$14)*1
A15: Cena 2 | K15: =IF(AA15>0,"O Google leu como fórmula: escolha de novo ou digite com ' na frente.",IF(AND(LEN($Y$15)>0,COUNTIF('Dados'!$A$284:$A$289,$Y$15)=0),"Dificuldade fora da lista (27.2)",IF(AND(LEN($Z$15)>0,COUNTIF('Dados'!$AP$6:$AP$10,$Z$15)=0),"Faixa fora da lista: usando a do grupo",IF(AND(LEN($X$15)>0,$X$15<>"Nenhum",$X$15<>"A",$X$15<>"B",$X$15<>"C"),"Encontro fora da lista (A, B ou C)","")))) | R15: =IF(ISERROR($B$15),"",IF(ISBLANK($B$15),"",$B$15)) | X15: =IF(ISERROR($H$15),"",IF(ISBLANK($H$15),"",$H$15)) | Y15: =IF(ISERROR($I$15),"",IF(ISBLANK($I$15),"",$I$15)) | Z15: =IF(ISERROR($J$15),"",IF(ISBLANK($J$15),"",$J$15)) | AA15: =ISERROR($B$15)*1+ISERROR($C$15)*1+ISERROR($F$15)*1+ISERROR($H$15)*1+ISERROR($I$15)*1+ISERROR($J$15)*1
A16: Cena 3 | K16: =IF(AA16>0,"O Google leu como fórmula: escolha de novo ou digite com ' na frente.",IF(AND(LEN($Y$16)>0,COUNTIF('Dados'!$A$284:$A$289,$Y$16)=0),"Dificuldade fora da lista (27.2)",IF(AND(LEN($Z$16)>0,COUNTIF('Dados'!$AP$6:$AP$10,$Z$16)=0),"Faixa fora da lista: usando a do grupo",IF(AND(LEN($X$16)>0,$X$16<>"Nenhum",$X$16<>"A",$X$16<>"B",$X$16<>"C"),"Encontro fora da lista (A, B ou C)","")))) | R16: =IF(ISERROR($B$16),"",IF(ISBLANK($B$16),"",$B$16)) | X16: =IF(ISERROR($H$16),"",IF(ISBLANK($H$16),"",$H$16)) | Y16: =IF(ISERROR($I$16),"",IF(ISBLANK($I$16),"",$I$16)) | Z16: =IF(ISERROR($J$16),"",IF(ISBLANK($J$16),"",$J$16)) | AA16: =ISERROR($B$16)*1+ISERROR($C$16)*1+ISERROR($F$16)*1+ISERROR($H$16)*1+ISERROR($I$16)*1+ISERROR($J$16)*1
A17: Cena 4 | K17: =IF(AA17>0,"O Google leu como fórmula: escolha de novo ou digite com ' na frente.",IF(AND(LEN($Y$17)>0,COUNTIF('Dados'!$A$284:$A$289,$Y$17)=0),"Dificuldade fora da lista (27.2)",IF(AND(LEN($Z$17)>0,COUNTIF('Dados'!$AP$6:$AP$10,$Z$17)=0),"Faixa fora da lista: usando a do grupo",IF(AND(LEN($X$17)>0,$X$17<>"Nenhum",$X$17<>"A",$X$17<>"B",$X$17<>"C"),"Encontro fora da lista (A, B ou C)","")))) | R17: =IF(ISERROR($B$17),"",IF(ISBLANK($B$17),"",$B$17)) | X17: =IF(ISERROR($H$17),"",IF(ISBLANK($H$17),"",$H$17)) | Y17: =IF(ISERROR($I$17),"",IF(ISBLANK($I$17),"",$I$17)) | Z17: =IF(ISERROR($J$17),"",IF(ISBLANK($J$17),"",$J$17)) | AA17: =ISERROR($B$17)*1+ISERROR($C$17)*1+ISERROR($F$17)*1+ISERROR($H$17)*1+ISERROR($I$17)*1+ISERROR($J$17)*1
A18: Cena 5 | K18: =IF(AA18>0,"O Google leu como fórmula: escolha de novo ou digite com ' na frente.",IF(AND(LEN($Y$18)>0,COUNTIF('Dados'!$A$284:$A$289,$Y$18)=0),"Dificuldade fora da lista (27.2)",IF(AND(LEN($Z$18)>0,COUNTIF('Dados'!$AP$6:$AP$10,$Z$18)=0),"Faixa fora da lista: usando a do grupo",IF(AND(LEN($X$18)>0,$X$18<>"Nenhum",$X$18<>"A",$X$18<>"B",$X$18<>"C"),"Encontro fora da lista (A, B ou C)","")))) | R18: =IF(ISERROR($B$18),"",IF(ISBLANK($B$18),"",$B$18)) | X18: =IF(ISERROR($H$18),"",IF(ISBLANK($H$18),"",$H$18)) | Y18: =IF(ISERROR($I$18),"",IF(ISBLANK($I$18),"",$I$18)) | Z18: =IF(ISERROR($J$18),"",IF(ISBLANK($J$18),"",$J$18)) | AA18: =ISERROR($B$18)*1+ISERROR($C$18)*1+ISERROR($F$18)*1+ISERROR($H$18)*1+ISERROR($I$18)*1+ISERROR($J$18)*1
A19: Cena | B19: DT (automático) | C19: Encontro ligado (aba Encontros) | G19: Contrato da Fraqueza (27.5) | K19: Aviso
A20: Cena 1 | B20: =IF(LEN($Y$14)=0,"",IFERROR(IF(IF(LEN($Z$14)=0,'Campanha'!$B$18,IFERROR(MATCH($Z$14,'Dados'!$AP$6:$AP$10,0),'Campanha'!$B$18))=1,INDEX('Dados'!$B$284:$B$289,MATCH($Y$14,'Dados'!$A$284:$A$289,0)),IF(IF(LEN($Z$14)=0,'Campanha'!$B$18,IFERROR(MATCH($Z$14,'Dados'!$AP$6:$AP$10,0),'Campanha'!$B$18))=2,INDEX('Dados'!$C$284:$C$289,MATCH($Y$14,'Dados'!$A$284:$A$289,0)),IF(IF(LEN($Z$14)=0,'Campanha'!$B$18,IFERROR(MATCH($Z$14,'Dados'!$AP$6:$AP$10,0),'Campanha'!$B$18))=3,INDEX('Dados'!$D$284:$D$289,MATCH($Y$14,'Dados'!$A$284:$A$289,0)),IF(IF(LEN($Z$14)=0,'Campanha'!$B$18,IFERROR(MATCH($Z$14,'Dados'!$AP$6:$AP$10,0),'Campanha'!$B$18))=4,INDEX('Dados'!$E$284:$E$289,MATCH($Y$14,'Dados'!$A$284:$A$289,0)),INDEX('Dados'!$F$284:$F$289,MATCH($Y$14,'Dados'!$A$284:$A$289,0)))))),"")) | C20: =IF($X$14="A",IF(LEN('Encontros'!$BH$19&"")>0,'Encontros'!$BH$19&": ","Encontro A: ")&"custo "&'Encontros'!$B$38&" · "&'Encontros'!$G$38,IF($X$14="B",IF(LEN('Encontros'!$BH$47&"")>0,'Encontros'!$BH$47&": ","Encontro B: ")&"custo "&'Encontros'!$B$66&" · "&'Encontros'!$G$66,IF($X$14="C",IF(LEN('Encontros'!$BH$75&"")>0,'Encontros'!$BH$75&": ","Encontro C: ")&"custo "&'Encontros'!$B$94&" · "&'Encontros'!$G$94,""))) | G20: =IF($X$14="A",'Encontros'!$J$41,IF($X$14="B",'Encontros'!$J$69,IF($X$14="C",'Encontros'!$J$97,"")))
A21: Cena 2 | B21: =IF(LEN($Y$15)=0,"",IFERROR(IF(IF(LEN($Z$15)=0,'Campanha'!$B$18,IFERROR(MATCH($Z$15,'Dados'!$AP$6:$AP$10,0),'Campanha'!$B$18))=1,INDEX('Dados'!$B$284:$B$289,MATCH($Y$15,'Dados'!$A$284:$A$289,0)),IF(IF(LEN($Z$15)=0,'Campanha'!$B$18,IFERROR(MATCH($Z$15,'Dados'!$AP$6:$AP$10,0),'Campanha'!$B$18))=2,INDEX('Dados'!$C$284:$C$289,MATCH($Y$15,'Dados'!$A$284:$A$289,0)),IF(IF(LEN($Z$15)=0,'Campanha'!$B$18,IFERROR(MATCH($Z$15,'Dados'!$AP$6:$AP$10,0),'Campanha'!$B$18))=3,INDEX('Dados'!$D$284:$D$289,MATCH($Y$15,'Dados'!$A$284:$A$289,0)),IF(IF(LEN($Z$15)=0,'Campanha'!$B$18,IFERROR(MATCH($Z$15,'Dados'!$AP$6:$AP$10,0),'Campanha'!$B$18))=4,INDEX('Dados'!$E$284:$E$289,MATCH($Y$15,'Dados'!$A$284:$A$289,0)),INDEX('Dados'!$F$284:$F$289,MATCH($Y$15,'Dados'!$A$284:$A$289,0)))))),"")) | C21: =IF($X$15="A",IF(LEN('Encontros'!$BH$19&"")>0,'Encontros'!$BH$19&": ","Encontro A: ")&"custo "&'Encontros'!$B$38&" · "&'Encontros'!$G$38,IF($X$15="B",IF(LEN('Encontros'!$BH$47&"")>0,'Encontros'!$BH$47&": ","Encontro B: ")&"custo "&'Encontros'!$B$66&" · "&'Encontros'!$G$66,IF($X$15="C",IF(LEN('Encontros'!$BH$75&"")>0,'Encontros'!$BH$75&": ","Encontro C: ")&"custo "&'Encontros'!$B$94&" · "&'Encontros'!$G$94,""))) | G21: =IF($X$15="A",'Encontros'!$J$41,IF($X$15="B",'Encontros'!$J$69,IF($X$15="C",'Encontros'!$J$97,"")))
A22: Cena 3 | B22: =IF(LEN($Y$16)=0,"",IFERROR(IF(IF(LEN($Z$16)=0,'Campanha'!$B$18,IFERROR(MATCH($Z$16,'Dados'!$AP$6:$AP$10,0),'Campanha'!$B$18))=1,INDEX('Dados'!$B$284:$B$289,MATCH($Y$16,'Dados'!$A$284:$A$289,0)),IF(IF(LEN($Z$16)=0,'Campanha'!$B$18,IFERROR(MATCH($Z$16,'Dados'!$AP$6:$AP$10,0),'Campanha'!$B$18))=2,INDEX('Dados'!$C$284:$C$289,MATCH($Y$16,'Dados'!$A$284:$A$289,0)),IF(IF(LEN($Z$16)=0,'Campanha'!$B$18,IFERROR(MATCH($Z$16,'Dados'!$AP$6:$AP$10,0),'Campanha'!$B$18))=3,INDEX('Dados'!$D$284:$D$289,MATCH($Y$16,'Dados'!$A$284:$A$289,0)),IF(IF(LEN($Z$16)=0,'Campanha'!$B$18,IFERROR(MATCH($Z$16,'Dados'!$AP$6:$AP$10,0),'Campanha'!$B$18))=4,INDEX('Dados'!$E$284:$E$289,MATCH($Y$16,'Dados'!$A$284:$A$289,0)),INDEX('Dados'!$F$284:$F$289,MATCH($Y$16,'Dados'!$A$284:$A$289,0)))))),"")) | C22: =IF($X$16="A",IF(LEN('Encontros'!$BH$19&"")>0,'Encontros'!$BH$19&": ","Encontro A: ")&"custo "&'Encontros'!$B$38&" · "&'Encontros'!$G$38,IF($X$16="B",IF(LEN('Encontros'!$BH$47&"")>0,'Encontros'!$BH$47&": ","Encontro B: ")&"custo "&'Encontros'!$B$66&" · "&'Encontros'!$G$66,IF($X$16="C",IF(LEN('Encontros'!$BH$75&"")>0,'Encontros'!$BH$75&": ","Encontro C: ")&"custo "&'Encontros'!$B$94&" · "&'Encontros'!$G$94,""))) | G22: =IF($X$16="A",'Encontros'!$J$41,IF($X$16="B",'Encontros'!$J$69,IF($X$16="C",'Encontros'!$J$97,"")))
