Workbook

Sheet Início
A1: Início — Explorando Galáxias v1.1
A2: Legenda: | B2: Entrada (preencha) | C2: Calculada (automático) | D2: Aviso (texto em vermelho) | E2: Título de bloco | F2: Cabeçalho de coluna | G2: Rótulo da linha | H2: Linha alternada (outro tom) | I2: Não se aplica
A3: Comece por aqui: semente da campanha, índice das abas e como a planilha se organiza.
A5: Comece por aqui
A6: 1. Abra no Google Planilhas (Arquivo → Importar) e trabalhe numa cópia por campanha.
A7: 2. Aba Campanha: nível do grupo e nº de jogadores (uma vez; todas as abas leem daqui).
A8: 3. Aba Grupo: copie da ficha de cada jogador os números de combate.
A9: 4. Prepare o combate: Inimigos (criar), Bestiário (consultar) e Encontros (montar e conferir o contrato).
A10: 5. Jogue com a aba Combate: carregue o encontro, siga a Fila e registre o estado (sem macro: tudo é digitado).
A11: Amarelo = você preenche; azul = automático; vermelho = aviso; 'Sugestão da planilha' = não é regra do livro.
A12: Não comece um texto com +, - ou =: o Google entende como fórmula. Se precisar, digite um apóstrofo (') antes.
A14: Semente da campanha (geradores determinísticos, sem sorteio escondido)
A15: Semente da campanha | D15: Semente efetiva | E15: =IF(ISNUMBER($P$15),IF(AND($P$15>=1,$P$15<=2147483646,INT($P$15)=$P$15),$P$15,12345),12345) | G15: Vazia = 12345. | K15: =IF(Q15>0,"O Google leu como fórmula: digite de novo com ' na frente.",IF(LEN($P$15)=0,"",IF(ISNUMBER($P$15),IF(AND($P$15>=1,$P$15<=2147483646,INT($P$15)=$P$15),"","Semente fora de 1 a 2.147.483.646: usando 12345"),"Semente fora de 1 a 2.147.483.646: usando 12345"))) | P15: =IF(ISERROR($B$15),"",IF(ISBLANK($B$15),"",$B$15)) | Q15: =ISERROR($B$15)*1
A16: Mesma semente e mesma 'Rolagem nº' dão sempre o mesmo resultado; editar outra célula não muda o sorteio. Para rolar de novo, some 1 na 'Rolagem nº' do gerador; para outra campanha, troque a semente.
A18: Índice das abas
A19: Aba | B19: Para que serve | G19: Quando usar | K19: Situação
A20: Início | B20: Semente da campanha e índice. | G20: Na primeira vez e para trocar a semente. | K20: Pronta
A21: Campanha | B21: Nível do grupo, nº de jogadores e os números que saem deles. | G21: Ao começar e a cada marco. | K21: Pronta (Mesa)
A22: Grupo | B22: Os PJs copiados da ficha de cada jogador. | G22: Ao começar e quando a ficha muda. | K22: Pronta
A23: Sessões | B23: Preparar a próxima sessão e o diário. | G23: Entre sessões. | K23: Em construção
A24: Missões | B24: Missões oferecidas, ativas e concluídas. | G24: Entre sessões. | K24: Em construção
A25: NPCs | B25: Gerador de NPCs, elenco e cartões. | G25: Preparando a história. | K25: Pronta
A26: Inimigos | B26: Criador de Inimigos: a ficha de 28.1 pronta. | G26: Preparando o combate. | K26: Pronta
A27: Bestiário | B27: As 32 fichas do capítulo 28 com filtro. | G27: Preparando o combate. | K27: Pronta
A28: Encontros | B28: Orçamento, encontros salvos, contrato da Fraqueza, encontro aleatório. | G28: Preparando o combate. | K28: Pronta
A29: Aba | B29: Para que serve | G29: Quando usar | K29: Situação
A30: Combate | B30: Fila de Ação, PV, Tenacidade e Quebra, condições, Morrendo. | G30: Na mesa, durante a luta. | K30: Pronta
... A38: Dados | B38: Tabelas do livro usadas pelas fórmulas. Não edite. | G38: Nunca: o gerador reescreve. | K38: Pronta
A40: Células com erro na planilha (o Google leu como fórmula um texto digitado)
A41: Células com erro na planilha | B41: =$B$42+$D$42+$F$42+$H$42+$J$42+$B$43+$D$43+$F$43+$H$43+$J$43+$B$44+$D$44+$F$44+$H$44+$J$44+$B$45+$D$45+$F$45 | C41: =IF($B$41=0,"Nenhuma célula com erro.","O Google leu como fórmula um texto que começa com +, - ou =. Veja abaixo a aba com erro: o aviso da linha diz o que fazer. Apague e escreva de novo com um apóstrofo (') na frente, ou escolha de novo na lista.")
A42: Início | B42: =SUMPRODUCT(ISERROR($A$1:$Q$40)*1) | C42: Campanha | D42: =SUMPRODUCT(ISERROR('Campanha'!$A$1:$Q$34)*1) | E42: Grupo | F42: =SUMPRODUCT(ISERROR('Grupo'!$A$1:$Y$45)*1) | G42: Sessões | H42: =SUMPRODUCT(ISERROR('Sessões'!$A$1:$L$5)*1) | I42: Missões | J42: =SUMPRODUCT(ISERROR('Missões'!$A$1:$L$5)*1)
A43: NPCs | B43: =SUMPRODUCT(ISERROR('NPCs'!$A$1:$BF$232)*1) | C43: Inimigos | D43: =SUMPRODUCT(ISERROR('Inimigos'!$A$1:$EA$219)*1) | E43: Bestiário | F43: =SUMPRODUCT(ISERROR('Bestiário'!$A$1:$S$121)*1) | G43: Encontros | H43: =SUMPRODUCT(ISERROR('Encontros'!$A$1:$BN$122)*1) | I43: Combate | J43: =SUMPRODUCT(ISERROR('Combate'!$A$1:$CK$216)*1)
A44: Aventuras | B44: =SUMPRODUCT(ISERROR('Aventuras'!$A$1:$AU$116)*1) | C44: Recompensas | D44: =SUMPRODUCT(ISERROR('Recompensas'!$A$1:$AK$159)*1) | E44: Mundos | F44: =SUMPRODUCT(ISERROR('Mundos'!$A$1:$L$5)*1) | G44: Improviso | H44: =SUMPRODUCT(ISERROR('Improviso'!$A$1:$L$5)*1) | I44: Escudo do Mestre | J44: =SUMPRODUCT(ISERROR('Escudo do Mestre'!$A$1:$L$5)*1)
A45: Minhas Tabelas | B45: =SUMPRODUCT(ISERROR('Minhas Tabelas'!$A$1:$L$5)*1) | C45: Tabelas | D45: =SUMPRODUCT(ISERROR('Tabelas'!$A$1:$AG$808)*1) | E45: Dados | F45: =SUMPRODUCT(ISERROR('Dados'!$A$1:$BU$588)*1)

Sheet Campanha
A1: Campanha — Explorando Galáxias v1.1
A2: Legenda: | B2: Entrada (preencha) | C2: Calculada (automático) | D2: Aviso (texto em vermelho) | E2: Título de bloco | F2: Cabeçalho de coluna | G2: Rótulo da linha | H2: Linha alternada (outro tom) | I2: Não se aplica
A3: A mesa: nível do grupo, número de jogadores e os números que saem deles.
A5: Mesa (preencha uma vez: todas as abas leem daqui — D9)
A6: Campo | B6: Valor (preencha) | E6: O que a planilha usa (automático) | K6: Aviso
A7: Nome da campanha | E7: ="A campanha aparece no título das abas de jogo." | K7: =IF(Q7>0,"O Google leu como fórmula: digite de novo com ' na frente.","") | Q7: =ISERROR($B$7)*1
A8: Nº de jogadores | E8: =IF(ISNUMBER($P$8),"Jogadores na mesa: "&$B$21&".","Vazio: usando o nº de PJs da aba Grupo ("&$B$21&").") | K8: =IF(Q8>0,"O Google leu como fórmula: digite de novo com ' na frente.",IF(LEN($P$8)=0,"",IF(NOT(ISNUMBER($P$8)),"Nº de jogadores não é número: usando o nº de PJs do Grupo",IF(OR($P$8<1,$P$8>6,INT($P$8)<>$P$8),"Nº de jogadores fora de 1 a 6: usando o limite",IF(OR($P$8<3,$P$8>6),"Fora da tabela de 16.2 (3 a 6): PH calculado com o limite 3 a 6",""))))) | P8: =IF(ISERROR($B$8),"",IF(ISBLANK($B$8),"",$B$8)) | Q8: =ISERROR($B$8)*1
A9: Nível do grupo | E9: =IF(ISNUMBER($P$9),"Nível "&$B$17&", faixa "&$B$19&".","Vazio: as abas calculam com o nível 1 (faixa 1-4).") | K9: =IF(Q9>0,"O Google leu como fórmula: digite de novo com ' na frente.",IF(LEN($P$9)=0,"",IF(NOT(ISNUMBER($P$9)),"Nível não é número: usando 1",IF(OR($P$9<1,$P$9>20,INT($P$9)<>$P$9),"Nível fora de 1 a 20: usando o limite","")))) | P9: =IF(ISERROR($B$9),"",IF(ISBLANK($B$9),"",$B$9)) | Q9: =ISERROR($B$9)*1
A10: Sessão atual | E10: ="Sessões e diário: aba Sessões (próxima fase)." | K10: =IF(Q10>0,"O Google leu como fórmula: digite de novo com ' na frente.","") | P10: =IF(ISERROR($B$10),"",IF(ISBLANK($B$10),"",$B$10)) | Q10: =ISERROR($B$10)*1
A11: Dia de campanha | E11: ="Usado pela linha do tempo (próxima fase)." | K11: =IF(Q11>0,"O Google leu como fórmula: digite de novo com ' na frente.","") | Q11: =ISERROR($B$11)*1
A12: Método de atributos | E12: ="Lembrete da Sessão Zero (capítulo 03)." | K12: =IF(Q12>0,"O Google leu como fórmula: escolha de novo na lista.","") | Q12: =ISERROR($B$12)*1
A13: Variantes da mesa | E13: ="Texto livre: média impressa, PV rolado, outra variante (06.4, 28.3)." | K13: =IF(Q13>0,"O Google leu como fórmula: digite de novo com ' na frente.","") | Q13: =ISERROR($B$13)*1
A15: Números do grupo (automático)
A16: Campo | B16: Valor | D16: Fonte no livro | G16: Observação
A17: Nível efetivo | B17: =IF(ISNUMBER($P$9),MIN(20,MAX(1,INT($P$9))),1) | D17: 26.1 | G17: Vazio = 1.
A18: Índice da faixa | B18: =INT(($B$17-1)/4)+1 | D18: 26.3 | G18: 1 a 5.
A19: Faixa do grupo | B19: =INDEX('Dados'!$B$7:$B$11,$B$18) | D19: 26.3 | G19: A faixa do inimigo é a faixa do grupo (28.4 passo 1).
A20: Eficiência | B20: =INDEX('Dados'!$B$15:$B$34,$B$17) | D20: 26.2 (02.3) | G20: Usada no Dano de Quebra e nas condições.
A21: Nº de jogadores efetivo | B21: =IF(ISNUMBER($P$8),MIN(6,MAX(1,INT($P$8))),MAX(1,'Grupo'!$B$42)) | D21: 16.2 | G21: Vazio = nº de PJs da aba Grupo (mínimo 1).
A22: Jogadores para o PH | B22: =MIN(6,MAX(3,$B$21)) | D22: 16.2 | G22: A tabela de 16.2 vai de 3 a 6 jogadores.
A23: Degrau de PH | B23: =IF($B$17<=8,1,IF($B$17<=16,2,3)) | D23: 16.2 | G23: 1 = níveis 1-8; 2 = 9-16; 3 = 17-20.
A24: PH máximo do grupo | B24: =IF($B$23=1,INDEX('Dados'!$B$343:$B$346,MATCH($B$22,'Dados'!$A$343:$A$346,0)),IF($B$23=2,INDEX('Dados'!$C$343:$C$346,MATCH($B$22,'Dados'!$A$343:$A$346,0)),INDEX('Dados'!$D$343:$D$346,MATCH($B$22,'Dados'!$A$343:$A$346,0)))) | D24: 16.2 | G24: Degraus 1-8, 9-16 e 17-20.
A25: PH no início do combate | B25: =IF($B$23=1,INDEX('Dados'!$E$343:$E$346,MATCH($B$22,'Dados'!$A$343:$A$346,0)),IF($B$23=2,INDEX('Dados'!$F$343:$F$346,MATCH($B$22,'Dados'!$A$343:$A$346,0)),INDEX('Dados'!$G$343:$G$346,MATCH($B$22,'Dados'!$A$343:$A$346,0)))) | D25: 16.2 | G25: Começa cada combate com o máximo menos 2.
A26: Campo | B26: Valor | D26: Fonte no livro | G26: Observação
A27: DT Média da faixa | B27: =IF($B$18=1,INDEX('Dados'!$B$284:$B$289,3),IF($B$18=2,INDEX('Dados'!$C$284:$C$289,3),IF($B$18=3,INDEX('Dados'!$D$284:$D$289,3),IF($B$18=4,INDEX('Dados'!$E$284:$E$289,3),INDEX('Dados'!$F$284:$F$289,3))))) | D27: 27.2 | G27: Regra 1: a faixa é a do desafio, não a do personagem.
A28: DT Difícil da faixa | B28: =IF($B$18=1,INDEX('Dados'!$B$284:$B$289,4),IF($B$18=2,INDEX('Dados'!$C$284:$C$289,4),IF($B$18=3,INDEX('Dados'!$D$284:$D$289,4),IF($B$18=4,INDEX('Dados'!$E$284:$E$289,4),INDEX('Dados'!$F$284:$F$289,4))))) | D28: 27.2
A29: DT para descobrir Fraqueza | B29: =IFERROR(INDEX('Dados'!$B$293:$B$297,MATCH($B$19,'Dados'!$A$293:$A$297,0)),"") | D29: 20.2 | G29: Pela faixa do inimigo mais forte da cena.
A30: Cone de Luz máximo | B30: =IFERROR(INDEX('Dados'!$B$380:$B$384,MATCH($B$19,'Dados'!$A$380:$A$384,0)),"") | D30: 25.1
A31: Relíquias | B31: =IFERROR(INDEX('Dados'!$C$380:$C$384,MATCH($B$19,'Dados'!$A$380:$A$384,0)),"") | D31: 25.1
A32: Verba de marco (Cr) | B32: =IFERROR(INDEX('Dados'!$B$372:$B$376,MATCH($B$19,'Dados'!$A$372:$A$376,0)),"") | D32: 24.5 | G32: Por marco, para o grupo.
A34: Não existe experiência por inimigo derrotado: a progressão é por marco narrativo (26.1).

Sheet Grupo
A1: Grupo — Explorando Galáxias v1.1
A2: Legenda: | B2: Entrada (preencha) | C2: Calculada (automático) | D2: Aviso (texto em vermelho) | E2: Título de bloco | F2: Cabeçalho de coluna | G2: Rótulo da linha | H2: Linha alternada (outro tom) | I2: Não se aplica
A3: Os personagens jogadores, copiados da ficha de cada jogador (uma linha por PJ).
A5: G1 · Quem é (preencha, da ficha de cada jogador)
A6: Nome do PJ | B6: Jogador | C6: Raça | D6: Caminho | E6: Elemento | F6: Propósito de Vida | I6: Crença do Esforço (Humano) | K6: Aviso
K7: =IF(Y7>0,"O Google leu como fórmula: escolha de novo ou digite com ' na frente.",IF(AND(LEN($R$7)>0,COUNTIF('Dados'!$A$350:$A$356,$R$7)=0),"Raça fora da lista do capítulo 05",IF(AND(LEN($T$7)>0,COUNTIF($T$7:$T$12,$T$7)>1),"Elemento repetido no grupo: cuidado com a Resistência (regra irmã, 27.5)",IF(AND(LEN($P$7)=0,LEN($R$7&$T$7&$S$7)>0),"Linha sem nome: o PJ não entra na contagem","")))) | P7: =IF(ISERROR($A$7),"",IF(ISBLANK($A$7),"",$A$7)) | R7: =IF(ISERROR($C$7),"",IF(ISBLANK($C$7),"",$C$7)) | S7: =IF(ISERROR($D$7),"",IF(ISBLANK($D$7),"",$D$7)) | T7: =IF(ISERROR($E$7),"",IF(ISBLANK($E$7),"",$E$7)) | Y7: =ISERROR($A$7)*1+ISERROR($B$7)*1+ISERROR($C$7)*1+ISERROR($D$7)*1+ISERROR($E$7)*1+ISERROR($F$7)*1+ISERROR($I$7)*1
K8: =IF(Y8>0,"O Google leu como fórmula: escolha de novo ou digite com ' na frente.",IF(AND(LEN($R$8)>0,COUNTIF('Dados'!$A$350:$A$356,$R$8)=0),"Raça fora da lista do capítulo 05",IF(AND(LEN($T$8)>0,COUNTIF($T$7:$T$12,$T$8)>1),"Elemento repetido no grupo: cuidado com a Resistência (regra irmã, 27.5)",IF(AND(LEN($P$8)=0,LEN($R$8&$T$8&$S$8)>0),"Linha sem nome: o PJ não entra na contagem","")))) | P8: =IF(ISERROR($A$8),"",IF(ISBLANK($A$8),"",$A$8)) | R8: =IF(ISERROR($C$8),"",IF(ISBLANK($C$8),"",$C$8)) | S8: =IF(ISERROR($D$8),"",IF(ISBLANK($D$8),"",$D$8)) | T8: =IF(ISERROR($E$8),"",IF(ISBLANK($E$8),"",$E$8)) | Y8: =ISERROR($A$8)*1+ISERROR($B$8)*1+ISERROR($C$8)*1+ISERROR($D$8)*1+ISERROR($E$8)*1+ISERROR($F$8)*1+ISERROR($I$8)*1
K9: =IF(Y9>0,"O Google leu como fórmula: escolha de novo ou digite com ' na frente.",IF(AND(LEN($R$9)>0,COUNTIF('Dados'!$A$350:$A$356,$R$9)=0),"Raça fora da lista do capítulo 05",IF(AND(LEN($T$9)>0,COUNTIF($T$7:$T$12,$T$9)>1),"Elemento repetido no grupo: cuidado com a Resistência (regra irmã, 27.5)",IF(AND(LEN($P$9)=0,LEN($R$9&$T$9&$S$9)>0),"Linha sem nome: o PJ não entra na contagem","")))) | P9: =IF(ISERROR($A$9),"",IF(ISBLANK($A$9),"",$A$9)) | R9: =IF(ISERROR($C$9),"",IF(ISBLANK($C$9),"",$C$9)) | S9: =IF(ISERROR($D$9),"",IF(ISBLANK($D$9),"",$D$9)) | T9: =IF(ISERROR($E$9),"",IF(ISBLANK($E$9),"",$E$9)) | Y9: =ISERROR($A$9)*1+ISERROR($B$9)*1+ISERROR($C$9)*1+ISERROR($D$9)*1+ISERROR($E$9)*1+ISERROR($F$9)*1+ISERROR($I$9)*1
K10: =IF(Y10>0,"O Google leu como fórmula: escolha de novo ou digite com ' na frente.",IF(AND(LEN($R$10)>0,COUNTIF('Dados'!$A$350:$A$356,$R$10)=0),"Raça fora da lista do capítulo 05",IF(AND(LEN($T$10)>0,COUNTIF($T$7:$T$12,$T$10)>1),"Elemento repetido no grupo: cuidado com a Resistência (regra irmã, 27.5)",IF(AND(LEN($P$10)=0,LEN($R$10&$T$10&$S$10)>0),"Linha sem nome: o PJ não entra na contagem","")))) | P10: =IF(ISERROR($A$10),"",IF(ISBLANK($A$10),"",$A$10)) | R10: =IF(ISERROR($C$10),"",IF(ISBLANK($C$10),"",$C$10)) | S10: =IF(ISERROR($D$10),"",IF(ISBLANK($D$10),"",$D$10)) | T10: =IF(ISERROR($E$10),"",IF(ISBLANK($E$10),"",$E$10)) | Y10: =ISERROR($A$10)*1+ISERROR($B$10)*1+ISERROR($C$10)*1+ISERROR($D$10)*1+ISERROR($E$10)*1+ISERROR($F$10)*1+ISERROR($I$10)*1
K11: =IF(Y11>0,"O Google leu como fórmula: escolha de novo ou digite com ' na frente.",IF(AND(LEN($R$11)>0,COUNTIF('Dados'!$A$350:$A$356,$R$11)=0),"Raça fora da lista do capítulo 05",IF(AND(LEN($T$11)>0,COUNTIF($T$7:$T$12,$T$11)>1),"Elemento repetido no grupo: cuidado com a Resistência (regra irmã, 27.5)",IF(AND(LEN($P$11)=0,LEN($R$11&$T$11&$S$11)>0),"Linha sem nome: o PJ não entra na contagem","")))) | P11: =IF(ISERROR($A$11),"",IF(ISBLANK($A$11),"",$A$11)) | R11: =IF(ISERROR($C$11),"",IF(ISBLANK($C$11),"",$C$11)) | S11: =IF(ISERROR($D$11),"",IF(ISBLANK($D$11),"",$D$11)) | T11: =IF(ISERROR($E$11),"",IF(ISBLANK($E$11),"",$E$11)) | Y11: =ISERROR($A$11)*1+ISERROR($B$11)*1+ISERROR($C$11)*1+ISERROR($D$11)*1+ISERROR($E$11)*1+ISERROR($F$11)*1+ISERROR($I$11)*1
K12: =IF(Y12>0,"O Google leu como fórmula: escolha de novo ou digite com ' na frente.",IF(AND(LEN($R$12)>0,COUNTIF('Dados'!$A$350:$A$356,$R$12)=0),"Raça fora da lista do capítulo 05",IF(AND(LEN($T$12)>0,COUNTIF($T$7:$T$12,$T$12)>1),"Elemento repetido no grupo: cuidado com a Resistência (regra irmã, 27.5)",IF(AND(LEN($P$12)=0,LEN($R$12&$T$12&$S$12)>0),"Linha sem nome: o PJ não entra na contagem","")))) | P12: =IF(ISERROR($A$12),"",IF(ISBLANK($A$12),"",$A$12)) | R12: =IF(ISERROR($C$12),"",IF(ISBLANK($C$12),"",$C$12)) | S12: =IF(ISERROR($D$12),"",IF(ISBLANK($D$12),"",$D$12)) | T12: =IF(ISERROR($E$12),"",IF(ISBLANK($E$12),"",$E$12)) | Y12: =ISERROR($A$12)*1+ISERROR($B$12)*1+ISERROR($C$12)*1+ISERROR($D$12)*1+ISERROR($E$12)*1+ISERROR($F$12)*1+ISERROR($I$12)*1
A14: G2 · Números de combate (preencha, da aba Em Jogo da ficha)
A15: PJ | B15: PV máx. | C15: Defesa | D15: Esquiva | E15: RD | F15: VEL | G15: Bônus de Agilidade | H15: Bônus de Discernimento | I15: Bônus de Presença | J15: DT das Habilidades | K15: Aviso
A16: =IF(LEN($P$7)>0,$P$7,"PJ 1") | K16: =IF(Y16>0,"O Google leu como fórmula: digite de novo com ' na frente.",IF(AND(ISNUMBER($U$16),OR($U$16<7,$U$16>25)),"VEL fora dos extremos 7 a 25 da fórmula: confira na ficha (19.1)",IF(OR(AND(ISNUMBER($V$16),OR($V$16<-1,$V$16>5)),AND(ISNUMBER($W$16),OR($W$16<-1,$W$16>5)),AND(ISNUMBER($X$16),OR($X$16<-1,$X$16>5))),"Bônus de Atributo fora de -1 a +5: confira na ficha",IF(AND(ISNUMBER($Q$16),OR($Q$16<1,$Q$16>999)),"PV fora de 1 a 999: confira na ficha","")))) | Q16: =IF(ISERROR($B$16),"",IF(ISBLANK($B$16),"",$B$16)) | U16: =IF(ISERROR($F$16),"",IF(ISBLANK($F$16),"",$F$16)) | V16: =IF(ISERROR($G$16),"",IF(ISBLANK($G$16),"",$G$16)) | W16: =IF(ISERROR($H$16),"",IF(ISBLANK($H$16),"",$H$16)) | X16: =IF(ISERROR($I$16),"",IF(ISBLANK($I$16),"",$I$16)) | Y16: =ISERROR($B$16)*1+ISERROR($C$16)*1+ISERROR($D$16)*1+ISERROR($E$16)*1+ISERROR($F$16)*1+ISERROR($G$16)*1+ISERROR($H$16)*1+ISERROR($I$16)*1+ISERROR($J$16)*1
A17: =IF(LEN($P$8)>0,$P$8,"PJ 2") | K17: =IF(Y17>0,"O Google leu como fórmula: digite de novo com ' na frente.",IF(AND(ISNUMBER($U$17),OR($U$17<7,$U$17>25)),"VEL fora dos extremos 7 a 25 da fórmula: confira na ficha (19.1)",IF(OR(AND(ISNUMBER($V$17),OR($V$17<-1,$V$17>5)),AND(ISNUMBER($W$17),OR($W$17<-1,$W$17>5)),AND(ISNUMBER($X$17),OR($X$17<-1,$X$17>5))),"Bônus de Atributo fora de -1 a +5: confira na ficha",IF(AND(ISNUMBER($Q$17),OR($Q$17<1,$Q$17>999)),"PV fora de 1 a 999: confira na ficha","")))) | Q17: =IF(ISERROR($B$17),"",IF(ISBLANK($B$17),"",$B$17)) | U17: =IF(ISERROR($F$17),"",IF(ISBLANK($F$17),"",$F$17)) | V17: =IF(ISERROR($G$17),"",IF(ISBLANK($G$17),"",$G$17)) | W17: =IF(ISERROR($H$17),"",IF(ISBLANK($H$17),"",$H$17)) | X17: =IF(ISERROR($I$17),"",IF(ISBLANK($I$17),"",$I$17)) | Y17: =ISERROR($B$17)*1+ISERROR($C$17)*1+ISERROR($D$17)*1+ISERROR($E$17)*1+ISERROR($F$17)*1+ISERROR($G$17)*1+ISERROR($H$17)*1+ISERROR($I$17)*1+ISERROR($J$17)*1
A18: =IF(LEN($P$9)>0,$P$9,"PJ 3") | K18: =IF(Y18>0,"O Google leu como fórmula: digite de novo com ' na frente.",IF(AND(ISNUMBER($U$18),OR($U$18<7,$U$18>25)),"VEL fora dos extremos 7 a 25 da fórmula: confira na ficha (19.1)",IF(OR(AND(ISNUMBER($V$18),OR($V$18<-1,$V$18>5)),AND(ISNUMBER($W$18),OR($W$18<-1,$W$18>5)),AND(ISNUMBER($X$18),OR($X$18<-1,$X$18>5))),"Bônus de Atributo fora de -1 a +5: confira na ficha",IF(AND(ISNUMBER($Q$18),OR($Q$18<1,$Q$18>999)),"PV fora de 1 a 999: confira na ficha","")))) | Q18: =IF(ISERROR($B$18),"",IF(ISBLANK($B$18),"",$B$18)) | U18: =IF(ISERROR($F$18),"",IF(ISBLANK($F$18),"",$F$18)) | V18: =IF(ISERROR($G$18),"",IF(ISBLANK($G$18),"",$G$18)) | W18: =IF(ISERROR($H$18),"",IF(ISBLANK($H$18),"",$H$18)) | X18: =IF(ISERROR($I$18),"",IF(ISBLANK($I$18),"",$I$18)) | Y18: =ISERROR($B$18)*1+ISERROR($C$18)*1+ISERROR($D$18)*1+ISERROR($E$18)*1+ISERROR($F$18)*1+ISERROR($G$18)*1+ISERROR($H$18)*1+ISERROR($I$18)*1+ISERROR($J$18)*1
A19: =IF(LEN($P$10)>0,$P$10,"PJ 4") | K19: =IF(Y19>0,"O Google leu como fórmula: digite de novo com ' na frente.",IF(AND(ISNUMBER($U$19),OR($U$19<7,$U$19>25)),"VEL fora dos extremos 7 a 25 da fórmula: confira na ficha (19.1)",IF(OR(AND(ISNUMBER($V$19),OR($V$19<-1,$V$19>5)),AND(ISNUMBER($W$19),OR($W$19<-1,$W$19>5)),AND(ISNUMBER($X$19),OR($X$19<-1,$X$19>5))),"Bônus de Atributo fora de -1 a +5: confira na ficha",IF(AND(ISNUMBER($Q$19),OR($Q$19<1,$Q$19>999)),"PV fora de 1 a 999: confira na ficha","")))) | Q19: =IF(ISERROR($B$19),"",IF(ISBLANK($B$19),"",$B$19)) | U19: =IF(ISERROR($F$19),"",IF(ISBLANK($F$19),"",$F$19)) | V19: =IF(ISERROR($G$19),"",IF(ISBLANK($G$19),"",$G$19)) | W19: =IF(ISERROR($H$19),"",IF(ISBLANK($H$19),"",$H$19)) | X19: =IF(ISERROR($I$19),"",IF(ISBLANK($I$19),"",$I$19)) | Y19: =ISERROR($B$19)*1+ISERROR($C$19)*1+ISERROR($D$19)*1+ISERROR($E$19)*1+ISERROR($F$19)*1+ISERROR($G$19)*1+ISERROR($H$19)*1+ISERROR($I$19)*1+ISERROR($J$19)*1
A20: =IF(LEN($P$11)>0,$P$11,"PJ 5") | K20: =IF(Y20>0,"O Google leu como fórmula: digite de novo com ' na frente.",IF(AND(ISNUMBER($U$20),OR($U$20<7,$U$20>25)),"VEL fora dos extremos 7 a 25 da fórmula: confira na ficha (19.1)",IF(OR(AND(ISNUMBER($V$20),OR($V$20<-1,$V$20>5)),AND(ISNUMBER($W$20),OR($W$20<-1,$W$20>5)),AND(ISNUMBER($X$20),OR($X$20<-1,$X$20>5))),"Bônus de Atributo fora de -1 a +5: confira na ficha",IF(AND(ISNUMBER($Q$20),OR($Q$20<1,$Q$20>999)),"PV fora de 1 a 999: confira na ficha","")))) | Q20: =IF(ISERROR($B$20),"",IF(ISBLANK($B$20),"",$B$20)) | U20: =IF(ISERROR($F$20),"",IF(ISBLANK($F$20),"",$F$20)) | V20: =IF(ISERROR($G$20),"",IF(ISBLANK($G$20),"",$G$20)) | W20: =IF(ISERROR($H$20),"",IF(ISBLANK($H$20),"",$H$20)) | X20: =IF(ISERROR($I$20),"",IF(ISBLANK($I$20),"",$I$20)) | Y20: =ISERROR($B$20)*1+ISERROR($C$20)*1+ISERROR($D$20)*1+ISERROR($E$20)*1+ISERROR($F$20)*1+ISERROR($G$20)*1+ISERROR($H$20)*1+ISERROR($I$20)*1+ISERROR($J$20)*1
A21: =IF(LEN($P$12)>0,$P$12,"PJ 6") | K21: =IF(Y21>0,"O Google leu como fórmula: digite de novo com ' na frente.",IF(AND(ISNUMBER($U$21),OR($U$21<7,$U$21>25)),"VEL fora dos extremos 7 a 25 da fórmula: confira na ficha (19.1)",IF(OR(AND(ISNUMBER($V$21),OR($V$21<-1,$V$21>5)),AND(ISNUMBER($W$21),OR($W$21<-1,$W$21>5)),AND(ISNUMBER($X$21),OR($X$21<-1,$X$21>5))),"Bônus de Atributo fora de -1 a +5: confira na ficha",IF(AND(ISNUMBER($Q$21),OR($Q$21<1,$Q$21>999)),"PV fora de 1 a 999: confira na ficha","")))) | Q21: =IF(ISERROR($B$21),"",IF(ISBLANK($B$21),"",$B$21)) | U21: =IF(ISERROR($F$21),"",IF(ISBLANK($F$21),"",$F$21)) | V21: =IF(ISERROR($G$21),"",IF(ISBLANK($G$21),"",$G$21)) | W21: =IF(ISERROR($H$21),"",IF(ISBLANK($H$21),"",$H$21)) | X21: =IF(ISERROR($I$21),"",IF(ISBLANK($I$21),"",$I$21)) | Y21: =ISERROR($B$21)*1+ISERROR($C$21)*1+ISERROR($D$21)*1+ISERROR($E$21)*1+ISERROR($F$21)*1+ISERROR($G$21)*1+ISERROR($H$21)*1+ISERROR($I$21)*1+ISERROR($J$21)*1
A23: G3 · Equipamento de faixa (preencha)
A24: PJ | B24: Nível do Cone | C24: Tier de Relíquias | D24: Slots de Relíquia | E24: Sobreposições nesta faixa | F24: Ressonâncias escolhidas | K24: Aviso
A25: =IF(LEN($P$7)>0,$P$7,"PJ 1") | K25: =IF(Y25>0,"O Google leu como fórmula: digite de novo com ' na frente.",IF(AND(ISNUMBER($Q$25),$Q$25>'Campanha'!$B$18),"Cone acima do máximo da faixa (25.1)",IF(AND(ISNUMBER($T$25),$T$25>1),"Mais de 1 Sobreposição nesta faixa (25.2)",""))) | Q25: =IF(ISERROR($B$25),"",IF(ISBLANK($B$25),"",$B$25)) | T25: =IF(ISERROR($E$25),"",IF(ISBLANK($E$25),"",$E$25)) | Y25: =ISERROR($B$25)*1+ISERROR($C$25)*1+ISERROR($D$25)*1+ISERROR($E$25)*1+ISERROR($F$25)*1
A26: =IF(LEN($P$8)>0,$P$8,"PJ 2") | K26: =IF(Y26>0,"O Google leu como fórmula: digite de novo com ' na frente.",IF(AND(ISNUMBER($Q$26),$Q$26>'Campanha'!$B$18),"Cone acima do máximo da faixa (25.1)",IF(AND(ISNUMBER($T$26),$T$26>1),"Mais de 1 Sobreposição nesta faixa (25.2)",""))) | Q26: =IF(ISERROR($B$26),"",IF(ISBLANK($B$26),"",$B$26)) | T26: =IF(ISERROR($E$26),"",IF(ISBLANK($E$26),"",$E$26)) | Y26: =ISERROR($B$26)*1+ISERROR($C$26)*1+ISERROR($D$26)*1+ISERROR($E$26)*1+ISERROR($F$26)*1
A27: =IF(LEN($P$9)>0,$P$9,"PJ 3") | K27: =IF(Y27>0,"O Google leu como fórmula: digite de novo com ' na frente.",IF(AND(ISNUMBER($Q$27),$Q$27>'Campanha'!$B$18),"Cone acima do máximo da faixa (25.1)",IF(AND(ISNUMBER($T$27),$T$27>1),"Mais de 1 Sobreposição nesta faixa (25.2)",""))) | Q27: =IF(ISERROR($B$27),"",IF(ISBLANK($B$27),"",$B$27)) | T27: =IF(ISERROR($E$27),"",IF(ISBLANK($E$27),"",$E$27)) | Y27: =ISERROR($B$27)*1+ISERROR($C$27)*1+ISERROR($D$27)*1+ISERROR($E$27)*1+ISERROR($F$27)*1
A28: =IF(LEN($P$10)>0,$P$10,"PJ 4") | K28: =IF(Y28>0,"O Google leu como fórmula: digite de novo com ' na frente.",IF(AND(ISNUMBER($Q$28),$Q$28>'Campanha'!$B$18),"Cone acima do máximo da faixa (25.1)",IF(AND(ISNUMBER($T$28),$T$28>1),"Mais de 1 Sobreposição nesta faixa (25.2)",""))) | Q28: =IF(ISERROR($B$28),"",IF(ISBLANK($B$28),"",$B$28)) | T28: =IF(ISERROR($E$28),"",IF(ISBLANK($E$28),"",$E$28)) | Y28: =ISERROR($B$28)*1+ISERROR($C$28)*1+ISERROR($D$28)*1+ISERROR($E$28)*1+ISERROR($F$28)*1
A29: =IF(LEN($P$11)>0,$P$11,"PJ 5") | K29: =IF(Y29>0,"O Google leu como fórmula: digite de novo com ' na frente.",IF(AND(ISNUMBER($Q$29),$Q$29>'Campanha'!$B$18),"Cone acima do máximo da faixa (25.1)",IF(AND(ISNUMBER($T$29),$T$29>1),"Mais de 1 Sobreposição nesta faixa (25.2)",""))) | Q29: =IF(ISERROR($B$29),"",IF(ISBLANK($B$29),"",$B$29)) | T29: =IF(ISERROR($E$29),"",IF(ISBLANK($E$29),"",$E$29)) | Y29: =ISERROR($B$29)*1+ISERROR($C$29)*1+ISERROR($D$29)*1+ISERROR($E$29)*1+ISERROR($F$29)*1
A30: =IF(LEN($P$12)>0,$P$12,"PJ 6") | K30: =IF(Y30>0,"O Google leu como fórmula: digite de novo com ' na frente.",IF(AND(ISNUMBER($Q$30),$Q$30>'Campanha'!$B$18),"Cone acima do máximo da faixa (25.1)",IF(AND(ISNUMBER($T$30),$T$30>1),"Mais de 1 Sobreposição nesta faixa (25.2)",""))) | Q30: =IF(ISERROR($B$30),"",IF(ISBLANK($B$30),"",$B$30)) | T30: =IF(ISERROR($E$30),"",IF(ISBLANK($E$30),"",$E$30)) | Y30: =ISERROR($B$30)*1+ISERROR($C$30)*1+ISERROR($D$30)*1+ISERROR($E$30)*1+ISERROR($F$30)*1
A32: G4 · O que a Raça muda no combate (automático)
A33: PJ | B33: Morrendo com Vantagem? | C33: Pode ser Executado? | D33: Esforço? | E33: Descobre Fraqueza | G33: Lembrete da Raça | K33: Aviso
A34: =IF(LEN($P$7)>0,$P$7,"PJ 1") | B34: =IFERROR(INDEX('Dados'!$B$350:$B$356,MATCH($R$7,'Dados'!$A$350:$A$356,0)),"") | C34: =IFERROR(INDEX('Dados'!$C$350:$C$356,MATCH($R$7,'Dados'!$A$350:$A$356,0)),"") | D34: =IFERROR(INDEX('Dados'!$D$350:$D$356,MATCH($R$7,'Dados'!$A$350:$A$356,0)),"") | E34: =IFERROR(INDEX('Dados'!$E$350:$E$356,MATCH($R$7,'Dados'!$A$350:$A$356,0)),"") | G34: =IF($R$7="Vulpes","Raposa Astuta: segunda chance contra a Surpresa (DT 10, 19.3 e 27.3)",IF($R$7="Haloviano","To na sua mente: DT 13 de ativação (27.3)",IF($R$7="Xianzhouíta","Não pode ser Executado (05, 23.5)",IF($R$7="Intellitron","Descobre Fraqueza com Vantagem e 2 por sucesso (20.2)",IF($R$7="Humano","Esforço: no máximo 1 ponto (05)",""))))) | K34: =IF(AND(ISNUMBER($Q$25),$Q$25<'Campanha'!$B$18),"Cone abaixo do esperado: encontros ficam mais duros (27.8)","")
A35: =IF(LEN($P$8)>0,$P$8,"PJ 2") | B35: =IFERROR(INDEX('Dados'!$B$350:$B$356,MATCH($R$8,'Dados'!$A$350:$A$356,0)),"") | C35: =IFERROR(INDEX('Dados'!$C$350:$C$356,MATCH($R$8,'Dados'!$A$350:$A$356,0)),"") | D35: =IFERROR(INDEX('Dados'!$D$350:$D$356,MATCH($R$8,'Dados'!$A$350:$A$356,0)),"") | E35: =IFERROR(INDEX('Dados'!$E$350:$E$356,MATCH($R$8,'Dados'!$A$350:$A$356,0)),"") | G35: =IF($R$8="Vulpes","Raposa Astuta: segunda chance contra a Surpresa (DT 10, 19.3 e 27.3)",IF($R$8="Haloviano","To na sua mente: DT 13 de ativação (27.3)",IF($R$8="Xianzhouíta","Não pode ser Executado (05, 23.5)",IF($R$8="Intellitron","Descobre Fraqueza com Vantagem e 2 por sucesso (20.2)",IF($R$8="Humano","Esforço: no máximo 1 ponto (05)",""))))) | K35: =IF(AND(ISNUMBER($Q$26),$Q$26<'Campanha'!$B$18),"Cone abaixo do esperado: encontros ficam mais duros (27.8)","")
A36: =IF(LEN($P$9)>0,$P$9,"PJ 3") | B36: =IFERROR(INDEX('Dados'!$B$350:$B$356,MATCH($R$9,'Dados'!$A$350:$A$356,0)),"") | C36: =IFERROR(INDEX('Dados'!$C$350:$C$356,MATCH($R$9,'Dados'!$A$350:$A$356,0)),"") | D36: =IFERROR(INDEX('Dados'!$D$350:$D$356,MATCH($R$9,'Dados'!$A$350:$A$356,0)),"") | E36: =IFERROR(INDEX('Dados'!$E$350:$E$356,MATCH($R$9,'Dados'!$A$350:$A$356,0)),"") | G36: =IF($R$9="Vulpes","Raposa Astuta: segunda chance contra a Surpresa (DT 10, 19.3 e 27.3)",IF($R$9="Haloviano","To na sua mente: DT 13 de ativação (27.3)",IF($R$9="Xianzhouíta","Não pode ser Executado (05, 23.5)",IF($R$9="Intellitron","Descobre Fraqueza com Vantagem e 2 por sucesso (20.2)",IF($R$9="Humano","Esforço: no máximo 1 ponto (05)",""))))) | K36: =IF(AND(ISNUMBER($Q$27),$Q$27<'Campanha'!$B$18),"Cone abaixo do esperado: encontros ficam mais duros (27.8)","")
A37: =IF(LEN($P$10)>0,$P$10,"PJ 4") | B37: =IFERROR(INDEX('Dados'!$B$350:$B$356,MATCH($R$10,'Dados'!$A$350:$A$356,0)),"") | C37: =IFERROR(INDEX('Dados'!$C$350:$C$356,MATCH($R$10,'Dados'!$A$350:$A$356,0)),"") | D37: =IFERROR(INDEX('Dados'!$D$350:$D$356,MATCH($R$10,'Dados'!$A$350:$A$356,0)),"") | E37: =IFERROR(INDEX('Dados'!$E$350:$E$356,MATCH($R$10,'Dados'!$A$350:$A$356,0)),"") | G37: =IF($R$10="Vulpes","Raposa Astuta: segunda chance contra a Surpresa (DT 10, 19.3 e 27.3)",IF($R$10="Haloviano","To na sua mente: DT 13 de ativação (27.3)",IF($R$10="Xianzhouíta","Não pode ser Executado (05, 23.5)",IF($R$10="Intellitron","Descobre Fraqueza com Vantagem e 2 por sucesso (20.2)",IF($R$10="Humano","Esforço: no máximo 1 ponto (05)",""))))) | K37: =IF(AND(ISNUMBER($Q$28),$Q$28<'Campanha'!$B$18),"Cone abaixo do esperado: encontros ficam mais duros (27.8)","")
A38: =IF(LEN($P$11)>0,$P$11,"PJ 5") | B38: =IFERROR(INDEX('Dados'!$B$350:$B$356,MATCH($R$11,'Dados'!$A$350:$A$356,0)),"") | C38: =IFERROR(INDEX('Dados'!$C$350:$C$356,MATCH($R$11,'Dados'!$A$350:$A$356,0)),"") | D38: =IFERROR(INDEX('Dados'!$D$350:$D$356,MATCH($R$11,'Dados'!$A$350:$A$356,0)),"") | E38: =IFERROR(INDEX('Dados'!$E$350:$E$356,MATCH($R$11,'Dados'!$A$350:$A$356,0)),"") | G38: =IF($R$11="Vulpes","Raposa Astuta: segunda chance contra a Surpresa (DT 10, 19.3 e 27.3)",IF($R$11="Haloviano","To na sua mente: DT 13 de ativação (27.3)",IF($R$11="Xianzhouíta","Não pode ser Executado (05, 23.5)",IF($R$11="Intellitron","Descobre Fraqueza com Vantagem e 2 por sucesso (20.2)",IF($R$11="Humano","Esforço: no máximo 1 ponto (05)",""))))) | K38: =IF(AND(ISNUMBER($Q$29),$Q$29<'Campanha'!$B$18),"Cone abaixo do esperado: encontros ficam mais duros (27.8)","")
A39: =IF(LEN($P$12)>0,$P$12,"PJ 6") | B39: =IFERROR(INDEX('Dados'!$B$350:$B$356,MATCH($R$12,'Dados'!$A$350:$A$356,0)),"") | C39: =IFERROR(INDEX('Dados'!$C$350:$C$356,MATCH($R$12,'Dados'!$A$350:$A$356,0)),"") | D39: =IFERROR(INDEX('Dados'!$D$350:$D$356,MATCH($R$12,'Dados'!$A$350:$A$356,0)),"") | E39: =IFERROR(INDEX('Dados'!$E$350:$E$356,MATCH($R$12,'Dados'!$A$350:$A$356,0)),"") | G39: =IF($R$12="Vulpes","Raposa Astuta: segunda chance contra a Surpresa (DT 10, 19.3 e 27.3)",IF($R$12="Haloviano","To na sua mente: DT 13 de ativação (27.3)",IF($R$12="Xianzhouíta","Não pode ser Executado (05, 23.5)",IF($R$12="Intellitron","Descobre Fraqueza com Vantagem e 2 por sucesso (20.2)",IF($R$12="Humano","Esforço: no máximo 1 ponto (05)",""))))) | K39: =IF(AND(ISNUMBER($Q$30),$Q$30<'Campanha'!$B$18),"Cone abaixo do esperado: encontros ficam mais duros (27.8)","")
A41: Resumo do grupo (automático)
A42: Nº de PJs | B42: =SUMPRODUCT((LEN($P$7:$P$12)>0)*1) | C42: =IF(AND(ISNUMBER('Campanha'!$P$8),$B$42>0,$B$42<>'Campanha'!$P$8),"Nº de PJs diferente do nº de jogadores da aba Campanha","")
A43: Elemento | B43: Físico | C43: Fogo | D43: Gelo | E43: Raio | F43: Vento | G43: Quântico | H43: Imaginário | I43: Distintos | J43: Em dobro
A44: No grupo? | B44: =IF(COUNTIF($T$7:$T$12,"Físico")>0,"Sim","Não") | C44: =IF(COUNTIF($T$7:$T$12,"Fogo")>0,"Sim","Não") | D44: =IF(COUNTIF($T$7:$T$12,"Gelo")>0,"Sim","Não") | E44: =IF(COUNTIF($T$7:$T$12,"Raio")>0,"Sim","Não") | F44: =IF(COUNTIF($T$7:$T$12,"Vento")>0,"Sim","Não") | G44: =IF(COUNTIF($T$7:$T$12,"Quântico")>0,"Sim","Não") | H44: =IF(COUNTIF($T$7:$T$12,"Imaginário")>0,"Sim","Não") | I44: =IF($B$44="Sim",1,0)+IF($C$44="Sim",1,0)+IF($D$44="Sim",1,0)+IF($E$44="Sim",1,0)+IF($F$44="Sim",1,0)+IF($G$44="Sim",1,0)+IF($H$44="Sim",1,0) | J44: =IF(COUNTIF($T$7:$T$12,"Físico")>1,1,0)+IF(COUNTIF($T$7:$T$12,"Fogo")>1,1,0)+IF(COUNTIF($T$7:$T$12,"Gelo")>1,1,0)+IF(COUNTIF($T$7:$T$12,"Raio")>1,1,0)+IF(COUNTIF($T$7:$T$12,"Vento")>1,1,0)+IF(COUNTIF($T$7:$T$12,"Quântico")>1,1,0)+IF(COUNTIF($T$7:$T$12,"Imaginário")>1,1,0)
A45: Presenças | B45: =IF(COUNTIF($R$7:$R$12,"Intellitron")>0,"Intellitron no grupo: descobre Fraqueza com Vantagem e 2 por sucesso (20.2). ","")&IF(COUNTIF($R$7:$R$12,"Humano")>0,"Humano no grupo: Esforço (05). ","")&IF(COUNTIF($S$7:$S$12,"A Preservação")+COUNTIF($S$7:$S$12,"A Abundância")>0,"Há Caminho de sustentação (27.7).","Sem Preservação nem Abundância: cuidado com o dia de jogo (27.7).")

Sheet Sessões
A1: Sessões — Explorando Galáxias v1.1
A2: Legenda: | B2: Entrada (preencha) | C2: Calculada (automático) | D2: Aviso (texto em vermelho) | E2: Título de bloco | F2: Cabeçalho de coluna | G2: Rótulo da linha | H2: Linha alternada (outro tom) | I2: Não se aplica
A3: Preparar a próxima sessão e o diário de campanha.
A5: Em construção: esta aba chega numa próxima fase da Planilha do Mestre.

Sheet Missões
A1: Missões — Explorando Galáxias v1.1
A2: Legenda: | B2: Entrada (preencha) | C2: Calculada (automático) | D2: Aviso (texto em vermelho) | E2: Título de bloco | F2: Cabeçalho de coluna | G2: Rótulo da linha | H2: Linha alternada (outro tom) | I2: Não se aplica
A3: As missões oferecidas, ativas e concluídas.
A5: Em construção: esta aba chega numa próxima fase da Planilha do Mestre.

Sheet NPCs
A1: NPCs — Explorando Galáxias v1.1
A2: Legenda: | B2: Entrada (preencha) | C2: Calculada (automático) | D2: Aviso (texto em vermelho) | E2: Título de bloco | F2: Cabeçalho de coluna | G2: Rótulo da linha | H2: Linha alternada (outro tom) | I2: Não se aplica
A3: Gerador de NPCs (nome por cultura, Raça, Caminho, ocupação, voz, segredo, gancho), elenco e cartões.
A5: Gerador de NPCs (G = 200): vazio = Sortear; a semente é a da aba Início
A6: Rolagem nº | B6: Raça | D6: Caminho | F6: Papel na história | H6: Bloco de combate | J6: Tipo do bloco | K6: Aviso
K7: =IF(BF7>0,"O Google leu como fórmula: escolha de novo ou digite com ' na frente.",IF(LEN(IF(LEN($AV$7)=0,"",IF(ISNUMBER($AV$7),IF(AND($AV$7>=1,$AV$7<=1000000,INT($AV$7)=$AV$7),"","Rolagem nº fora de 1 a 1.000.000: usando 1"),"Rolagem nº fora de 1 a 1.000.000: usando 1")))>0,IF(LEN($AV$7)=0,"",IF(ISNUMBER($AV$7),IF(AND($AV$7>=1,$AV$7<=1000000,INT($AV$7)=$AV$7),"","Rolagem nº fora de 1 a 1.000.000: usando 1"),"Rolagem nº fora de 1 a 1.000.000: usando 1")),IF(AND(LEN($AW$7)>0,$AW$7<>"Sortear",COUNTIF('Dados'!$A$350:$A$356,$AW$7)=0),"Raça fora da lista do capítulo 05: sorteando",IF(AND(LEN($AY$7)>0,$AY$7<>"Sortear",$AY$7<>"Nenhum",COUNTIF('Dados'!$A$360:$A$368,$AY$7)=0),"Caminho fora da lista: sorteando",IF(AND(LEN($BA$7)>0,$BA$7<>"Sortear",COUNTIF('Dados'!$A$398:$A$404,$BA$7)=0),"Papel fora da lista: sorteando",IF(AND(LEN($BC$7)>0,$BC$7<>"Nenhum",$BC$7<>"Do grupo",LEN(IFERROR(INDEX('Dados'!$B$7:$B$11,MATCH($BC$7,'Dados'!$AP$6:$AP$10,0)),""))=0),"Bloco de combate fora da lista: sem bloco",IF(AND(LEN($BE$7)>0,$BE$7<>"Comum",$BE$7<>"Elite"),"Tipo do bloco fora da lista: usando Comum",""))))))) | AV7: =IF(ISERROR($A$7),"",IF(ISBLANK($A$7),"",$A$7)) | AW7: =IF(ISERROR($B$7),"",IF(ISBLANK($B$7),"",$B$7)) | AY7: =IF(ISERROR($D$7),"",IF(ISBLANK($D$7),"",$D$7)) | BA7: =IF(ISERROR($F$7),"",IF(ISBLANK($F$7),"",$F$7)) | BC7: =IF(ISERROR($H$7),"",IF(ISBLANK($H$7),"",$H$7)) | BE7: =IF(ISERROR($J$7),"",IF(ISBLANK($J$7),"",$J$7)) | BF7: =ISERROR($A$7)*1+ISERROR($B$7)*1+ISERROR($D$7)*1+ISERROR($F$7)*1+ISERROR($H$7)*1+ISERROR($J$7)*1
A8: Rolagem efetiva | B8: =IF(ISNUMBER($AV$7),IF(AND($AV$7>=1,$AV$7<=1000000,INT($AV$7)=$AV$7),$AV$7,1),1) | C8: Mesma semente e mesma Rolagem nº dão o mesmo NPC; para outro, some 1 na Rolagem nº. Bloco de combate vazio = Nenhum; tipo vazio = Comum.
A10: NPC sorteado (automático) | N10: =IF(COUNTIF('Dados'!$A$350:$A$356,$AW$7)>0,$AW$7,INDEX('Dados'!$A$350:$A$356,INT($AC$10*7/2147483647)+1)) | AA10: =MOD(MOD(MOD((MOD('Início'!$E$15+104729*$B$8+2883509,2147483646)+1)*16807,2147483647)*16807,2147483647)*16807,2147483647) | AB10: =MOD(MOD(MOD((MOD(MOD(INT($AA$10/65536)*$AA$10,2147483647)*65536+MOD($AA$10,65536)*$AA$10,2147483647))*16807,2147483647)*16807,2147483647)*16807,2147483647) | AC10: =MOD(MOD(MOD((MOD($AB$10+INT($AB$10/65536)*MOD($AB$10,65536),2147483646)+1)*16807,2147483647)*16807,2147483647)*16807,2147483647) | AE10: =0+IF(AND(LEN($N$15)>0,INDEX('Tabelas'!$X$472:$X$578,1)&""=$N$15,LEN(INDEX('Tabelas'!$Y$472:$Y$578,1)&"")>0),1,0) | AG10: =$AV$46&"" | AH10: =$AW$46&"" | AI10: =$AY$46&"" | AJ10: =$BC$46&"" | AK10: =$AW$80&"" | AL10: =$AW$148&"" | AM10: =$AW$114&"" | AN10: =$BA$114&"" | AO10: =$AZ$148&"" | AP10: =$BA$46&"" | AT10: ='Tabelas'!$AE$357&""
A11: Campo | B11: Sorteado | I11: De onde vem | K11: Aviso | N11: =IFERROR(MATCH($N$10,'Dados'!$A$388:$A$394,0),1) | AA11: =MOD(MOD(MOD((MOD('Início'!$E$15+104729*$B$8+4183218,2147483646)+1)*16807,2147483647)*16807,2147483647)*16807,2147483647) | AB11: =MOD(MOD(MOD((MOD(MOD(INT($AA$11/65536)*$AA$11,2147483647)*65536+MOD($AA$11,65536)*$AA$11,2147483647))*16807,2147483647)*16807,2147483647)*16807,2147483647) | AC11: =MOD(MOD(MOD((MOD($AB$11+INT($AB$11/65536)*MOD($AB$11,65536),2147483646)+1)*16807,2147483647)*16807,2147483647)*16807,2147483647) | AE11: =$AE$10+IF(AND(LEN($N$15)>0,INDEX('Tabelas'!$X$472:$X$578,2)&""=$N$15,LEN(INDEX('Tabelas'!$Y$472:$Y$578,2)&"")>0),1,0) | AG11: =$AV$47&"" | AH11: =$AW$47&"" | AI11: =$AY$47&"" | AJ11: =$BC$47&"" | AK11: =$AW$81&"" | AL11: =$AW$149&"" | AM11: =$AW$115&"" | AN11: =$BA$115&"" | AO11: =$AZ$149&"" | AP11: =$BA$47&"" | AT11: ='Tabelas'!$AE$358&""
A12: Nome completo | B12: =$N$14 | I12: ="Tabelas: nome e sobrenome da cultura "&$N$10&" (estilo de 05)" | K12: =IF($N$11=1,IF('Tabelas'!$B$124+'Tabelas'!$B$239<=0,"Listas de nome da cultura Humano vazias (aba Tabelas)",""),IF($N$11=2,IF('Tabelas'!$C$124+'Tabelas'!$C$239<=0,"Listas de nome da cultura Xianzhouíta vazias (aba Tabelas)",""),IF($N$11=3,IF('Tabelas'!$D$124+'Tabelas'!$D$239<=0,"Listas de nome da cultura Vidyadhara vazias (aba Tabelas)",""),IF($N$11=4,IF('Tabelas'!$E$124+'Tabelas'!$E$239<=0,"Listas de nome da cultura Vulpes vazias (aba Tabelas)",""),IF($N$11=5,IF('Tabelas'!$F$124+'Tabelas'!$F$239<=0,"Listas de nome da cultura Haloviano vazias (aba Tabelas)",""),IF($N$11=6,IF('Tabelas'!$G$124+'Tabelas'!$G$239<=0,"Listas de nome da cultura Avginiano vazias (aba Tabelas)",""),IF('Tabelas'!$H$124+'Tabelas'!$H$239<=0,"Listas de nome da cultura Intellitron vazias (aba Tabelas)",""))))))) | N12: =IF($N$11=1,IF('Tabelas'!$B$124<=0,"",IFERROR(INDEX('Tabelas'!$X$127:$X$233,MATCH(IF('Tabelas'!$B$124<=0,0,INT($AC$11*'Tabelas'!$B$124/2147483647)+1),'Tabelas'!$N$127:$N$233,0))&"","")),IF($N$11=2,IF('Tabelas'!$C$124<=0,"",IFERROR(INDEX('Tabelas'!$Y$127:$Y$233,MATCH(IF('Tabelas'!$C$124<=0,0,INT($AC$11*'Tabelas'!$C$124/2147483647)+1),'Tabelas'!$O$127:$O$233,0))&"","")),IF($N$11=3,IF('Tabelas'!$D$124<=0,"",IFERROR(INDEX('Tabelas'!$Z$127:$Z$233,MATCH(IF('Tabelas'!$D$124<=0,0,INT($AC$11*'Tabelas'!$D$124/2147483647)+1),'Tabelas'!$P$127:$P$233,0))&"","")),IF($N$11=4,IF('Tabelas'!$E$124<=0,"",IFERROR(INDEX('Tabelas'!$AA$127:$AA$233,MATCH(IF('Tabelas'!$E$124<=0,0,INT($AC$11*'Tabelas'!$E$124/2147483647)+1),'Tabelas'!$Q$127:$Q$233,0))&"","")),IF($N$11=5,IF('Tabelas'!$F$124<=0,"",IFERROR(INDEX('Tabelas'!$AB$127:$AB$233,MATCH(IF('Tabelas'!$F$124<=0,0,INT($AC$11*'Tabelas'!$F$124/2147483647)+1),'Tabelas'!$R$127:$R$233,0))&"","")),IF($N$11=6,IF('Tabelas'!$G$124<=0,"",IFERROR(INDEX('Tabelas'!$AC$127:$AC$233,MATCH(IF('Tabelas'!$G$124<=0,0,INT($AC$11*'Tabelas'!$G$124/2147483647)+1),'Tabelas'!$S$127:$S$233,0))&"","")),IF('Tabelas'!$H$124<=0,"",IFERROR(INDEX('Tabelas'!$AD$127:$AD$233,MATCH(IF('Tabelas'!$H$124<=0,0,INT($AC$11*'Tabelas'!$H$124/2147483647)+1),'Tabelas'!$T$127:$T$233,0))&"","")))))))) | AA12: =MOD(MOD(MOD((MOD('Início'!$E$15+104729*$B$8+5482927,2147483646)+1)*16807,2147483647)*16807,2147483647)*16807,2147483647) | AB12: =MOD(MOD(MOD((MOD(MOD(INT($AA$12/65536)*$AA$12,2147483647)*65536+MOD($AA$12,65536)*$AA$12,2147483647))*16807,2147483647)*16807,2147483647)*16807,2147483647) | AC12: =MOD(MOD(MOD((MOD($AB$12+INT($AB$12/65536)*MOD($AB$12,65536),2147483646)+1)*16807,2147483647)*16807,2147483647)*16807,2147483647) | AE12: =$AE$11+IF(AND(LEN($N$15)>0,INDEX('Tabelas'!$X$472:$X$578,3)&""=$N$15,LEN(INDEX('Tabelas'!$Y$472:$Y$578,3)&"")>0),1,0) | AG12: =$AV$48&"" | AH12: =$AW$48&"" | AI12: =$AY$48&"" | AJ12: =$BC$48&"" | AK12: =$AW$82&"" | AL12: =$AW$150&"" | AM12: =$AW$116&"" | AN12: =$BA$116&"" | AO12: =$AZ$150&"" | AP12: =$BA$48&"" | AT12: ='Tabelas'!$AE$359&""
A13: Raça | B13: =$N$10 | I13: =IF(COUNTIF('Dados'!$A$350:$A$356,$AW$7)>0,"Escolhida","Sorteada entre as 7 Raças de 05") | N13: =IF($N$11=1,IF('Tabelas'!$B$239<=0,"",IFERROR(INDEX('Tabelas'!$X$242:$X$348,MATCH(IF('Tabelas'!$B$239<=0,0,INT($AC$12*'Tabelas'!$B$239/2147483647)+1),'Tabelas'!$N$242:$N$348,0))&"","")),IF($N$11=2,IF('Tabelas'!$C$239<=0,"",IFERROR(INDEX('Tabelas'!$Y$242:$Y$348,MATCH(IF('Tabelas'!$C$239<=0,0,INT($AC$12*'Tabelas'!$C$239/2147483647)+1),'Tabelas'!$O$242:$O$348,0))&"","")),IF($N$11=3,IF('Tabelas'!$D$239<=0,"",IFERROR(INDEX('Tabelas'!$Z$242:$Z$348,MATCH(IF('Tabelas'!$D$239<=0,0,INT($AC$12*'Tabelas'!$D$239/2147483647)+1),'Tabelas'!$P$242:$P$348,0))&"","")),IF($N$11=4,IF('Tabelas'!$E$239<=0,"",IFERROR(INDEX('Tabelas'!$AA$242:$AA$348,MATCH(IF('Tabelas'!$E$239<=0,0,INT($AC$12*'Tabelas'!$E$239/2147483647)+1),'Tabelas'!$Q$242:$Q$348,0))&"","")),IF($N$11=5,IF('Tabelas'!$F$239<=0,"",IFERROR(INDEX('Tabelas'!$AB$242:$AB$348,MATCH(IF('Tabelas'!$F$239<=0,0,INT($AC$12*'Tabelas'!$F$239/2147483647)+1),'Tabelas'!$R$242:$R$348,0))&"","")),IF($N$11=6,IF('Tabelas'!$G$239<=0,"",IFERROR(INDEX('Tabelas'!$AC$242:$AC$348,MATCH(IF('Tabelas'!$G$239<=0,0,INT($AC$12*'Tabelas'!$G$239/2147483647)+1),'Tabelas'!$S$242:$S$348,0))&"","")),IF('Tabelas'!$H$239<=0,"",IFERROR(INDEX('Tabelas'!$AD$242:$AD$348,MATCH(IF('Tabelas'!$H$239<=0,0,INT($AC$12*'Tabelas'!$H$239/2147483647)+1),'Tabelas'!$T$242:$T$348,0))&"","")))))))) | AA13: =MOD(MOD(MOD((MOD('Início'!$E$15+104729*$B$8+6782636,2147483646)+1)*16807,2147483647)*16807,2147483647)*16807,2147483647) | AB13: =MOD(MOD(MOD((MOD(MOD(INT($AA$13/65536)*$AA$13,2147483647)*65536+MOD($AA$13,65536)*$AA$13,2147483647))*16807,2147483647)*16807,2147483647)*16807,2147483647) | AC13: =MOD(MOD(MOD((MOD($AB$13+INT($AB$13/65536)*MOD($AB$13,65536),2147483646)+1)*16807,2147483647)*16807,2147483647)*16807,2147483647) | AE13: =$AE$12+IF(AND(LEN($N$15)>0,INDEX('Tabelas'!$X$472:$X$578,4)&""=$N$15,LEN(INDEX('Tabelas'!$Y$472:$Y$578,4)&"")>0),1,0) | AG13: =$AV$49&"" | AH13: =$AW$49&"" | AI13: =$AY$49&"" | AJ13: =$BC$49&"" | AK13: =$AW$83&"" | AL13: =$AW$151&"" | AM13: =$AW$117&"" | AN13: =$BA$117&"" | AO13: =$AZ$151&"" | AP13: =$BA$49&"" | AT13: ='Tabelas'!$AE$360&""
A14: Caminho | B14: =$N$15 | I14: =IF(OR($AY$7="Nenhum",COUNTIF('Dados'!$A$360:$A$368,$AY$7)>0),"Escolhido","Tabelas: Caminho do NPC (06.3; Nenhum ×3, 27.12) · Sugestão da planilha — não é regra do livro (H11)") | N14: =IF(LEN($N$13)=0,$N$12,IF(LEN($N$12)=0,$N$13,IF(INDEX('Dados'!$B$388:$B$394,$N$11)=2,$N$13&INDEX('Dados'!$C$388:$C$394,$N$11)&$N$12,$N$12&INDEX('Dados'!$C$388:$C$394,$N$11)&$N$13))) | AA14: =MOD(MOD(MOD((MOD('Início'!$E$15+104729*$B$8+8082345,2147483646)+1)*16807,2147483647)*16807,2147483647)*16807,2147483647) | AB14: =MOD(MOD(MOD((MOD(MOD(INT($AA$14/65536)*$AA$14,2147483647)*65536+MOD($AA$14,65536)*$AA$14,2147483647))*16807,2147483647)*16807,2147483647)*16807,2147483647) | AC14: =MOD(MOD(MOD((MOD($AB$14+INT($AB$14/65536)*MOD($AB$14,65536),2147483646)+1)*16807,2147483647)*16807,2147483647)*16807,2147483647) | AE14: =$AE$13+IF(AND(LEN($N$15)>0,INDEX('Tabelas'!$X$472:$X$578,5)&""=$N$15,LEN(INDEX('Tabelas'!$Y$472:$Y$578,5)&"")>0),1,0) | AG14: =$AV$50&"" | AH14: =$AW$50&"" | AI14: =$AY$50&"" | AJ14: =$BC$50&"" | AK14: =$AW$84&"" | AL14: =$AW$152&"" | AM14: =$AW$118&"" | AN14: =$BA$118&"" | AO14: =$AZ$152&"" | AP14: =$BA$50&"" | AT14: ='Tabelas'!$AE$361&""
A15: Ocupação | B15: =$N$16 | I15: ="Tabelas: Ocupação (NPC)" | K15: =IF('Tabelas'!$B$354<=0,"Lista 'Ocupação (NPC)' está vazia (aba Tabelas)","") | N15: =IF(OR($AY$7="Nenhum",COUNTIF('Dados'!$A$360:$A$368,$AY$7)>0),$AY$7,IF('Tabelas'!$H$354<=0,"",IFERROR(INDEX('Tabelas'!$AD$357:$AD$463,MATCH(IF('Tabelas'!$H$354<=0,0,INT($AC$13*'Tabelas'!$H$354/2147483647)+1),'Tabelas'!$T$357:$T$463,0))&"",""))) | AA15: =MOD(MOD(MOD((MOD('Início'!$E$15+104729*$B$8+9382054,2147483646)+1)*16807,2147483647)*16807,2147483647)*16807,2147483647) | AB15: =MOD(MOD(MOD((MOD(MOD(INT($AA$15/65536)*$AA$15,2147483647)*65536+MOD($AA$15,65536)*$AA$15,2147483647))*16807,2147483647)*16807,2147483647)*16807,2147483647) | AC15: =MOD(MOD(MOD((MOD($AB$15+INT($AB$15/65536)*MOD($AB$15,65536),2147483646)+1)*16807,2147483647)*16807,2147483647)*16807,2147483647) | AE15: =$AE$14+IF(AND(LEN($N$15)>0,INDEX('Tabelas'!$X$472:$X$578,6)&""=$N$15,LEN(INDEX('Tabelas'!$Y$472:$Y$578,6)&"")>0),1,0) | AG15: =$AV$51&"" | AH15: =$AW$51&"" | AI15: =$AY$51&"" | AJ15: =$BC$51&"" | AK15: =$AW$85&"" | AL15: =$AW$153&"" | AM15: =$AW$119&"" | AN15: =$BA$119&"" | AO15: =$AZ$153&"" | AP15: =$BA$51&"" | AT15: ='Tabelas'!$AE$362&""
A16: Aparência | B16: =$N$20 | I16: Sugestão da planilha — não é regra do livro (H25): 2 traços | K16: =IF('Tabelas'!$C$354<=0,"Lista 'Traço de aparência' está vazia (aba Tabelas)","") | N16: =IF('Tabelas'!$B$354<=0,"",IFERROR(INDEX('Tabelas'!$X$357:$X$463,MATCH(IF('Tabelas'!$B$354<=0,0,INT($AC$14*'Tabelas'!$B$354/2147483647)+1),'Tabelas'!$N$357:$N$463,0))&"","")) | AA16: =MOD(MOD(MOD((MOD('Início'!$E$15+104729*$B$8+10681763,2147483646)+1)*16807,2147483647)*16807,2147483647)*16807,2147483647) | AB16: =MOD(MOD(MOD((MOD(MOD(INT($AA$16/65536)*$AA$16,2147483647)*65536+MOD($AA$16,65536)*$AA$16,2147483647))*16807,2147483647)*16807,2147483647)*16807,2147483647) | AC16: =MOD(MOD(MOD((MOD($AB$16+INT($AB$16/65536)*MOD($AB$16,65536),2147483646)+1)*16807,2147483647)*16807,2147483647)*16807,2147483647) | AE16: =$AE$15+IF(AND(LEN($N$15)>0,INDEX('Tabelas'!$X$472:$X$578,7)&""=$N$15,LEN(INDEX('Tabelas'!$Y$472:$Y$578,7)&"")>0),1,0) | AG16: =$AV$52&"" | AH16: =$AW$52&"" | AI16: =$AY$52&"" | AJ16: =$BC$52&"" | AK16: =$AW$86&"" | AL16: =$AW$154&"" | AM16: =$AW$120&"" | AN16: =$BA$120&"" | AO16: =$AZ$154&"" | AP16: =$BA$52&"" | AT16: ='Tabelas'!$AE$363&""
A17: Personalidade | B17: =$N$21 | I17: ="Tabelas: Personalidade" | K17: =IF('Tabelas'!$D$354<=0,"Lista 'Personalidade' está vazia (aba Tabelas)","") | N17: =IF('Tabelas'!$C$354<=0,0,INT($AC$15*'Tabelas'!$C$354/2147483647)+1) | AA17: =MOD(MOD(MOD((MOD('Início'!$E$15+104729*$B$8+11981472,2147483646)+1)*16807,2147483647)*16807,2147483647)*16807,2147483647) | AB17: =MOD(MOD(MOD((MOD(MOD(INT($AA$17/65536)*$AA$17,2147483647)*65536+MOD($AA$17,65536)*$AA$17,2147483647))*16807,2147483647)*16807,2147483647)*16807,2147483647) | AC17: =MOD(MOD(MOD((MOD($AB$17+INT($AB$17/65536)*MOD($AB$17,65536),2147483646)+1)*16807,2147483647)*16807,2147483647)*16807,2147483647) | AE17: =$AE$16+IF(AND(LEN($N$15)>0,INDEX('Tabelas'!$X$472:$X$578,8)&""=$N$15,LEN(INDEX('Tabelas'!$Y$472:$Y$578,8)&"")>0),1,0) | AG17: =$AV$53&"" | AH17: =$AW$53&"" | AI17: =$AY$53&"" | AJ17: =$BC$53&"" | AK17: =$AW$87&"" | AL17: =$AW$155&"" | AM17: =$AW$121&"" | AN17: =$BA$121&"" | AO17: =$AZ$155&"" | AP17: =$BA$53&"" | AT17: ='Tabelas'!$AE$364&""
A18: Motivação | B18: =$N$23 | I18: =IF(OR($N$15="Nenhum",LEN($N$15)=0,$N$22=0),"Tabelas: Motivação (sem Caminho)","Tabelas: Motivação por Caminho (27.12)") | K18: =IF(AND($N$22=0,'Tabelas'!$E$354<=0),"Listas de motivação vazias (aba Tabelas)","") | N18: =IF('Tabelas'!$C$354<=0,"",IFERROR(INDEX('Tabelas'!$Y$357:$Y$463,MATCH($N$17,'Tabelas'!$O$357:$O$463,0))&"","")) | AA18: =MOD(MOD(MOD((MOD('Início'!$E$15+104729*$B$8+13281181,2147483646)+1)*16807,2147483647)*16807,2147483647)*16807,2147483647) | AB18: =MOD(MOD(MOD((MOD(MOD(INT($AA$18/65536)*$AA$18,2147483647)*65536+MOD($AA$18,65536)*$AA$18,2147483647))*16807,2147483647)*16807,2147483647)*16807,2147483647) | AC18: =MOD(MOD(MOD((MOD($AB$18+INT($AB$18/65536)*MOD($AB$18,65536),2147483646)+1)*16807,2147483647)*16807,2147483647)*16807,2147483647) | AE18: =$AE$17+IF(AND(LEN($N$15)>0,INDEX('Tabelas'!$X$472:$X$578,9)&""=$N$15,LEN(INDEX('Tabelas'!$Y$472:$Y$578,9)&"")>0),1,0) | AG18: =$AV$54&"" | AH18: =$AW$54&"" | AI18: =$AY$54&"" | AJ18: =$BC$54&"" | AK18: =$AW$88&"" | AL18: =$AW$156&"" | AM18: =$AW$122&"" | AN18: =$BA$122&"" | AO18: =$AZ$156&"" | AP18: =$BA$54&"" | AT18: ='Tabelas'!$AE$365&""
A19: Segredo | B19: =$N$24 | I19: ="Tabelas: Segredo" | K19: =IF('Tabelas'!$F$354<=0,"Lista 'Segredo' está vazia (aba Tabelas)","") | N19: =IF('Tabelas'!$C$354<=0,"",IFERROR(INDEX('Tabelas'!$Y$357:$Y$463,MATCH(IF('Tabelas'!$C$354<=1,$N$17,MOD($N$17-1+1+INT($AC$16*('Tabelas'!$C$354-1)/2147483647),'Tabelas'!$C$354)+1),'Tabelas'!$O$357:$O$463,0))&"","")) | AA19: =MOD(MOD(MOD((MOD('Início'!$E$15+104729*$B$8+14580890,2147483646)+1)*16807,2147483647)*16807,2147483647)*16807,2147483647) | AB19: =MOD(MOD(MOD((MOD(MOD(INT($AA$19/65536)*$AA$19,2147483647)*65536+MOD($AA$19,65536)*$AA$19,2147483647))*16807,2147483647)*16807,2147483647)*16807,2147483647) | AC19: =MOD(MOD(MOD((MOD($AB$19+INT($AB$19/65536)*MOD($AB$19,65536),2147483646)+1)*16807,2147483647)*16807,2147483647)*16807,2147483647) | AE19: =$AE$18+IF(AND(LEN($N$15)>0,INDEX('Tabelas'!$X$472:$X$578,10)&""=$N$15,LEN(INDEX('Tabelas'!$Y$472:$Y$578,10)&"")>0),1,0) | AG19: =$AV$55&"" | AH19: =$AW$55&"" | AI19: =$AY$55&"" | AJ19: =$BC$55&"" | AK19: =$AW$89&"" | AL19: =$AW$157&"" | AM19: =$AW$123&"" | AN19: =$BA$123&"" | AO19: =$AZ$157&"" | AP19: =$BA$55&"" | AT19: ='Tabelas'!$AE$366&""
A20: Maneirismo e voz | B20: =$N$25 | I20: ="Tabelas: Maneirismo e voz" | K20: =IF('Tabelas'!$G$354<=0,"Lista 'Maneirismo e voz' está vazia (aba Tabelas)","") | N20: =IF(LEN($N$18)=0,"",IF(OR($N$19=$N$18,LEN($N$19)=0),$N$18,$N$18&"; "&$N$19)) | AA20: =MOD(MOD(MOD((MOD('Início'!$E$15+104729*$B$8+15880599,2147483646)+1)*16807,2147483647)*16807,2147483647)*16807,2147483647) | AB20: =MOD(MOD(MOD((MOD(MOD(INT($AA$20/65536)*$AA$20,2147483647)*65536+MOD($AA$20,65536)*$AA$20,2147483647))*16807,2147483647)*16807,2147483647)*16807,2147483647) | AC20: =MOD(MOD(MOD((MOD($AB$20+INT($AB$20/65536)*MOD($AB$20,65536),2147483646)+1)*16807,2147483647)*16807,2147483647)*16807,2147483647) | AE20: =$AE$19+IF(AND(LEN($N$15)>0,INDEX('Tabelas'!$X$472:$X$578,11)&""=$N$15,LEN(INDEX('Tabelas'!$Y$472:$Y$578,11)&"")>0),1,0) | AG20: =$AV$57&"" | AH20: =$AW$57&"" | AI20: =$AY$57&"" | AJ20: =$BC$57&"" | AK20: =$AW$91&"" | AL20: =$AW$159&"" | AM20: =$AW$125&"" | AN20: =$BA$125&"" | AO20: =$AZ$159&"" | AP20: =$BA$57&"" | AT20: ='Tabelas'!$AE$367&""
A21: Atitude com o grupo | B21: =$N$26 | I21: ="Tabelas: Atitude com o grupo · Sugestão da planilha — não é regra do livro (H11)" | K21: =IF('Tabelas'!$I$354<=0,"Lista 'Atitude com o grupo' está vazia (aba Tabelas)","") | N21: =IF('Tabelas'!$D$354<=0,"",IFERROR(INDEX('Tabelas'!$Z$357:$Z$463,MATCH(IF('Tabelas'!$D$354<=0,0,INT($AC$17*'Tabelas'!$D$354/2147483647)+1),'Tabelas'!$P$357:$P$463,0))&"","")) | AA21: =MOD(MOD(MOD((MOD('Início'!$E$15+104729*$B$8+17180308,2147483646)+1)*16807,2147483647)*16807,2147483647)*16807,2147483647) | AB21: =MOD(MOD(MOD((MOD(MOD(INT($AA$21/65536)*$AA$21,2147483647)*65536+MOD($AA$21,65536)*$AA$21,2147483647))*16807,2147483647)*16807,2147483647)*16807,2147483647) | AC21: =MOD(MOD(MOD((MOD($AB$21+INT($AB$21/65536)*MOD($AB$21,65536),2147483646)+1)*16807,2147483647)*16807,2147483647)*16807,2147483647) | AE21: =$AE$20+IF(AND(LEN($N$15)>0,INDEX('Tabelas'!$X$472:$X$578,12)&""=$N$15,LEN(INDEX('Tabelas'!$Y$472:$Y$578,12)&"")>0),1,0) | AG21: =$AV$58&"" | AH21: =$AW$58&"" | AI21: =$AY$58&"" | AJ21: =$BC$58&"" | AK21: =$AW$92&"" | AL21: =$AW$160&"" | AM21: =$AW$126&"" | AN21: =$BA$126&"" | AO21: =$AZ$160&"" | AP21: =$BA$58&"" | AT21: ='Tabelas'!$AE$368&""
A22: Gancho | B22: =$N$30 | I22: =IF($N$27=1,"27.18, faixa "&'Campanha'!$B$19,"Tabelas: Gancho do NPC")&" · Sugestão da planilha — não é regra do livro (H20)" | K22: =IF(LEN($N$30)=0,"Listas de gancho vazias (aba Tabelas)","") | N22: =$AE$116 | AA22: =MOD(MOD(MOD((MOD('Início'!$E$15+104729*$B$8+18480017,2147483646)+1)*16807,2147483647)*16807,2147483647)*16807,2147483647) | AB22: =MOD(MOD(MOD((MOD(MOD(INT($AA$22/65536)*$AA$22,2147483647)*65536+MOD($AA$22,65536)*$AA$22,2147483647))*16807,2147483647)*16807,2147483647)*16807,2147483647) | AC22: =MOD(MOD(MOD((MOD($AB$22+INT($AB$22/65536)*MOD($AB$22,65536),2147483646)+1)*16807,2147483647)*16807,2147483647)*16807,2147483647) | AE22: =$AE$21+IF(AND(LEN($N$15)>0,INDEX('Tabelas'!$X$472:$X$578,13)&""=$N$15,LEN(INDEX('Tabelas'!$Y$472:$Y$578,13)&"")>0),1,0) | AG22: =$AV$59&"" | AH22: =$AW$59&"" | AI22: =$AY$59&"" | AJ22: =$BC$59&"" | AK22: =$AW$93&"" | AL22: =$AW$161&"" | AM22: =$AW$127&"" | AN22: =$BA$127&"" | AO22: =$AZ$161&"" | AP22: =$BA$59&"" | AT22: ='Tabelas'!$AE$369&""
A23: Papel na história | B23: =$N$31 | I23: =IF(COUNTIF('Dados'!$A$398:$A$404,$BA$7)>0,"Escolhido","Sorteado entre os 7 papéis") | N23: =IF(OR($N$15="Nenhum",LEN($N$15)=0,$N$22=0),IF('Tabelas'!$E$354<=0,"",IFERROR(INDEX('Tabelas'!$AA$357:$AA$463,MATCH(IF('Tabelas'!$E$354<=0,0,INT($AC$18*'Tabelas'!$E$354/2147483647)+1),'Tabelas'!$Q$357:$Q$463,0))&"","")),IFERROR(INDEX('Tabelas'!$Y$472:$Y$578,MATCH(INT($AC$18*$N$22/2147483647)+1,$AE$10:$AE$116,0))&"","")) | AA23: =MOD(MOD(MOD((MOD('Início'!$E$15+104729*$B$8+19779726,2147483646)+1)*16807,2147483647)*16807,2147483647)*16807,2147483647) | AB23: =MOD(MOD(MOD((MOD(MOD(INT($AA$23/65536)*$AA$23,2147483647)*65536+MOD($AA$23,65536)*$AA$23,2147483647))*16807,2147483647)*16807,2147483647)*16807,2147483647) | AC23: =MOD(MOD(MOD((MOD($AB$23+INT($AB$23/65536)*MOD($AB$23,65536),2147483646)+1)*16807,2147483647)*16807,2147483647)*16807,2147483647) | AE23: =$AE$22 | AG23: =$AV$60&"" | AH23: =$AW$60&"" | AI23: =$AY$60&"" | AJ23: =$BC$60&"" | AK23: =$AW$94&"" | AL23: =$AW$162&"" | AM23: =$AW$128&"" | AN23: =$BA$128&"" | AO23: =$AZ$162&"" | AP23: =$BA$60&"" | AT23: ='Tabelas'!$AE$371&""
N24: =IF('Tabelas'!$F$354<=0,"",IFERROR(INDEX('Tabelas'!$AB$357:$AB$463,MATCH(IF('Tabelas'!$F$354<=0,0,INT($AC$19*'Tabelas'!$F$354/2147483647)+1),'Tabelas'!$R$357:$R$463,0))&"","")) | AA24: =MOD(MOD(MOD((MOD('Início'!$E$15+104729*$B$8+21079435,2147483646)+1)*16807,2147483647)*16807,2147483647)*16807,2147483647) | AB24: =MOD(MOD(MOD((MOD(MOD(INT($AA$24/65536)*$AA$24,2147483647)*65536+MOD($AA$24,65536)*$AA$24,2147483647))*16807,2147483647)*16807,2147483647)*16807,2147483647) | AC24: =MOD(MOD(MOD((MOD($AB$24+INT($AB$24/65536)*MOD($AB$24,65536),2147483646)+1)*16807,2147483647)*16807,2147483647)*16807,2147483647) | AE24: =$AE$23+IF(AND(LEN($N$15)>0,INDEX('Tabelas'!$X$472:$X$578,15)&""=$N$15,LEN(INDEX('Tabelas'!$Y$472:$Y$578,15)&"")>0),1,0) | AG24: =$AV$61&"" | AH24: =$AW$61&"" | AI24: =$AY$61&"" | AJ24: =$BC$61&"" | AK24: =$AW$95&"" | AL24: =$AW$163&"" | AM24: =$AW$129&"" | AN24: =$BA$129&"" | AO24: =$AZ$163&"" | AP24: =$BA$61&"" | AT24: ='Tabelas'!$AE$372&""
A25: Bloco de combate (âncoras de 28.3; o mesmo número do Criador de Inimigos no modo Faixa do livro) | N25: =IF('Tabelas'!$G$354<=0,"",IFERROR(INDEX('Tabelas'!$AC$357:$AC$463,MATCH(IF('Tabelas'!$G$354<=0,0,INT($AC$20*'Tabelas'!$G$354/2147483647)+1),'Tabelas'!$S$357:$S$463,0))&"","")) | AE25: =$AE$24+IF(AND(LEN($N$15)>0,INDEX('Tabelas'!$X$472:$X$578,16)&""=$N$15,LEN(INDEX('Tabelas'!$Y$472:$Y$578,16)&"")>0),1,0) | AG25: =$AV$62&"" | AH25: =$AW$62&"" | AI25: =$AY$62&"" | AJ25: =$BC$62&"" | AK25: =$AW$96&"" | AL25: =$AW$164&"" | AM25: =$AW$130&"" | AN25: =$BA$130&"" | AO25: =$AZ$164&"" | AP25: =$BA$62&"" | AT25: ='Tabelas'!$AE$373&""
A26: Faixa · tipo | B26: PV | C26: Defesa | D26: RD | E26: Tenacidade | F26: VEL | G26: Ataque | H26: DT dos efeitos | I26: Teste de Resistência | J26: Nº de Fraquezas | K26: Aviso | N26: =IF('Tabelas'!$I$354<=0,"",IFERROR(INDEX('Tabelas'!$AE$357:$AE$463,MATCH(IF('Tabelas'!$I$354<=0,0,INT($AC$21*'Tabelas'!$I$354/2147483647)+1),'Tabelas'!$U$357:$U$463,0))&"","")) | AE26: =$AE$25+IF(AND(LEN($N$15)>0,INDEX('Tabelas'!$X$472:$X$578,17)&""=$N$15,LEN(INDEX('Tabelas'!$Y$472:$Y$578,17)&"")>0),1,0) | AG26: =$AV$63&"" | AH26: =$AW$63&"" | AI26: =$AY$63&"" | AJ26: =$BC$63&"" | AK26: =$AW$97&"" | AL26: =$AW$165&"" | AM26: =$AW$131&"" | AN26: =$BA$131&"" | AO26: =$AZ$165&"" | AP26: =$BA$63&"" | AT26: ='Tabelas'!$AE$374&""
A27: =IF(LEN($N$35)=0,"Sem bloco",$N$33&" · "&$N$34) | B27: =IF(LEN($N$35)=0,"",IFERROR(INDEX('Dados'!$D$38:$D$52,MATCH($N$35,'Dados'!$A$38:$A$52,0)),"")) | C27: =IF(LEN($N$35)=0,"",IFERROR(INDEX('Dados'!$E$38:$E$52,MATCH($N$35,'Dados'!$A$38:$A$52,0)),"")) | D27: =IF(LEN($N$35)=0,"",IFERROR(INDEX('Dados'!$F$38:$F$52,MATCH($N$35,'Dados'!$A$38:$A$52,0)),"")) | E27: =IF(LEN($N$35)=0,"",IFERROR(INDEX('Dados'!$G$38:$G$52,MATCH($N$35,'Dados'!$A$38:$A$52,0)),"")) | F27: =IF(LEN($N$35)=0,"",IFERROR(INDEX('Dados'!$H$38:$H$52,MATCH($N$35,'Dados'!$A$38:$A$52,0)),"")) | G27: =IF(LEN($N$35)=0,"","+"&IFERROR(INDEX('Dados'!$I$38:$I$52,MATCH($N$35,'Dados'!$A$38:$A$52,0)),"")) | H27: =IF(LEN($N$35)=0,"",IFERROR(INDEX('Dados'!$L$38:$L$52,MATCH($N$35,'Dados'!$A$38:$A$52,0)),"")) | I27: =IF(LEN($N$35)=0,"","+"&IFERROR(INDEX('Dados'!$M$38:$M$52,MATCH($N$35,'Dados'!$A$38:$A$52,0)),"")) | J27: =IF(LEN($N$35)=0,"",IFERROR(INDEX('Dados'!$N$38:$N$52,MATCH($N$35,'Dados'!$A$38:$A$52,0)),"")) | N27: =(1+INT($AC$23*((2)-(1)+1)/2147483647)) | AE27: =$AE$26+IF(AND(LEN($N$15)>0,INDEX('Tabelas'!$X$472:$X$578,18)&""=$N$15,LEN(INDEX('Tabelas'!$Y$472:$Y$578,18)&"")>0),1,0) | AG27: =$AV$64&"" | AH27: =$AW$64&"" | AI27: =$AY$64&"" | AJ27: =$BC$64&"" | AK27: =$AW$98&"" | AL27: =$AW$166&"" | AM27: =$AW$132&"" | AN27: =$BA$132&"" | AO27: =$AZ$166&"" | AP27: =$BA$64&"" | AT27: ='Tabelas'!$AE$375&""
A28: Dano por acerto | B28: =IF(LEN($N$35)=0,"",IFERROR(INDEX('Dados'!$J$38:$J$52,MATCH($N$35,'Dados'!$A$38:$A$52,0)),"")&" · média "&IFERROR(INDEX('Dados'!$K$38:$K$52,MATCH($N$35,'Dados'!$A$38:$A$52,0)),"")) | F28: Na Fila | G28: =IF(LEN($N$35)=0,"","VEL "&IFERROR(INDEX('Dados'!$H$38:$H$52,MATCH($N$35,'Dados'!$A$38:$A$52,0)),"")&", "&IFERROR(INDEX('Dados'!$P$38:$P$52,MATCH($N$35,'Dados'!$A$38:$A$52,0)),"")) | N28: =IF('Campanha'!$B$18=1,IF('Tabelas'!$D$9<=0,"",IFERROR(INDEX('Tabelas'!$Z$12:$Z$118,MATCH(IF('Tabelas'!$D$9<=0,0,INT($AC$22*'Tabelas'!$D$9/2147483647)+1),'Tabelas'!$P$12:$P$118,0))&"","")),IF('Campanha'!$B$18=2,IF('Tabelas'!$E$9<=0,"",IFERROR(INDEX('Tabelas'!$AA$12:$AA$118,MATCH(IF('Tabelas'!$E$9<=0,0,INT($AC$22*'Tabelas'!$E$9/2147483647)+1),'Tabelas'!$Q$12:$Q$118,0))&"","")),IF('Campanha'!$B$18=3,IF('Tabelas'!$F$9<=0,"",IFERROR(INDEX('Tabelas'!$AB$12:$AB$118,MATCH(IF('Tabelas'!$F$9<=0,0,INT($AC$22*'Tabelas'!$F$9/2147483647)+1),'Tabelas'!$R$12:$R$118,0))&"","")),IF('Campanha'!$B$18=4,IF('Tabelas'!$G$9<=0,"",IFERROR(INDEX('Tabelas'!$AC$12:$AC$118,MATCH(IF('Tabelas'!$G$9<=0,0,INT($AC$22*'Tabelas'!$G$9/2147483647)+1),'Tabelas'!$S$12:$S$118,0))&"","")),IF('Tabelas'!$H$9<=0,"",IFERROR(INDEX('Tabelas'!$AD$12:$AD$118,MATCH(IF('Tabelas'!$H$9<=0,0,INT($AC$22*'Tabelas'!$H$9/2147483647)+1),'Tabelas'!$T$12:$T$118,0))&"","")))))) | AE28: =$AE$27+IF(AND(LEN($N$15)>0,INDEX('Tabelas'!$X$472:$X$578,19)&""=$N$15,LEN(INDEX('Tabelas'!$Y$472:$Y$578,19)&"")>0),1,0) | AG28: =$AV$65&"" | AH28: =$AW$65&"" | AI28: =$AY$65&"" | AJ28: =$BC$65&"" | AK28: =$AW$99&"" | AL28: =$AW$167&"" | AM28: =$AW$133&"" | AN28: =$BA$133&"" | AO28: =$AZ$167&"" | AP28: =$BA$65&"" | AT28: ='Tabelas'!$AE$376&""
A29: =IF(LEN($N$35)=0,"Escolha a faixa do bloco (ou Do grupo) para ver os números.","NPC aliado também usa as âncoras de 28.3 (sem Esquiva, PH, Energia nem Ultimate, 28.2); Execução: ser racional pode Executar (23.5).") | N29: =IF('Tabelas'!$J$354<=0,"",IFERROR(INDEX('Tabelas'!$AF$357:$AF$463,MATCH(IF('Tabelas'!$J$354<=0,0,INT($AC$22*'Tabelas'!$J$354/2147483647)+1),'Tabelas'!$V$357:$V$463,0))&"","")) | AE29: =$AE$28+IF(AND(LEN($N$15)>0,INDEX('Tabelas'!$X$472:$X$578,20)&""=$N$15,LEN(INDEX('Tabelas'!$Y$472:$Y$578,20)&"")>0),1,0) | AG29: =$AV$66&"" | AH29: =$AW$66&"" | AI29: =$AY$66&"" | AJ29: =$BC$66&"" | AK29: =$AW$100&"" | AL29: =$AW$168&"" | AM29: =$AW$134&"" | AN29: =$BA$134&"" | AO29: =$AZ$168&"" | AP29: =$BA$66&"" | AT29: ='Tabelas'!$AE$377&""
A30: =IF(LEN($N$35)=0,"","Para levar ao combate: na aba Inimigos, crie uma linha com o nome "&$N$14&", tipo "&$N$34&" e faixa "&$N$33&" (modo Faixa do livro); ele entra nas listas de Encontros e Combate.") | N30: =IF($N$27=1,IF(LEN($N$28)>0,$N$28,$N$29),IF(LEN($N$29)>0,$N$29,$N$28)) | AE30: =$AE$29+IF(AND(LEN($N$15)>0,INDEX('Tabelas'!$X$472:$X$578,21)&""=$N$15,LEN(INDEX('Tabelas'!$Y$472:$Y$578,21)&"")>0),1,0) | AG30: =$AV$68&"" | AH30: =$AW$68&"" | AI30: =$AY$68&"" | AJ30: =$BC$68&"" | AK30: =$AW$102&"" | AL30: =$AW$170&"" | AM30: =$AW$136&"" | AN30: =$BA$136&"" | AO30: =$AZ$170&"" | AP30: =$BA$68&"" | AT30: ='Tabelas'!$AE$378&""
